Workbook

Sheet SVM
A1: ID_Student | B1: code_etudiant | C1: Resultat_reel | E1: 28 | F1: 29 | G1: 29 | H1: 29 | L1: 1 | M1: 2 | N1: 3 | O1: 4 | P1: 5 | Q1: 6 | R1: 7 | S1: 8 | T1: 9 | U1: 10 | V1: 11 | W1: 12 | X1: 13 | Y1: 14 | Z1: 15 | AA1: 16 | AB1: 17 | AC1: 18 | AD1: 19 | AE1: 20 | AF1: 21 | AG1: 22 | AH1: 23 | AI1: 24 | AJ1: 25 | AK1: 26 | AL1: 27 | AM1: 28 | AN1: 29
A2: 0 | B2: 3 | C2: Fail | E2: Dropout | F2: Fail | G2: Dropout | H2: Dropout | L2: Dropout | M2: Dropout | N2: Dropout | O2: Dropout | P2: Dropout | Q2: Dropout | R2: Dropout | S2: Dropout | T2: Dropout | U2: Dropout | V2: Dropout | W2: Dropout | X2: Dropout | Y2: Dropout | Z2: Dropout | AA2: Dropout | AB2: Dropout | AC2: Dropout | AD2: Dropout | AE2: Dropout | AF2: Dropout | AG2: Dropout | AH2: Dropout | AI2: Dropout | AJ2: Dropout | AK2: Dropout | AL2: Dropout | AM2: Dropout | AN2: Dropout
A3: 1 | B3: 4 | C3: Dropout | E3: Dropout | F3: Dropout | G3: Dropout | H3: Dropout | L3: Dropout | M3: Dropout | N3: Dropout | O3: Dropout | P3: Dropout | Q3: Dropout | R3: Dropout | S3: Dropout | T3: Dropout | U3: Dropout | V3: Dropout | W3: Dropout | X3: Dropout | Y3: Dropout | Z3: Dropout | AA3: Dropout | AB3: Dropout | AC3: Dropout | AD3: Dropout | AE3: Dropout | AF3: Dropout | AG3: Dropout | AH3: Dropout | AI3: Dropout | AJ3: Dropout | AK3: Dropout | AL3: Dropout | AM3: Dropout | AN3: Dropout
A4: 2 | B4: 5 | C4: Pass | E4: Pass | F4: Pass | G4: Pass | H4: Pass | L4: Pass | M4: Pass | N4: Pass | O4: Pass | P4: Pass | Q4: Pass | R4: Pass | S4: Pass | T4: Pass | U4: Pass | V4: Pass | W4: Pass | X4: Pass | Y4: Pass | Z4: Pass | AA4: Pass | AB4: Pass | AC4: Pass | AD4: Pass | AE4: Pass | AF4: Pass | AG4: Pass | AH4: Pass | AI4: Pass | AJ4: Pass | AK4: Pass | AL4: Pass | AM4: Pass | AN4: Pass
A5: 3 | B5: 12 | C5: Pass | E5: Pass | F5: Pass | G5: Pass | H5: Pass | L5: Pass | M5: Pass | N5: Pass | O5: Pass | P5: Pass | Q5: Pass | R5: Pass | S5: Pass | T5: Pass | U5: Pass | V5: Pass | W5: Pass | X5: Pass | Y5: Pass | Z5: Pass | AA5: Pass | AB5: Pass | AC5: Pass | AD5: Pass | AE5: Pass | AF5: Pass | AG5: Pass | AH5: Pass | AI5: Pass | AJ5: Pass | AK5: Pass | AL5: Pass | AM5: Pass | AN5: Pass
A6: 4 | B6: 13 | C6: Fail | E6: Dropout | F6: Fail | G6: Dropout | H6: Dropout | L6: Dropout | M6: Dropout | N6: Dropout | O6: Dropout | P6: Dropout | Q6: Dropout | R6: Dropout | S6: Dropout | T6: Dropout | U6: Dropout | V6: Dropout | W6: Dropout | X6: Dropout | Y6: Dropout | Z6: Dropout | AA6: Dropout | AB6: Dropout | AC6: Dropout | AD6: Dropout | AE6: Dropout | AF6: Dropout | AG6: Dropout | AH6: Dropout | AI6: Dropout | AJ6: Dropout | AK6: Dropout | AL6: Dropout | AM6: Dropout | AN6: Dropout
A7: 5 | B7: 25 | C7: Pass | E7: Dropout | F7: Fail | G7: Dropout | H7: Fail | L7: Dropout | M7: Dropout | N7: Pass | O7: Dropout | P7: Dropout | Q7: Dropout | R7: Dropout | S7: Dropout | T7: Dropout | U7: Dropout | V7: Dropout | W7: Dropout | X7: Dropout | Y7: Dropout | Z7: Pass | AA7: Pass | AB7: Dropout | AC7: Dropout | AD7: Dropout | AE7: Dropout | AF7: Dropout | AG7: Dropout | AH7: Dropout | AI7: Dropout | AJ7: Dropout | AK7: Dropout | AL7: Dropout | AM7: Dropout | AN7: Fail
A8: 6 | B8: 40 | C8: Dropout | E8: Dropout | F8: Dropout | G8: Dropout | H8: Dropout | L8: Dropout | M8: Dropout | N8: Dropout | O8: Dropout | P8: Dropout | Q8: Dropout | R8: Dropout | S8: Dropout | T8: Dropout | U8: Dropout | V8: Dropout | W8: Dropout | X8: Dropout | Y8: Dropout | Z8: Dropout | AA8: Dropout | AB8: Dropout | AC8: Dropout | AD8: Dropout | AE8: Dropout | AF8: Dropout | AG8: Dropout | AH8: Dropout | AI8: Dropout | AJ8: Dropout | AK8: Dropout | AL8: Dropout | AM8: Dropout | AN8: Dropout
A9: 7 | B9: 55 | C9: Pass | E9: Pass | F9: Pass | G9: Dropout | H9: Pass | L9: Pass | M9: Pass | N9: Pass | O9: Pass | P9: Pass | Q9: Pass | R9: Pass | S9: Pass | T9: Pass | U9: Pass | V9: Pass | W9: Pass | X9: Pass | Y9: Pass | Z9: Pass | AA9: Pass | AB9: Pass | AC9: Pass | AD9: Pass | AE9: Pass | AF9: Pass | AG9: Pass | AH9: Pass | AI9: Pass | AJ9: Pass | AK9: Pass | AL9: Pass | AM9: Pass | AN9: Pass
A10: 8 | B10: 60 | C10: Pass | E10: Pass | F10: Pass | G10: Pass | H10: Pass | L10: Pass | M10: Pass | N10: Pass | O10: Pass | P10: Pass | Q10: Pass | R10: Pass | S10: Pass | T10: Pass | U10: Pass | V10: Pass | W10: Pass | X10: Pass | Y10: Pass | Z10: Pass | AA10: Pass | AB10: Pass | AC10: Pass | AD10: Pass | AE10: Pass | AF10: Pass | AG10: Pass | AH10: Pass | AI10: Pass | AJ10: Pass | AK10: Pass | AL10: Pass | AM10: Pass | AN10: Pass
A11: 9 | B11: 70 | C11: Dropout | E11: Dropout | F11: Dropout | G11: Pass | H11: Dropout | L11: Dropout | M11: Dropout | N11: Pass | O11: Pass | P11: Pass | Q11: Pass | R11: Pass | S11: Dropout | T11: Dropout | U11: Dropout | V11: Dropout | W11: Dropout | X11: Dropout | Y11: Dropout | Z11: Dropout | AA11: Dropout | AB11: Dropout | AC11: Dropout | AD11: Dropout | AE11: Dropout | AF11: Dropout | AG11: Dropout | AH11: Dropout | AI11: Dropout | AJ11: Dropout | AK11: Dropout | AL11: Dropout | AM11: Dropout | AN11: Dropout
A12: 10 | B12: 72 | C12: Fail | E12: Pass | F12: Pass | G12: Pass | H12: Pass | L12: Pass | M12: Pass | N12: Pass | O12: Pass | P12: Pass | Q12: Pass | R12: Pass | S12: Pass | T12: Pass | U12: Pass | V12: Pass | W12: Pass | X12: Pass | Y12: Pass | Z12: Pass | AA12: Pass | AB12: Pass | AC12: Pass | AD12: Pass | AE12: Pass | AF12: Pass | AG12: Pass | AH12: Pass | AI12: Pass | AJ12: Pass | AK12: Pass | AL12: Pass | AM12: Pass | AN12: Pass
A13: 11 | B13: 85 | C13: Pass | E13: Pass | F13: Pass | G13: Dropout | H13: Pass | L13: Dropout | M13: Dropout | N13: Dropout | O13: Dropout | P13: Dropout | Q13: Dropout | R13: Dropout | S13: Pass | T13: Pass | U13: Pass | V13: Pass | W13: Pass | X13: Pass | Y13: Pass | Z13: Pass | AA13: Pass | AB13: Pass | AC13: Pass | AD13: Pass | AE13: Pass | AF13: Pass | AG13: Pass | AH13: Pass | AI13: Pass | AJ13: Pass | AK13: Pass | AL13: Pass | AM13: Pass | AN13: Pass
... A201: 199 | B201: 2365 | C201: Dropout | E201: Dropout | F201: Dropout | G201: Dropout | H201: Dropout | L201: Dropout | M201: Dropout | N201: Dropout | O201: Dropout | P201: Dropout | Q201: Dropout | R201: Dropout | S201: Dropout | T201: Dropout | U201: Dropout | V201: Dropout | W201: Dropout | X201: Dropout | Y201: Dropout | Z201: Dropout | AA201: Dropout | AB201: Dropout | AC201: Dropout | AD201: Dropout | AE201: Dropout | AF201: Dropout | AG201: Dropout | AH201: Dropout | AI201: Dropout | AJ201: Dropout | AK201: Dropout | AL201: Dropout | AM201: Dropout | AN201: Dropout

Sheet AnalyseTCD
A3: Nombre de 29 | B3: 29
A4: Resultat_reel | B4: Dropout | C4: Fail | D4: Pass | E4: (vide) | F4: Total général
A5: Dropout | B5: 70 | C5: 1 | D5: 1 | F5: 72
A6: Fail | B6: 16 | C6: 5 | D6: 13 | F6: 34
A7: Pass | B7: 1 | C7: 1 | D7: 92 | F7: 94
A8: (vide)
A9: Total général | B9: 87 | C9: 7 | D9: 106 | F9: 200

Sheet ResultsPass
A2: 29 | B2: Resultat_reel | C2: Dropout | D2: Fail | E2: Pass | F2: Pass - Pass (VP) | G2: =E5 -> 92 | H2: 9 | I2: Resultat_reel | J2: Dropout | K2: Fail | L2: Pass | M2: Pass - Pass (VP) | N2: =L5 -> 91 | O2: 18 | P2: Resultat_reel | Q2: Dropout | R2: Fail | S2: Pass | T2: Pass - Pass (VP) | U2: =S5 -> 92 | V2: 27 | W2: Resultat_reel | X2: Dropout | Y2: Fail | Z2: Pass | AA2: Pass - Pass (VP) | AB2: =Z5 -> 92
B3: Dropout | C3: 70 | D3: 1 | E3: 1 | F3: Pass - Others (FN) | G3: =D5+C5 -> 2 | I3: Dropout | J3: 59 | K3: 6 | L3: 7 | M3: Pass - Others (FN) | N3: =K5+J5 -> 3 | P3: Dropout | Q3: 67 | R3: 1 | S3: 4 | T3: Pass - Others (FN) | U3: =R5+Q5 -> 2 | W3: Dropout | X3: 69 | Y3: 2 | Z3: 1 | AA3: Pass - Others (FN) | AB3: =Y5+X5 -> 2
B4: Fail | C4: 16 | D4: 5 | E4: 13 | F4: Others - Pass (FP) | G4: =E4+E3 -> 14 | I4: Fail | J4: 10 | K4: 8 | L4: 16 | M4: Others - Pass (FP) | N4: =L4+L3 -> 23 | P4: Fail | Q4: 14 | R4: 6 | S4: 14 | T4: Others - Pass (FP) | U4: =S4+S3 -> 18 | W4: Fail | X4: 15 | Y4: 6 | Z4: 13 | AA4: Others - Pass (FP) | AB4: =Z4+Z3 -> 14
B5: Pass | C5: 1 | D5: 1 | E5: 92 | F5: Others - Others(VN) | G5: =C3+C4+D3+D4 -> 92 | I5: Pass | J5: 1 | K5: 2 | L5: 91 | M5: Others - Others(VN) | N5: =J3+J4+K3+K4 -> 83 | P5: Pass | Q5: 1 | R5: 1 | S5: 92 | T5: Others - Others(VN) | U5: =Q3+Q4+R3+R4 -> 88 | W5: Pass | X5: 1 | Y5: 1 | Z5: 92 | AA5: Others - Others(VN) | AB5: =X3+X4+Y3+Y4 -> 92
A7: 1 | B7: Resultat_reel | C7: Dropout | D7: Fail | E7: Pass | F7: Pass - Pass (VP) | G7: =E10 -> 89 | H7: 10 | I7: Resultat_reel | J7: Dropout | K7: Fail | L7: Pass | M7: Pass - Pass (VP) | N7: =L10 -> 91 | O7: 19 | P7: Resultat_reel | Q7: Dropout | R7: Fail | S7: Pass | T7: Pass - Pass (VP) | U7: =S10 -> 92 | V7: 28 | W7: Resultat_reel | X7: Dropout | Y7: Fail | Z7: Pass | AA7: Pass - Pass (VP) | AB7: =Z10 -> 92
B8: Dropout | C8: 68 | E8: 4 | F8: Pass - Others (FN) | G8: =D10+C10 -> 5 | I8: Dropout | J8: 58 | K8: 7 | L8: 7 | M8: Pass - Others (FN) | N8: =K10+J10 -> 3 | P8: Dropout | Q8: 65 | R8: 3 | S8: 4 | T8: Pass - Others (FN) | U8: =R10+Q10 -> 2 | W8: Dropout | X8: 69 | Y8: 2 | Z8: 1 | AA8: Pass - Others (FN) | AB8: =Y10+X10 -> 2
B9: Fail | C9: 22 | E9: 12 | F9: Others - Pass (FP) | G9: =E9+E8 -> 16 | I9: Fail | J9: 8 | K9: 10 | L9: 16 | M9: Others - Pass (FP) | N9: =L9+L8 -> 23 | P9: Fail | Q9: 15 | R9: 5 | S9: 14 | T9: Others - Pass (FP) | U9: =S9+S8 -> 18 | W9: Fail | X9: 15 | Y9: 6 | Z9: 13 | AA9: Others - Pass (FP) | AB9: =Z9+Z8 -> 14
B10: Pass | C10: 5 | E10: 89 | F10: Others - Others(VN) | G10: =C8+C9+D8+D9 -> 90 | I10: Pass | J10: 1 | K10: 2 | L10: 91 | M10: Others - Others(VN) | N10: =J8+J9+K8+K9 -> 83 | P10: Pass | Q10: 1 | R10: 1 | S10: 92 | T10: Others - Others(VN) | U10: =Q8+Q9+R8+R9 -> 88 | W10: Pass | X10: 1 | Y10: 1 | Z10: 92 | AA10: Others - Others(VN) | AB10: =X8+X9+Y8+Y9 -> 92
A12: 2 | B12: Resultat_reel | C12: Dropout | D12: Fail | E12: Pass | F12: Pass - Pass (VP) | G12: =E15 -> 89 | H12: 11 | I12: Resultat_reel | J12: Dropout | K12: Fail | L12: Pass | M12: Pass - Pass (VP) | N12: =L15 -> 90 | O12: 20 | P12: Resultat_reel | Q12: Dropout | R12: Fail | S12: Pass | T12: Pass - Pass (VP) | U12: =S15 -> 91
B13: Dropout | C13: 68 | E13: 4 | F13: Pass - Others (FN) | G13: =D15+C15 -> 5 | I13: Dropout | J13: 62 | K13: 4 | L13: 6 | M13: Pass - Others (FN) | N13: =K15+J15 -> 4 | P13: Dropout | Q13: 66 | R13: 3 | S13: 3 | T13: Pass - Others (FN) | U13: =R15+Q15 -> 3
B14: Fail | C14: 22 | E14: 12 | F14: Others - Pass (FP) | G14: =E14+E13 -> 16 | I14: Fail | J14: 11 | K14: 9 | L14: 14 | M14: Others - Pass (FP) | N14: =L14+L13 -> 20 | P14: Fail | Q14: 16 | R14: 5 | S14: 13 | T14: Others - Pass (FP) | U14: =S14+S13 -> 16
B15: Pass | C15: 5 | E15: 89 | F15: Others - Others(VN) | G15: =C13+C14+D13+D14 -> 90 | I15: Pass | J15: 2 | K15: 2 | L15: 90 | M15: Others - Others(VN) | N15: =J13+J14+K13+K14 -> 86 | P15: Pass | Q15: 1 | R15: 2 | S15: 91 | T15: Others - Others(VN) | U15: =Q13+Q14+R13+R14 -> 90
A17: 3 | B17: Resultat_reel | C17: Dropout | D17: Fail | E17: Pass | F17: Pass - Pass (VP) | G17: =E20 -> 90 | H17: 12 | I17: Resultat_reel | J17: Dropout | K17: Fail | L17: Pass | M17: Pass - Pass (VP) | N17: =L20 -> 90 | O17: 21 | P17: Resultat_reel | Q17: Dropout | R17: Fail | S17: Pass | T17: Pass - Pass (VP) | U17: =S20 -> 93
B18: Dropout | C18: 63 | E18: 9 | F18: Pass - Others (FN) | G18: =D20+C20 -> 4 | I18: Dropout | J18: 62 | K18: 5 | L18: 5 | M18: Pass - Others (FN) | N18: =K20+J20 -> 4 | P18: Dropout | Q18: 65 | R18: 4 | S18: 3 | T18: Pass - Others (FN) | U18: =R20+Q20 -> 1
B19: Fail | C19: 21 | E19: 13 | F19: Others - Pass (FP) | G19: =E19+E18 -> 22 | I19: Fail | J19: 11 | K19: 8 | L19: 15 | M19: Others - Pass (FP) | N19: =L19+L18 -> 20 | P19: Fail | Q19: 14 | R19: 6 | S19: 14 | T19: Others - Pass (FP) | U19: =S19+S18 -> 17
B20: Pass | C20: 4 | E20: 90 | F20: Others - Others(VN) | G20: =C18+C19+D18+D19 -> 84 | I20: Pass | J20: 2 | K20: 2 | L20: 90 | M20: Others - Others(VN) | N20: =J18+J19+K18+K19 -> 86 | P20: Pass | Q20: 1 | S20: 93 | T20: Others - Others(VN) | U20: =Q18+Q19+R18+R19 -> 89
A22: 4 | B22: Resultat_reel | C22: Dropout | D22: Fail | E22: Pass | F22: Pass - Pass (VP) | G22: =E25 -> 90 | H22: 13 | I22: Resultat_reel | J22: Dropout | K22: Fail | L22: Pass | M22: Pass - Pass (VP) | N22: =L25 -> 90 | O22: 22 | P22: Resultat_reel | Q22: Dropout | R22: Fail | S22: Pass | T22: Pass - Pass (VP) | U22: =S25 -> 92
B23: Dropout | C23: 64 | E23: 8 | F23: Pass - Others (FN) | G23: =D25+C25 -> 4 | I23: Dropout | J23: 62 | K23: 5 | L23: 5 | M23: Pass - Others (FN) | N23: =K25+J25 -> 4 | P23: Dropout | Q23: 67 | R23: 3 | S23: 2 | T23: Pass - Others (FN) | U23: =R25+Q25 -> 2
B24: Fail | C24: 20 | E24: 14 | F24: Others - Pass (FP) | G24: =E24+E23 -> 22 | I24: Fail | J24: 11 | K24: 9 | L24: 14 | M24: Others - Pass (FP) | N24: =L24+L23 -> 19 | P24: Fail | Q24: 14 | R24: 6 | S24: 14 | T24: Others - Pass (FP) | U24: =S24+S23 -> 16
B25: Pass | C25: 4 | E25: 90 | F25: Others - Others(VN) | G25: =C23+C24+D23+D24 -> 84 | I25: Pass | J25: 3 | K25: 1 | L25: 90 | M25: Others - Others(VN) | N25: =J23+J24+K23+K24 -> 87 | P25: Pass | Q25: 1 | R25: 1 | S25: 92 | T25: Others - Others(VN) | U25: =Q23+Q24+R23+R24 -> 90
A27: 5 | B27: Resultat_reel | C27: Dropout | D27: Fail | E27: Pass | F27: Pass - Pass (VP) | G27: =E30 -> 91 | H27: 14 | I27: Resultat_reel | J27: Dropout | K27: Fail | L27: Pass | M27: Pass - Pass (VP) | N27: =L30 -> 90 | O27: 23 | P27: Resultat_reel | Q27: Dropout | R27: Fail | S27: Pass | T27: Pass - Pass (VP) | U27: =S30 -> 92
B28: Dropout | C28: 55 | D28: 6 | E28: 11 | F28: Pass - Others (FN) | G28: =D30+C30 -> 3 | I28: Dropout | J28: 64 | K28: 3 | L28: 5 | M28: Pass - Others (FN) | N28: =K30+J30 -> 4 | P28: Dropout | Q28: 65 | R28: 5 | S28: 2 | T28: Pass - Others (FN) | U28: =R30+Q30 -> 2
B29: Fail | C29: 14 | D29: 4 | E29: 16 | F29: Others - Pass (FP) | G29: =E29+E28 -> 27 | I29: Fail | J29: 14 | K29: 5 | L29: 15 | M29: Others - Pass (FP) | N29: =L29+L28 -> 20 | P29: Fail | Q29: 15 | R29: 6 | S29: 13 | T29: Others - Pass (FP) | U29: =S29+S28 -> 15
B30: Pass | C30: 3 | E30: 91 | F30: Others - Others(VN) | G30: =C28+C29+D28+D29 -> 79 | I30: Pass | J30: 3 | K30: 1 | L30: 90 | M30: Others - Others(VN) | N30: =J28+J29+K28+K29 -> 86 | P30: Pass | Q30: 1 | R30: 1 | S30: 92 | T30: Others - Others(VN) | U30: =Q28+Q29+R28+R29 -> 91
A32: 6 | B32: Resultat_reel | C32: Dropout | D32: Fail | E32: Pass | F32: Pass - Pass (VP) | G32: =E35 -> 90 | H32: 15 | I32: Resultat_reel | J32: Dropout | K32: Fail | L32: Pass | M32: Pass - Pass (VP) | N32: =L35 -> 93 | O32: 24 | P32: Resultat_reel | Q32: Dropout | R32: Fail | S32: Pass | T32: Pass - Pass (VP) | U32: =S35 -> 92
B33: Dropout | C33: 57 | D33: 7 | E33: 8 | F33: Pass - Others (FN) | G33: =D35+C35 -> 4 | I33: Dropout | J33: 67 | K33: 1 | L33: 4 | M33: Pass - Others (FN) | N33: =K35+J35 -> 1 | P33: Dropout | Q33: 67 | R33: 3 | S33: 2 | T33: Pass - Others (FN) | U33: =R35+Q35 -> 2
B34: Fail | C34: 14 | D34: 4 | E34: 16 | F34: Others - Pass (FP) | G34: =E34+E33 -> 24 | I34: Fail | J34: 15 | K34: 4 | L34: 15 | M34: Others - Pass (FP) | N34: =L34+L33 -> 19 | P34: Fail | Q34: 16 | R34: 5 | S34: 13 | T34: Others - Pass (FP) | U34: =S34+S33 -> 15
B35: Pass | C35: 4 | E35: 90 | F35: Others - Others(VN) | G35: =C33+C34+D33+D34 -> 82 | I35: Pass | J35: 1 | L35: 93 | M35: Others - Others(VN) | N35: =J33+J34+K33+K34 -> 87 | P35: Pass | Q35: 1 | R35: 1 | S35: 92 | T35: Others - Others(VN) | U35: =Q33+Q34+R33+R34 -> 91
A37: 7 | B37: Resultat_reel | C37: Dropout | D37: Fail | E37: Pass | F37: Pass - Pass (VP) | G37: =E40 -> 91 | H37: 16 | I37: Resultat_reel | J37: Dropout | K37: Fail | L37: Pass | M37: Pass - Pass (VP) | N37: =L40 -> 93 | O37: 25 | P37: Resultat_reel | Q37: Dropout | R37: Fail | S37: Pass | T37: Pass - Pass (VP) | U37: =S40 -> 92
B38: Dropout | C38: 53 | D38: 11 | E38: 8 | F38: Pass - Others (FN) | G38: =D40+C40 -> 3 | I38: Dropout | J38: 67 | K38: 1 | L38: 4 | M38: Pass - Others (FN) | N38: =K40+J40 -> 1 | P38: Dropout | Q38: 65 | R38: 5 | S38: 2 | T38: Pass - Others (FN) | U38: =R40+Q40 -> 2
B39: Fail | C39: 13 | D39: 5 | E39: 16 | F39: Others - Pass (FP) | G39: =E39+E38 -> 24 | I39: Fail | J39: 14 | K39: 5 | L39: 15 | M39: Others - Pass (FP) | N39: =L39+L38 -> 19 | P39: Fail | Q39: 16 | R39: 5 | S39: 13 | T39: Others - Pass (FP) | U39: =S39+S38 -> 15
B40: Pass | C40: 3 | E40: 91 | F40: Others - Others(VN) | G40: =C38+C39+D38+D39 -> 82 | I40: Pass | K40: 1 | L40: 93 | M40: Others - Others(VN) | N40: =J38+J39+K38+K39 -> 87 | P40: Pass | Q40: 1 | R40: 1 | S40: 92 | T40: Others - Others(VN) | U40: =Q38+Q39+R38+R39 -> 91
A42: 8 | B42: Resultat_reel | C42: Dropout | D42: Fail | E42: Pass | F42: Pass - Pass (VP) | G42: =E45 -> 91 | H42: 17 | I42: Resultat_reel | J42: Dropout | K42: Fail | L42: Pass | M42: Pass - Pass (VP) | N42: =L45 -> 92 | O42: 26 | P42: Resultat_reel | Q42: Dropout | R42: Fail | S42: Pass | T42: Pass - Pass (VP) | U42: =S45 -> 92
B43: Dropout | C43: 58 | D43: 7 | E43: 7 | F43: Pass - Others (FN) | G43: =D45+C45 -> 3 | I43: Dropout | J43: 64 | K43: 4 | L43: 4 | M43: Pass - Others (FN) | N43: =K45+J45 -> 2 | P43: Dropout | Q43: 65 | R43: 5 | S43: 2 | T43: Pass - Others (FN) | U43: =R45+Q45 -> 2
B44: Fail | C44: 15 | D44: 4 | E44: 15 | F44: Others - Pass (FP) | G44: =E44+E43 -> 22 | I44: Fail | J44: 15 | K44: 5 | L44: 14 | M44: Others - Pass (FP) | N44: =L44+L43 -> 18 | P44: Fail | Q44: 15 | R44: 6 | S44: 13 | T44: Others - Pass (FP) | U44: =S44+S43 -> 15
B45: Pass | C45: 1 | D45: 2 | E45: 91 | F45: Others - Others(VN) | G45: =C43+C44+D43+D44 -> 84 | I45: Pass | J45: 1 | K45: 1 | L45: 92 | M45: Others - Others(VN) | N45: =J43+J44+K43+K44 -> 88 | P45: Pass | Q45: 1 | R45: 1 | S45: 92 | T45: Others - Others(VN) | U45: =Q43+Q44+R43+R44 -> 91
B47: 1 | C47: 2 | D47: 3 | E47: 4 | F47: 5 | G47: 6 | H47: 7 | I47: 8 | J47: 9 | K47: 10 | L47: 11 | M47: 12 | N47: 13 | O47: 14 | P47: 15 | Q47: 16 | R47: 17 | S47: 18 | T47: 19 | U47: 20 | V47: 21 | W47: 22 | X47: 23 | Y47: 24 | Z47: 25 | AA47: 26 | AB47: 27 | AC47: 28 | AD47: 29
A48: Pass - Pass (VP) | B48: =G7 -> 89 | C48: =G12 -> 89 | D48: =G17 -> 90 | E48: =G22 -> 90 | F48: =G27 -> 91 | G48: =G32 -> 90 | H48: =G37 -> 91 | I48: =G42 -> 91 | J48: =N2 -> 91 | K48: =N7 -> 91 | L48: =N12 -> 90 | M48: =N17 -> 90 | N48: =N22 -> 90 | O48: =N27 -> 90 | P48: =N32 -> 93 | Q48: =N37 -> 93 | R48: =N42 -> 92 | S48: =U2 -> 92 | T48: =U7 -> 92 | U48: =U12 -> 91 | V48: =U17 -> 93 | W48: =U22 -> 92 | X48: =U27 -> 92 | Y48: =U32 -> 92 | Z48: =U37 -> 92 | AA48: =U42 -> 92 | AB48: =AB2 -> 92 | AC48: =AB7 -> 92 | AD48: =G2 -> 92
A49: Pass - Others (FN) | B49: =G8 -> 5 | C49: =G13 -> 5 | D49: =G18 -> 4 | E49: =G23 -> 4 | F49: =G28 -> 3 | G49: =G33 -> 4 | H49: =G38 -> 3 | I49: =G43 -> 3 | J49: =N3 -> 3 | K49: =N8 -> 3 | L49: =N13 -> 4 | M49: =N18 -> 4 | N49: =N23 -> 4 | O49: =N28 -> 4 | P49: =N33 -> 1 | Q49: =N38 -> 1 | R49: =N43 -> 2 | S49: =U3 -> 2 | T49: =U8 -> 2 | U49: =U13 -> 3 | V49: =U18 -> 1 | W49: =U23 -> 2 | X49: =U28 -> 2 | Y49: =U33 -> 2 | Z49: =U38 -> 2 | AA49: =U43 -> 2 | AB49: =AB3 -> 2 | AC49: =AB8 -> 2 | AD49: =G3 -> 2
A50: Others - Pass (FP) | B50: =G9 -> 16 | C50: =G14 -> 16 | D50: =G19 -> 22 | E50: =G24 -> 22 | F50: =G29 -> 27 | G50: =G34 -> 24 | H50: =G39 -> 24 | I50: =G44 -> 22 | J50: =N4 -> 23 | K50: =N9 -> 23 | L50: =N14 -> 20 | M50: =N19 -> 20 | N50: =N24 -> 19 | O50: =N29 -> 20 | P50: =N34 -> 19 | Q50: =N39 -> 19 | R50: =N44 -> 18 | S50: =U4 -> 18 | T50: =U9 -> 18 | U50: =U14 -> 16 | V50: =U19 -> 17 | W50: =U24 -> 16 | X50: =U29 -> 15 | Y50: =U34 -> 15 | Z50: =U39 -> 15 | AA50: =U44 -> 15 | AB50: =AB4 -> 14 | AC50: =AB9 -> 14 | AD50: =G4 -> 14
...

Sheet ResultsFail
A2: 29 | B2: Resultat_reel | C2: Dropout | D2: Fail | E2: Pass | F2: Fail - Fail (VP) | G2: =D4 -> 5 | H2: 9 | I2: Resultat_reel | J2: Dropout | K2: Fail | L2: Pass | M2: Fail - Fail (VP) | N2: =K4 -> 8 | O2: 18 | P2: Resultat_reel | Q2: Dropout | R2: Fail | S2: Pass | T2: Fail - Fail (VP) | U2: =R4 -> 6 | V2: 27 | W2: Resultat_reel | X2: Dropout | Y2: Fail | Z2: Pass | AA2: Fail - Fail (VP) | AB2: =Y4 -> 6
B3: Dropout | C3: 70 | D3: 1 | E3: 1 | F3: Fail - Others (FN) | G3: =C4+E4 -> 29 | I3: Dropout | J3: 59 | K3: 6 | L3: 7 | M3: Fail - Others (FN) | N3: =J4+L4 -> 26 | P3: Dropout | Q3: 67 | R3: 1 | S3: 4 | T3: Fail - Others (FN) | U3: =Q4+S4 -> 28 | W3: Dropout | X3: 69 | Y3: 2 | Z3: 1 | AA3: Fail - Others (FN) | AB3: =X4+Z4 -> 28
B4: Fail | C4: 16 | D4: 5 | E4: 13 | F4: Others - Fail (FP) | G4: =D3+D5 -> 2 | I4: Fail | J4: 10 | K4: 8 | L4: 16 | M4: Others - Fail (FP) | N4: =K3+K5 -> 8 | P4: Fail | Q4: 14 | R4: 6 | S4: 14 | T4: Others - Fail (FP) | U4: =R3+R5 -> 2 | W4: Fail | X4: 15 | Y4: 6 | Z4: 13 | AA4: Others - Fail (FP) | AB4: =Y3+Y5 -> 3
B5: Pass | C5: 1 | D5: 1 | E5: 92 | F5: Others - Others(VN) | G5: =C3+E3+C5+E5 -> 164 | I5: Pass | J5: 1 | K5: 2 | L5: 91 | M5: Others - Others(VN) | N5: =J3+L3+J5+L5 -> 158 | P5: Pass | Q5: 1 | R5: 1 | S5: 92 | T5: Others - Others(VN) | U5: =Q3+S3+Q5+S5 -> 164 | W5: Pass | X5: 1 | Y5: 1 | Z5: 92 | AA5: Others - Others(VN) | AB5: =X3+Z3+X5+Z5 -> 163
A7: 1 | B7: Resultat_reel | C7: Dropout | D7: Fail | E7: Pass | F7: Fail - Fail (VP) | G7: =D9 -> 0 | H7: 10 | I7: Resultat_reel | J7: Dropout | K7: Fail | L7: Pass | M7: Fail - Fail (VP) | N7: =K9 -> 10 | O7: 19 | P7: Resultat_reel | Q7: Dropout | R7: Fail | S7: Pass | T7: Fail - Fail (VP) | U7: =R9 -> 5 | V7: 28 | W7: Resultat_reel | X7: Dropout | Y7: Fail | Z7: Pass | AA7: Fail - Fail (VP) | AB7: =Y9 -> 6
B8: Dropout | C8: 68 | E8: 4 | F8: Fail - Others (FN) | G8: =C9+E9 -> 34 | I8: Dropout | J8: 58 | K8: 7 | L8: 7 | M8: Fail - Others (FN) | N8: =J9+L9 -> 24 | P8: Dropout | Q8: 65 | R8: 3 | S8: 4 | T8: Fail - Others (FN) | U8: =Q9+S9 -> 29 | W8: Dropout | X8: 69 | Y8: 2 | Z8: 1 | AA8: Fail - Others (FN) | AB8: =X9+Z9 -> 28
B9: Fail | C9: 22 | E9: 12 | F9: Others - Fail (FP) | G9: =D8+D10 -> 0 | I9: Fail | J9: 8 | K9: 10 | L9: 16 | M9: Others - Fail (FP) | N9: =K8+K10 -> 9 | P9: Fail | Q9: 15 | R9: 5 | S9: 14 | T9: Others - Fail (FP) | U9: =R8+R10 -> 4 | W9: Fail | X9: 15 | Y9: 6 | Z9: 13 | AA9: Others - Fail (FP) | AB9: =Y8+Y10 -> 3
B10: Pass | C10: 5 | E10: 89 | F10: Others - Others(VN) | G10: =C8+E8+C10+E10 -> 166 | I10: Pass | J10: 1 | K10: 2 | L10: 91 | M10: Others - Others(VN) | N10: =J8+L8+J10+L10 -> 157 | P10: Pass | Q10: 1 | R10: 1 | S10: 92 | T10: Others - Others(VN) | U10: =Q8+S8+Q10+S10 -> 162 | W10: Pass | X10: 1 | Y10: 1 | Z10: 92 | AA10: Others - Others(VN) | AB10: =X8+Z8+X10+Z10 -> 163
A12: 2 | B12: Resultat_reel | C12: Dropout | D12: Fail | E12: Pass | F12: Fail - Fail (VP) | G12: =D14 -> 0 | H12: 11 | I12: Resultat_reel | J12: Dropout | K12: Fail | L12: Pass | M12: Fail - Fail (VP) | N12: =K14 -> 9 | O12: 20 | P12: Resultat_reel | Q12: Dropout | R12: Fail | S12: Pass | T12: Fail - Fail (VP) | U12: =R14 -> 5
B13: Dropout | C13: 68 | E13: 4 | F13: Fail - Others (FN) | G13: =C14+E14 -> 34 | I13: Dropout | J13: 62 | K13: 4 | L13: 6 | M13: Fail - Others (FN) | N13: =J14+L14 -> 25 | P13: Dropout | Q13: 66 | R13: 3 | S13: 3 | T13: Fail - Others (FN) | U13: =Q14+S14 -> 29
B14: Fail | C14: 22 | E14: 12 | F14: Others - Fail (FP) | G14: =D13+D15 -> 0 | I14: Fail | J14: 11 | K14: 9 | L14: 14 | M14: Others - Fail (FP) | N14: =K13+K15 -> 6 | P14: Fail | Q14: 16 | R14: 5 | S14: 13 | T14: Others - Fail (FP) | U14: =R13+R15 -> 5
B15: Pass | C15: 5 | E15: 89 | F15: Others - Others(VN) | G15: =C13+E13+C15+E15 -> 166 | I15: Pass | J15: 2 | K15: 2 | L15: 90 | M15: Others - Others(VN) | N15: =J13+L13+J15+L15 -> 160 | P15: Pass | Q15: 1 | R15: 2 | S15: 91 | T15: Others - Others(VN) | U15: =Q13+S13+Q15+S15 -> 161
A17: 3 | B17: Resultat_reel | C17: Dropout | D17: Fail | E17: Pass | F17: Fail - Fail (VP) | G17: =D19 -> 0 | H17: 12 | I17: Resultat_reel | J17: Dropout | K17: Fail | L17: Pass | M17: Fail - Fail (VP) | N17: =K19 -> 8 | O17: 21 | P17: Resultat_reel | Q17: Dropout | R17: Fail | S17: Pass | T17: Fail - Fail (VP) | U17: =R19 -> 6
B18: Dropout | C18: 63 | E18: 9 | F18: Fail - Others (FN) | G18: =C19+E19 -> 34 | I18: Dropout | J18: 62 | K18: 5 | L18: 5 | M18: Fail - Others (FN) | N18: =J19+L19 -> 26 | P18: Dropout | Q18: 65 | R18: 4 | S18: 3 | T18: Fail - Others (FN) | U18: =Q19+S19 -> 28
B19: Fail | C19: 21 | E19: 13 | F19: Others - Fail (FP) | G19: =D18+D20 -> 0 | I19: Fail | J19: 11 | K19: 8 | L19: 15 | M19: Others - Fail (FP) | N19: =K18+K20 -> 7 | P19: Fail | Q19: 14 | R19: 6 | S19: 14 | T19: Others - Fail (FP) | U19: =R18+R20 -> 4
B20: Pass | C20: 4 | E20: 90 | F20: Others - Others(VN) | G20: =C18+E18+C20+E20 -> 166 | I20: Pass | J20: 2 | K20: 2 | L20: 90 | M20: Others - Others(VN) | N20: =J18+L18+J20+L20 -> 159 | P20: Pass | Q20: 1 | S20: 93 | T20: Others - Others(VN) | U20: =Q18+S18+Q20+S20 -> 162
A22: 4 | B22: Resultat_reel | C22: Dropout | D22: Fail | E22: Pass | F22: Fail - Fail (VP) | G22: =D24 -> 0 | H22: 13 | I22: Resultat_reel | J22: Dropout | K22: Fail | L22: Pass | M22: Fail - Fail (VP) | N22: =K24 -> 9 | O22: 22 | P22: Resultat_reel | Q22: Dropout | R22: Fail | S22: Pass | T22: Fail - Fail (VP) | U22: =R24 -> 6
B23: Dropout | C23: 64 | E23: 8 | F23: Fail - Others (FN) | G23: =C24+E24 -> 34 | I23: Dropout | J23: 62 | K23: 5 | L23: 5 | M23: Fail - Others (FN) | N23: =J24+L24 -> 25 | P23: Dropout | Q23: 67 | R23: 3 | S23: 2 | T23: Fail - Others (FN) | U23: =Q24+S24 -> 28
B24: Fail | C24: 20 | E24: 14 | F24: Others - Fail (FP) | G24: =D23+D25 -> 0 | I24: Fail | J24: 11 | K24: 9 | L24: 14 | M24: Others - Fail (FP) | N24: =K23+K25 -> 6 | P24: Fail | Q24: 14 | R24: 6 | S24: 14 | T24: Others - Fail (FP) | U24: =R23+R25 -> 4
B25: Pass | C25: 4 | E25: 90 | F25: Others - Others(VN) | G25: =C23+E23+C25+E25 -> 166 | I25: Pass | J25: 3 | K25: 1 | L25: 90 | M25: Others - Others(VN) | N25: =J23+L23+J25+L25 -> 160 | P25: Pass | Q25: 1 | R25: 1 | S25: 92 | T25: Others - Others(VN) | U25: =Q23+S23+Q25+S25 -> 162
A27: 5 | B27: Resultat_reel | C27: Dropout | D27: Fail | E27: Pass | F27: Fail - Fail (VP) | G27: =D29 -> 4 | H27: 14 | I27: Resultat_reel | J27: Dropout | K27: Fail | L27: Pass | M27: Fail - Fail (VP) | N27: =K29 -> 5 | O27: 23 | P27: Resultat_reel | Q27: Dropout | R27: Fail | S27: Pass | T27: Fail - Fail (VP) | U27: =R29 -> 6
B28: Dropout | C28: 55 | D28: 6 | E28: 11 | F28: Fail - Others (FN) | G28: =C29+E29 -> 30 | I28: Dropout | J28: 64 | K28: 3 | L28: 5 | M28: Fail - Others (FN) | N28: =J29+L29 -> 29 | P28: Dropout | Q28: 65 | R28: 5 | S28: 2 | T28: Fail - Others (FN) | U28: =Q29+S29 -> 28
B29: Fail | C29: 14 | D29: 4 | E29: 16 | F29: Others - Fail (FP) | G29: =D28+D30 -> 6 | I29: Fail | J29: 14 | K29: 5 | L29: 15 | M29: Others - Fail (FP) | N29: =K28+K30 -> 4 | P29: Fail | Q29: 15 | R29: 6 | S29: 13 | T29: Others - Fail (FP) | U29: =R28+R30 -> 6
B30: Pass | C30: 3 | E30: 91 | F30: Others - Others(VN) | G30: =C28+E28+C30+E30 -> 160 | I30: Pass | J30: 3 | K30: 1 | L30: 90 | M30: Others - Others(VN) | N30: =J28+L28+J30+L30 -> 162 | P30: Pass | Q30: 1 | R30: 1 | S30: 92 | T30: Others - Others(VN) | U30: =Q28+S28+Q30+S30 -> 160
A32: 6 | B32: Resultat_reel | C32: Dropout | D32: Fail | E32: Pass | F32: Fail - Fail (VP) | G32: =D34 -> 4 | H32: 15 | I32: Resultat_reel | J32: Dropout | K32: Fail | L32: Pass | M32: Fail - Fail (VP) | N32: =K34 -> 4 | O32: 24 | P32: Resultat_reel | Q32: Dropout | R32: Fail | S32: Pass | T32: Fail - Fail (VP) | U32: =R34 -> 5
B33: Dropout | C33: 57 | D33: 7 | E33: 8 | F33: Fail - Others (FN) | G33: =C34+E34 -> 30 | I33: Dropout | J33: 67 | K33: 1 | L33: 4 | M33: Fail - Others (FN) | N33: =J34+L34 -> 30 | P33: Dropout | Q33: 67 | R33: 3 | S33: 2 | T33: Fail - Others (FN) | U33: =Q34+S34 -> 29
B34: Fail | C34: 14 | D34: 4 | E34: 16 | F34: Others - Fail (FP) | G34: =D33+D35 -> 7 | I34: Fail | J34: 15 | K34: 4 | L34: 15 | M34: Others - Fail (FP) | N34: =K33+K35 -> 1 | P34: Fail | Q34: 16 | R34: 5 | S34: 13 | T34: Others - Fail (FP) | U34: =R33+R35 -> 4
B35: Pass | C35: 4 | E35: 90 | F35: Others - Others(VN) | G35: =C33+E33+C35+E35 -> 159 | I35: Pass | J35: 1 | L35: 93 | M35: Others - Others(VN) | N35: =J33+L33+J35+L35 -> 165 | P35: Pass | Q35: 1 | R35: 1 | S35: 92 | T35: Others - Others(VN) | U35: =Q33+S33+Q35+S35 -> 162
A37: 7 | B37: Resultat_reel | C37: Dropout | D37: Fail | E37: Pass | F37: Fail - Fail (VP) | G37: =D39 -> 5 | H37: 16 | I37: Resultat_reel | J37: Dropout | K37: Fail | L37: Pass | M37: Fail - Fail (VP) | N37: =K39 -> 5 | O37: 25 | P37: Resultat_reel | Q37: Dropout | R37: Fail | S37: Pass | T37: Fail - Fail (VP) | U37: =R39 -> 5
B38: Dropout | C38: 53 | D38: 11 | E38: 8 | F38: Fail - Others (FN) | G38: =C39+E39 -> 29 | I38: Dropout | J38: 67 | K38: 1 | L38: 4 | M38: Fail - Others (FN) | N38: =J39+L39 -> 29 | P38: Dropout | Q38: 65 | R38: 5 | S38: 2 | T38: Fail - Others (FN) | U38: =Q39+S39 -> 29
B39: Fail | C39: 13 | D39: 5 | E39: 16 | F39: Others - Fail (FP) | G39: =D38+D40 -> 11 | I39: Fail | J39: 14 | K39: 5 | L39: 15 | M39: Others - Fail (FP) | N39: =K38+K40 -> 2 | P39: Fail | Q39: 16 | R39: 5 | S39: 13 | T39: Others - Fail (FP) | U39: =R38+R40 -> 6
B40: Pass | C40: 3 | E40: 91 | F40: Others - Others(VN) | G40: =C38+E38+C40+E40 -> 155 | I40: Pass | K40: 1 | L40: 93 | M40: Others - Others(VN) | N40: =J38+L38+J40+L40 -> 164 | P40: Pass | Q40: 1 | R40: 1 | S40: 92 | T40: Others - Others(VN) | U40: =Q38+S38+Q40+S40 -> 160
A42: 8 | B42: Resultat_reel | C42: Dropout | D42: Fail | E42: Pass | F42: Fail - Fail (VP) | G42: =D44 -> 4 | H42: 17 | I42: Resultat_reel | J42: Dropout | K42: Fail | L42: Pass | M42: Fail - Fail (VP) | N42: =K44 -> 5 | O42: 26 | P42: Resultat_reel | Q42: Dropout | R42: Fail | S42: Pass | T42: Fail - Fail (VP) | U42: =R44 -> 6
B43: Dropout | C43: 58 | D43: 7 | E43: 7 | F43: Fail - Others (FN) | G43: =C44+E44 -> 30 | I43: Dropout | J43: 64 | K43: 4 | L43: 4 | M43: Fail - Others (FN) | N43: =J44+L44 -> 29 | P43: Dropout | Q43: 65 | R43: 5 | S43: 2 | T43: Fail - Others (FN) | U43: =Q44+S44 -> 28
B44: Fail | C44: 15 | D44: 4 | E44: 15 | F44: Others - Fail (FP) | G44: =D43+D45 -> 9 | I44: Fail | J44: 15 | K44: 5 | L44: 14 | M44: Others - Fail (FP) | N44: =K43+K45 -> 5 | P44: Fail | Q44: 15 | R44: 6 | S44: 13 | T44: Others - Fail (FP) | U44: =R43+R45 -> 6
B45: Pass | C45: 1 | D45: 2 | E45: 91 | F45: Others - Others(VN) | G45: =C43+E43+C45+E45 -> 157 | I45: Pass | J45: 1 | K45: 1 | L45: 92 | M45: Others - Others(VN) | N45: =J43+L43+J45+L45 -> 161 | P45: Pass | Q45: 1 | R45: 1 | S45: 92 | T45: Others - Others(VN) | U45: =Q43+S43+Q45+S45 -> 160
B47: 1 | C47: 2 | D47: 3 | E47: 4 | F47: 5 | G47: 6 | H47: 7 | I47: 8 | J47: 9 | K47: 10 | L47: 11 | M47: 12 | N47: 13 | O47: 14 | P47: 15 | Q47: 16 | R47: 17 | S47: 18 | T47: 19 | U47: 20 | V47: 21 | W47: 22 | X47: 23 | Y47: 24 | Z47: 25 | AA47: 26 | AB47: 27 | AC47: 28 | AD47: 29
A48: Pass - Pass (VP) | B48: =G7 -> 0 | C48: =G12 -> 0 | D48: =G17 -> 0 | E48: =G22 -> 0 | F48: =G27 -> 4 | G48: =G32 -> 4 | H48: =G37 -> 5 | I48: =G42 -> 4 | J48: =N2 -> 8 | K48: =N7 -> 10 | L48: =N12 -> 9 | M48: =N17 -> 8 | N48: =N22 -> 9 | O48: =N27 -> 5 | P48: =N32 -> 4 | Q48: =N37 -> 5 | R48: =N42 -> 5 | S48: =U2 -> 6 | T48: =U7 -> 5 | U48: =U12 -> 5 | V48: =U17 -> 6 | W48: =U22 -> 6 | X48: =U27 -> 6 | Y48: =U32 -> 5 | Z48: =U37 -> 5 | AA48: =U42 -> 6 | AB48: =AB2 -> 6 | AC48: =AB7 -> 6 | AD48: =G2 -> 5
A49: Pass - Others (FN) | B49: =G8 -> 34 | C49: =G13 -> 34 | D49: =G18 -> 34 | E49: =G23 -> 34 | F49: =G28 -> 30 | G49: =G33 -> 30 | H49: =G38 -> 29 | I49: =G43 -> 30 | J49: =N3 -> 26 | K49: =N8 -> 24 | L49: =N13 -> 25 | M49: =N18 -> 26 | N49: =N23 -> 25 | O49: =N28 -> 29 | P49: =N33 -> 30 | Q49: =N38 -> 29 | R49: =N43 -> 29 | S49: =U3 -> 28 | T49: =U8 -> 29 | U49: =U13 -> 29 | V49: =U18 -> 28 | W49: =U23 -> 28 | X49: =U28 -> 28 | Y49: =U33 -> 29 | Z49: =U38 -> 29 | AA49: =U43 -> 28 | AB49: =AB3 -> 28 | AC49: =AB8 -> 28 | AD49: =G3 -> 29
A50: Others - Pass (FP) | B50: =G9 -> 0 | C50: =G14 -> 0 | D50: =G19 -> 0 | E50: =G24 -> 0 | F50: =G29 -> 6 | G50: =G34 -> 7 | H50: =G39 -> 11 | I50: =G44 -> 9 | J50: =N4 -> 8 | K50: =N9 -> 9 | L50: =N14 -> 6 | M50: =N19 -> 7 | N50: =N24 -> 6 | O50: =N29 -> 4 | P50: =N34 -> 1 | Q50: =N39 -> 2 | R50: =N44 -> 5 | S50: =U4 -> 2 | T50: =U9 -> 4 | U50: =U14 -> 5 | V50: =U19 -> 4 | W50: =U24 -> 4 | X50: =U29 -> 6 | Y50: =U34 -> 4 | Z50: =U39 -> 6 | AA50: =U44 -> 6 | AB50: =AB4 -> 3 | AC50: =AB9 -> 3 | AD50: =G4 -> 2
...

Sheet ResultsDropout
A2: 29 | B2: Resultat_reel | C2: Dropout | D2: Fail | E2: Pass | F2: Do - Do (VP) | G2: =C3 -> 70 | H2: 9 | I2: Resultat_reel | J2: Dropout | K2: Fail | L2: Pass | M2: Do - Do (VP) | N2: =J3 -> 59 | O2: 18 | P2: Resultat_reel | Q2: Dropout | R2: Fail | S2: Pass | T2: Do - Do (VP) | U2: =Q3 -> 67 | V2: 27 | W2: Resultat_reel | X2: Dropout | Y2: Fail | Z2: Pass | AA2: Do - Do (VP) | AB2: =X3 -> 69
B3: Dropout | C3: 70 | D3: 1 | E3: 1 | F3: Do - Others (FN) | G3: =D3+E3 -> 2 | I3: Dropout | J3: 59 | K3: 6 | L3: 7 | M3: Do - Others (FN) | N3: =K3+L3 -> 13 | P3: Dropout | Q3: 67 | R3: 1 | S3: 4 | T3: Do - Others (FN) | U3: =R3+S3 -> 5 | W3: Dropout | X3: 69 | Y3: 2 | Z3: 1 | AA3: Do - Others (FN) | AB3: =Y3+Z3 -> 3
B4: Fail | C4: 16 | D4: 5 | E4: 13 | F4: Others - Do (FP) | G4: =C4+C5 -> 17 | I4: Fail | J4: 10 | K4: 8 | L4: 16 | M4: Others - Do (FP) | N4: =J4+J5 -> 11 | P4: Fail | Q4: 14 | R4: 6 | S4: 14 | T4: Others - Do (FP) | U4: =Q4+Q5 -> 15 | W4: Fail | X4: 15 | Y4: 6 | Z4: 13 | AA4: Others - Do (FP) | AB4: =X4+X5 -> 16
B5: Pass | C5: 1 | D5: 1 | E5: 92 | F5: Others - Others(VN) | G5: =D4+E4+D5+E5 -> 111 | I5: Pass | J5: 1 | K5: 2 | L5: 91 | M5: Others - Others(VN) | N5: =K4+L4+K5+L5 -> 117 | P5: Pass | Q5: 1 | R5: 1 | S5: 92 | T5: Others - Others(VN) | U5: =R4+S4+R5+S5 -> 113 | W5: Pass | X5: 1 | Y5: 1 | Z5: 92 | AA5: Others - Others(VN) | AB5: =Y4+Z4+Y5+Z5 -> 112
A7: 1 | B7: Resultat_reel | C7: Dropout | D7: Fail | E7: Pass | F7: Do - Do (VP) | G7: =C8 -> 68 | H7: 10 | I7: Resultat_reel | J7: Dropout | K7: Fail | L7: Pass | M7: Do - Do (VP) | N7: =J8 -> 58 | O7: 19 | P7: Resultat_reel | Q7: Dropout | R7: Fail | S7: Pass | T7: Do - Do (VP) | U7: =Q8 -> 65 | V7: 28 | W7: Resultat_reel | X7: Dropout | Y7: Fail | Z7: Pass | AA7: Do - Do (VP) | AB7: =X8 -> 69
B8: Dropout | C8: 68 | E8: 4 | F8: Do - Others (FN) | G8: =D8+E8 -> 4 | I8: Dropout | J8: 58 | K8: 7 | L8: 7 | M8: Do - Others (FN) | N8: =K8+L8 -> 14 | P8: Dropout | Q8: 65 | R8: 3 | S8: 4 | T8: Do - Others (FN) | U8: =R8+S8 -> 7 | W8: Dropout | X8: 69 | Y8: 2 | Z8: 1 | AA8: Do - Others (FN) | AB8: =Y8+Z8 -> 3
B9: Fail | C9: 22 | E9: 12 | F9: Others - Do (FP) | G9: =C9+C10 -> 27 | I9: Fail | J9: 8 | K9: 10 | L9: 16 | M9: Others - Do (FP) | N9: =J9+J10 -> 9 | P9: Fail | Q9: 15 | R9: 5 | S9: 14 | T9: Others - Do (FP) | U9: =Q9+Q10 -> 16 | W9: Fail | X9: 15 | Y9: 6 | Z9: 13 | AA9: Others - Do (FP) | AB9: =X9+X10 -> 16
B10: Pass | C10: 5 | E10: 89 | F10: Others - Others(VN) | G10: =D9+E9+D10+E10 -> 101 | I10: Pass | J10: 1 | K10: 2 | L10: 91 | M10: Others - Others(VN) | N10: =K9+L9+K10+L10 -> 119 | P10: Pass | Q10: 1 | R10: 1 | S10: 92 | T10: Others - Others(VN) | U10: =R9+S9+R10+S10 -> 112 | W10: Pass | X10: 1 | Y10: 1 | Z10: 92 | AA10: Others - Others(VN) | AB10: =Y9+Z9+Y10+Z10 -> 112
A12: 2 | B12: Resultat_reel | C12: Dropout | D12: Fail | E12: Pass | F12: Do - Do (VP) | G12: =C13 -> 68 | H12: 11 | I12: Resultat_reel | J12: Dropout | K12: Fail | L12: Pass | M12: Do - Do (VP) | N12: =J13 -> 62 | O12: 20 | P12: Resultat_reel | Q12: Dropout | R12: Fail | S12: Pass | T12: Do - Do (VP) | U12: =Q13 -> 66
B13: Dropout | C13: 68 | E13: 4 | F13: Do - Others (FN) | G13: =D13+E13 -> 4 | I13: Dropout | J13: 62 | K13: 4 | L13: 6 | M13: Do - Others (FN) | N13: =K13+L13 -> 10 | P13: Dropout | Q13: 66 | R13: 3 | S13: 3 | T13: Do - Others (FN) | U13: =R13+S13 -> 6
B14: Fail | C14: 22 | E14: 12 | F14: Others - Do (FP) | G14: =C14+C15 -> 27 | I14: Fail | J14: 11 | K14: 9 | L14: 14 | M14: Others - Do (FP) | N14: =J14+J15 -> 13 | P14: Fail | Q14: 16 | R14: 5 | S14: 13 | T14: Others - Do (FP) | U14: =Q14+Q15 -> 17
B15: Pass | C15: 5 | E15: 89 | F15: Others - Others(VN) | G15: =D14+E14+D15+E15 -> 101 | I15: Pass | J15: 2 | K15: 2 | L15: 90 | M15: Others - Others(VN) | N15: =K14+L14+K15+L15 -> 115 | P15: Pass | Q15: 1 | R15: 2 | S15: 91 | T15: Others - Others(VN) | U15: =R14+S14+R15+S15 -> 111
A17: 3 | B17: Resultat_reel | C17: Dropout | D17: Fail | E17: Pass | F17: Do - Do (VP) | G17: =C18 -> 63 | H17: 12 | I17: Resultat_reel | J17: Dropout | K17: Fail | L17: Pass | M17: Do - Do (VP) | N17: =J18 -> 62 | O17: 21 | P17: Resultat_reel | Q17: Dropout | R17: Fail | S17: Pass | T17: Do - Do (VP) | U17: =Q18 -> 65
B18: Dropout | C18: 63 | E18: 9 | F18: Do - Others (FN) | G18: =D18+E18 -> 9 | I18: Dropout | J18: 62 | K18: 5 | L18: 5 | M18: Do - Others (FN) | N18: =K18+L18 -> 10 | P18: Dropout | Q18: 65 | R18: 4 | S18: 3 | T18: Do - Others (FN) | U18: =R18+S18 -> 7
B19: Fail | C19: 21 | E19: 13 | F19: Others - Do (FP) | G19: =C19+C20 -> 25 | I19: Fail | J19: 11 | K19: 8 | L19: 15 | M19: Others - Do (FP) | N19: =J19+J20 -> 13 | P19: Fail | Q19: 14 | R19: 6 | S19: 14 | T19: Others - Do (FP) | U19: =Q19+Q20 -> 15
B20: Pass | C20: 4 | E20: 90 | F20: Others - Others(VN) | G20: =D19+E19+D20+E20 -> 103 | I20: Pass | J20: 2 | K20: 2 | L20: 90 | M20: Others - Others(VN) | N20: =K19+L19+K20+L20 -> 115 | P20: Pass | Q20: 1 | S20: 93 | T20: Others - Others(VN) | U20: =R19+S19+R20+S20 -> 113
A22: 4 | B22: Resultat_reel | C22: Dropout | D22: Fail | E22: Pass | F22: Do - Do (VP) | G22: =C23 -> 64 | H22: 13 | I22: Resultat_reel | J22: Dropout | K22: Fail | L22: Pass | M22: Do - Do (VP) | N22: =J23 -> 62 | O22: 22 | P22: Resultat_reel | Q22: Dropout | R22: Fail | S22: Pass | T22: Do - Do (VP) | U22: =Q23 -> 67
B23: Dropout | C23: 64 | E23: 8 | F23: Do - Others (FN) | G23: =D23+E23 -> 8 | I23: Dropout | J23: 62 | K23: 5 | L23: 5 | M23: Do - Others (FN) | N23: =K23+L23 -> 10 | P23: Dropout | Q23: 67 | R23: 3 | S23: 2 | T23: Do - Others (FN) | U23: =R23+S23 -> 5
B24: Fail | C24: 20 | E24: 14 | F24: Others - Do (FP) | G24: =C24+C25 -> 24 | I24: Fail | J24: 11 | K24: 9 | L24: 14 | M24: Others - Do (FP) | N24: =J24+J25 -> 14 | P24: Fail | Q24: 14 | R24: 6 | S24: 14 | T24: Others - Do (FP) | U24: =Q24+Q25 -> 15
B25: Pass | C25: 4 | E25: 90 | F25: Others - Others(VN) | G25: =D24+E24+D25+E25 -> 104 | I25: Pass | J25: 3 | K25: 1 | L25: 90 | M25: Others - Others(VN) | N25: =K24+L24+K25+L25 -> 114 | P25: Pass | Q25: 1 | R25: 1 | S25: 92 | T25: Others - Others(VN) | U25: =R24+S24+R25+S25 -> 113
A27: 5 | B27: Resultat_reel | C27: Dropout | D27: Fail | E27: Pass | F27: Do - Do (VP) | G27: =C28 -> 55 | H27: 14 | I27: Resultat_reel | J27: Dropout | K27: Fail | L27: Pass | M27: Do - Do (VP) | N27: =J28 -> 64 | O27: 23 | P27: Resultat_reel | Q27: Dropout | R27: Fail | S27: Pass | T27: Do - Do (VP) | U27: =Q28 -> 65
B28: Dropout | C28: 55 | D28: 6 | E28: 11 | F28: Do - Others (FN) | G28: =D28+E28 -> 17 | I28: Dropout | J28: 64 | K28: 3 | L28: 5 | M28: Do - Others (FN) | N28: =K28+L28 -> 8 | P28: Dropout | Q28: 65 | R28: 5 | S28: 2 | T28: Do - Others (FN) | U28: =R28+S28 -> 7
B29: Fail | C29: 14 | D29: 4 | E29: 16 | F29: Others - Do (FP) | G29: =C29+C30 -> 17 | I29: Fail | J29: 14 | K29: 5 | L29: 15 | M29: Others - Do (FP) | N29: =J29+J30 -> 17 | P29: Fail | Q29: 15 | R29: 6 | S29: 13 | T29: Others - Do (FP) | U29: =Q29+Q30 -> 16
B30: Pass | C30: 3 | E30: 91 | F30: Others - Others(VN) | G30: =D29+E29+D30+E30 -> 111 | I30: Pass | J30: 3 | K30: 1 | L30: 90 | M30: Others - Others(VN) | N30: =K29+L29+K30+L30 -> 111 | P30: Pass | Q30: 1 | R30: 1 | S30: 92 | T30: Others - Others(VN) | U30: =R29+S29+R30+S30 -> 112
A32: 6 | B32: Resultat_reel | C32: Dropout | D32: Fail | E32: Pass | F32: Do - Do (VP) | G32: =C33 -> 57 | H32: 15 | I32: Resultat_reel | J32: Dropout | K32: Fail | L32: Pass | M32: Do - Do (VP) | N32: =J33 -> 67 | O32: 24 | P32: Resultat_reel | Q32: Dropout | R32: Fail | S32: Pass | T32: Do - Do (VP) | U32: =Q33 -> 67
B33: Dropout | C33: 57 | D33: 7 | E33: 8 | F33: Do - Others (FN) | G33: =D33+E33 -> 15 | I33: Dropout | J33: 67 | K33: 1 | L33: 4 | M33: Do - Others (FN) | N33: =K33+L33 -> 5 | P33: Dropout | Q33: 67 | R33: 3 | S33: 2 | T33: Do - Others (FN) | U33: =R33+S33 -> 5
B34: Fail | C34: 14 | D34: 4 | E34: 16 | F34: Others - Do (FP) | G34: =C34+C35 -> 18 | I34: Fail | J34: 15 | K34: 4 | L34: 15 | M34: Others - Do (FP) | N34: =J34+J35 -> 16 | P34: Fail | Q34: 16 | R34: 5 | S34: 13 | T34: Others - Do (FP) | U34: =Q34+Q35 -> 17
B35: Pass | C35: 4 | E35: 90 | F35: Others - Others(VN) | G35: =D34+E34+D35+E35 -> 110 | I35: Pass | J35: 1 | L35: 93 | M35: Others - Others(VN) | N35: =K34+L34+K35+L35 -> 112 | P35: Pass | Q35: 1 | R35: 1 | S35: 92 | T35: Others - Others(VN) | U35: =R34+S34+R35+S35 -> 111
A37: 7 | B37: Resultat_reel | C37: Dropout | D37: Fail | E37: Pass | F37: Do - Do (VP) | G37: =C38 -> 53 | H37: 16 | I37: Resultat_reel | J37: Dropout | K37: Fail | L37: Pass | M37: Do - Do (VP) | N37: =J38 -> 67 | O37: 25 | P37: Resultat_reel | Q37: Dropout | R37: Fail | S37: Pass | T37: Do - Do (VP) | U37: =Q38 -> 65
B38: Dropout | C38: 53 | D38: 11 | E38: 8 | F38: Do - Others (FN) | G38: =D38+E38 -> 19 | I38: Dropout | J38: 67 | K38: 1 | L38: 4 | M38: Do - Others (FN) | N38: =K38+L38 -> 5 | P38: Dropout | Q38: 65 | R38: 5 | S38: 2 | T38: Do - Others (FN) | U38: =R38+S38 -> 7
B39: Fail | C39: 13 | D39: 5 | E39: 16 | F39: Others - Do (FP) | G39: =C39+C40 -> 16 | I39: Fail | J39: 14 | K39: 5 | L39: 15 | M39: Others - Do (FP) | N39: =J39+J40 -> 14 | P39: Fail | Q39: 16 | R39: 5 | S39: 13 | T39: Others - Do (FP) | U39: =Q39+Q40 -> 17
B40: Pass | C40: 3 | E40: 91 | F40: Others - Others(VN) | G40: =D39+E39+D40+E40 -> 112 | I40: Pass | K40: 1 | L40: 93 | M40: Others - Others(VN) | N40: =K39+L39+K40+L40 -> 114 | P40: Pass | Q40: 1 | R40: 1 | S40: 92 | T40: Others - Others(VN) | U40: =R39+S39+R40+S40 -> 111
A42: 8 | B42: Resultat_reel | C42: Dropout | D42: Fail | E42: Pass | F42: Do - Do (VP) | G42: =C43 -> 58 | H42: 17 | I42: Resultat_reel | J42: Dropout | K42: Fail | L42: Pass | M42: Do - Do (VP) | N42: =J43 -> 64 | O42: 26 | P42: Resultat_reel | Q42: Dropout | R42: Fail | S42: Pass | T42: Do - Do (VP) | U42: =Q43 -> 65
B43: Dropout | C43: 58 | D43: 7 | E43: 7 | F43: Do - Others (FN) | G43: =D43+E43 -> 14 | I43: Dropout | J43: 64 | K43: 4 | L43: 4 | M43: Do - Others (FN) | N43: =K43+L43 -> 8 | P43: Dropout | Q43: 65 | R43: 5 | S43: 2 | T43: Do - Others (FN) | U43: =R43+S43 -> 7
B44: Fail | C44: 15 | D44: 4 | E44: 15 | F44: Others - Do (FP) | G44: =C44+C45 -> 16 | I44: Fail | J44: 15 | K44: 5 | L44: 14 | M44: Others - Do (FP) | N44: =J44+J45 -> 16 | P44: Fail | Q44: 15 | R44: 6 | S44: 13 | T44: Others - Do (FP) | U44: =Q44+Q45 -> 16
B45: Pass | C45: 1 | D45: 2 | E45: 91 | F45: Others - Others(VN) | G45: =D44+E44+D45+E45 -> 112 | I45: Pass | J45: 1 | K45: 1 | L45: 92 | M45: Others - Others(VN) | N45: =K44+L44+K45+L45 -> 112 | P45: Pass | Q45: 1 | R45: 1 | S45: 92 | T45: Others - Others(VN) | U45: =R44+S44+R45+S45 -> 112
B47: 1 | C47: 2 | D47: 3 | E47: 4 | F47: 5 | G47: 6 | H47: 7 | I47: 8 | J47: 9 | K47: 10 | L47: 11 | M47: 12 | N47: 13 | O47: 14 | P47: 15 | Q47: 16 | R47: 17 | S47: 18 | T47: 19 | U47: 20 | V47: 21 | W47: 22 | X47: 23 | Y47: 24 | Z47: 25 | AA47: 26 | AB47: 27 | AC47: 28 | AD47: 29
A48: Pass - Pass (VP) | B48: =G7 -> 68 | C48: =G12 -> 68 | D48: =G17 -> 63 | E48: =G22 -> 64 | F48: =G27 -> 55 | G48: =G32 -> 57 | H48: =G37 -> 53 | I48: =G42 -> 58 | J48: =N2 -> 59 | K48: =N7 -> 58 | L48: =N12 -> 62 | M48: =N17 -> 62 | N48: =N22 -> 62 | O48: =N27 -> 64 | P48: =N32 -> 67 | Q48: =N37 -> 67 | R48: =N42 -> 64 | S48: =U2 -> 67 | T48: =U7 -> 65 | U48: =U12 -> 66 | V48: =U17 -> 65 | W48: =U22 -> 67 | X48: =U27 -> 65 | Y48: =U32 -> 67 | Z48: =U37 -> 65 | AA48: =U42 -> 65 | AB48: =AB2 -> 69 | AC48: =AB7 -> 69 | AD48: =G2 -> 70
A49: Pass - Others (FN) | B49: =G8 -> 4 | C49: =G13 -> 4 | D49: =G18 -> 9 | E49: =G23 -> 8 | F49: =G28 -> 17 | G49: =G33 -> 15 | H49: =G38 -> 19 | I49: =G43 -> 14 | J49: =N3 -> 13 | K49: =N8 -> 14 | L49: =N13 -> 10 | M49: =N18 -> 10 | N49: =N23 -> 10 | O49: =N28 -> 8 | P49: =N33 -> 5 | Q49: =N38 -> 5 | R49: =N43 -> 8 | S49: =U3 -> 5 | T49: =U8 -> 7 | U49: =U13 -> 6 | V49: =U18 -> 7 | W49: =U23 -> 5 | X49: =U28 -> 7 | Y49: =U33 -> 5 | Z49: =U38 -> 7 | AA49: =U43 -> 7 | AB49: =AB3 -> 3 | AC49: =AB8 -> 3 | AD49: =G3 -> 2
A50: Others - Pass (FP) | B50: =G9 -> 27 | C50: =G14 -> 27 | D50: =G19 -> 25 | E50: =G24 -> 24 | F50: =G29 -> 17 | G50: =G34 -> 18 | H50: =G39 -> 16 | I50: =G44 -> 16 | J50: =N4 -> 11 | K50: =N9 -> 9 | L50: =N14 -> 13 | M50: =N19 -> 13 | N50: =N24 -> 14 | O50: =N29 -> 17 | P50: =N34 -> 16 | Q50: =N39 -> 14 | R50: =N44 -> 16 | S50: =U4 -> 15 | T50: =U9 -> 16 | U50: =U14 -> 17 | V50: =U19 -> 15 | W50: =U24 -> 15 | X50: =U29 -> 16 | Y50: =U34 -> 17 | Z50: =U39 -> 17 | AA50: =U44 -> 16 | AB50: =AB4 -> 16 | AC50: =AB9 -> 16 | AD50: =G4 -> 17
...

Sheet Analyse
A1: ID_Student | B1: code_etudiant | C1: Resultat_reel | D1: 1 | E1: 2 | F1: 3 | G1: 4 | H1: 5 | I1: 6 | J1: 7 | K1: 8 | L1: 9 | M1: 10 | N1: 11 | O1: 12 | P1: 13 | Q1: 14 | R1: 15 | S1: 16 | T1: 17 | U1: 18 | V1: 19 | W1: 20 | X1: 21 | Y1: 22 | Z1: 23 | AA1: 24 | AB1: 25 | AC1: 26 | AD1: 27 | AE1: 28 | AF1: 29
A2: 0 | B2: 3 | C2: Fail | D2: Dropout | E2: Dropout | F2: Dropout | G2: Dropout | H2: Dropout | I2: Dropout | J2: Dropout | K2: Dropout | L2: Dropout | M2: Dropout | N2: Dropout | O2: Dropout | P2: Dropout | Q2: Dropout | R2: Dropout | S2: Dropout | T2: Dropout | U2: Dropout | V2: Dropout | W2: Dropout | X2: Dropout | Y2: Dropout | Z2: Dropout | AA2: Dropout | AB2: Dropout | AC2: Dropout | AD2: Dropout | AE2: Dropout | AF2: Dropout
A3: 1 | B3: 4 | C3: Dropout | D3: Dropout | E3: Dropout | F3: Dropout | G3: Dropout | H3: Dropout | I3: Dropout | J3: Dropout | K3: Dropout | L3: Dropout | M3: Dropout | N3: Dropout | O3: Dropout | P3: Dropout | Q3: Dropout | R3: Dropout | S3: Dropout | T3: Dropout | U3: Dropout | V3: Dropout | W3: Dropout | X3: Dropout | Y3: Dropout | Z3: Dropout | AA3: Dropout | AB3: Dropout | AC3: Dropout | AD3: Dropout | AE3: Dropout | AF3: Dropout
A4: 2 | B4: 5 | C4: Pass | D4: Pass | E4: Pass | F4: Pass | G4: Pass | H4: Pass | I4: Pass | J4: Pass | K4: Pass | L4: Pass | M4: Pass | N4: Pass | O4: Pass | P4: Pass | Q4: Pass | R4: Pass | S4: Pass | T4: Pass | U4: Pass | V4: Pass | W4: Pass | X4: Pass | Y4: Pass | Z4: Pass | AA4: Pass | AB4: Pass | AC4: Pass | AD4: Pass | AE4: Pass | AF4: Pass
A5: 3 | B5: 12 | C5: Pass | D5: Pass | E5: Pass | F5: Pass | G5: Pass | H5: Pass | I5: Pass | J5: Pass | K5: Pass | L5: Pass | M5: Pass | N5: Pass | O5: Pass | P5: Pass | Q5: Pass | R5: Pass | S5: Pass | T5: Pass | U5: Pass | V5: Pass | W5: Pass | X5: Pass | Y5: Pass | Z5: Pass | AA5: Pass | AB5: Pass | AC5: Pass | AD5: Pass | AE5: Pass | AF5: Pass
A6: 4 | B6: 13 | C6: Fail | D6: Dropout | E6: Dropout | F6: Dropout | G6: Dropout | H6: Dropout | I6: Dropout | J6: Dropout | K6: Dropout | L6: Dropout | M6: Dropout | N6: Dropout | O6: Dropout | P6: Dropout | Q6: Dropout | R6: Dropout | S6: Dropout | T6: Dropout | U6: Dropout | V6: Dropout | W6: Dropout | X6: Dropout | Y6: Dropout | Z6: Dropout | AA6: Dropout | AB6: Dropout | AC6: Dropout | AD6: Dropout | AE6: Dropout | AF6: Dropout
A7: 5 | B7: 25 | C7: Pass | D7: Dropout | E7: Dropout | F7: Dropout | G7: Dropout | H7: Dropout | I7: Dropout | J7: Dropout | K7: Dropout | L7: Dropout | M7: Dropout | N7: Dropout | O7: Dropout | P7: Dropout | Q7: Dropout | R7: Pass | S7: Pass | T7: Pass | U7: Pass | V7: Pass | W7: Pass | X7: Pass | Y7: Pass | Z7: Pass | AA7: Pass | AB7: Pass | AC7: Pass | AD7: Pass | AE7: Pass | AF7: Pass
A8: 6 | B8: 40 | C8: Dropout | D8: Dropout | E8: Dropout | F8: Dropout | G8: Dropout | H8: Dropout | I8: Dropout | J8: Dropout | K8: Dropout | L8: Dropout | M8: Dropout | N8: Dropout | O8: Dropout | P8: Dropout | Q8: Dropout | R8: Dropout | S8: Dropout | T8: Dropout | U8: Dropout | V8: Dropout | W8: Dropout | X8: Dropout | Y8: Dropout | Z8: Dropout | AA8: Dropout | AB8: Dropout | AC8: Dropout | AD8: Dropout | AE8: Dropout | AF8: Dropout
A9: 7 | B9: 55 | C9: Pass | D9: Pass | E9: Pass | F9: Pass | G9: Pass | H9: Pass | I9: Pass | J9: Pass | K9: Pass | L9: Pass | M9: Pass | N9: Pass | O9: Pass | P9: Pass | Q9: Pass | R9: Pass | S9: Pass | T9: Pass | U9: Pass | V9: Pass | W9: Pass | X9: Pass | Y9: Pass | Z9: Pass | AA9: Pass | AB9: Pass | AC9: Pass | AD9: Pass | AE9: Pass | AF9: Pass
A10: 8 | B10: 60 | C10: Pass | D10: Pass | E10: Pass | F10: Pass | G10: Pass | H10: Pass | I10: Pass | J10: Pass | K10: Pass | L10: Pass | M10: Pass | N10: Pass | O10: Pass | P10: Pass | Q10: Pass | R10: Pass | S10: Pass | T10: Pass | U10: Pass | V10: Pass | W10: Pass | X10: Pass | Y10: Pass | Z10: Pass | AA10: Pass | AB10: Pass | AC10: Pass | AD10: Pass | AE10: Pass | AF10: Pass
A11: 9 | B11: 70 | C11: Dropout | D11: Dropout | E11: Dropout | F11: Dropout | G11: Dropout | H11: Dropout | I11: Dropout | J11: Dropout | K11: Dropout | L11: Dropout | M11: Dropout | N11: Dropout | O11: Dropout | P11: Dropout | Q11: Dropout | R11: Dropout | S11: Dropout | T11: Dropout | U11: Dropout | V11: Dropout | W11: Dropout | X11: Dropout | Y11: Dropout | Z11: Dropout | AA11: Dropout | AB11: Dropout | AC11: Dropout | AD11: Dropout | AE11: Dropout | AF11: Dropout
A12: 10 | B12: 72 | C12: Fail | D12: Pass | E12: Pass | F12: Pass | G12: Pass | H12: Pass | I12: Pass | J12: Pass | K12: Pass | L12: Pass | M12: Pass | N12: Pass | O12: Pass | P12: Pass | Q12: Pass | R12: Pass | S12: Pass | T12: Pass | U12: Pass | V12: Pass | W12: Pass | X12: Pass | Y12: Pass | Z12: Pass | AA12: Pass | AB12: Pass | AC12: Pass | AD12: Pass | AE12: Pass | AF12: Pass
A13: 11 | B13: 85 | C13: Pass | D13: Dropout | E13: Dropout | F13: Dropout | G13: Dropout | H13: Dropout | I13: Dropout | J13: Dropout | K13: Dropout | L13: Dropout | M13: Dropout | N13: Dropout | O13: Dropout | P13: Pass | Q13: Pass | R13: Pass | S13: Pass | T13: Pass | U13: Pass | V13: Pass | W13: Pass | X13: Pass | Y13: Pass | Z13: Pass | AA13: Pass | AB13: Pass | AC13: Pass | AD13: Pass | AE13: Pass | AF13: Pass
... A201: 199 | B201: 2365 | C201: Dropout | D201: Dropout | E201: Dropout | F201: Dropout | G201: Dropout | H201: Dropout | I201: Dropout | J201: Dropout | K201: Dropout | L201: Dropout | M201: Dropout | N201: Dropout | O201: Dropout | P201: Dropout | Q201: Dropout | R201: Dropout | S201: Dropout | T201: Dropout | U201: Dropout | V201: Dropout | W201: Dropout | X201: Dropout | Y201: Dropout | Z201: Dropout | AA201: Dropout | AB201: Dropout | AC201: Dropout | AD201: Dropout | AE201: Dropout | AF201: Dropout

Sheet Frame_sys_results
A1: =Analyse!AF1 -> 29 | B1: Final_frame
A2: =Analyse!AF2 -> Dropout | B2: =A2 -> Dropout
A3: =Analyse!AF3 -> Dropout | B3: =_xlfn.CONCAT(B2,",",A3) -> Dropout,Dropout
A4: =Analyse!AF4 -> Pass | B4: =_xlfn.CONCAT(B3,",",A4) -> Dropout,Dropout,Pass
A5: =Analyse!AF5 -> Pass | B5: =_xlfn.CONCAT(B4,",",A5) -> Dropout,Dropout,Pass,Pass
A6: =Analyse!AF6 -> Dropout | B6: =_xlfn.CONCAT(B5,",",A6) -> Dropout,Dropout,Pass,Pass,Dropout
A7: =Analyse!AF7 -> Pass | B7: =_xlfn.CONCAT(B6,",",A7) -> Dropout,Dropout,Pass,Pass,Dropout,Pass
A8: =Analyse!AF8 -> Dropout | B8: =_xlfn.CONCAT(B7,",",A8) -> Dropout,Dropout,Pass,Pass,Dropout,Pass,Dropout
A9: =Analyse!AF9 -> Pass | B9: =_xlfn.CONCAT(B8,",",A9) -> Dropout,Dropout,Pass,Pass,Dropout,Pass,Dropout,Pass
A10: =Analyse!AF10 -> Pass | B10: =_xlfn.CONCAT(B9,",",A10) -> Dropout,Dropout,Pass,Pass,Dropout,Pass,Dropout,Pass,Pass
A11: =Analyse!AF11 -> Dropout | B11: =_xlfn.CONCAT(B10,",",A11) -> Dropout,Dropout,Pass,Pass,Dropout,Pass,Dropout,Pass,Pass,Dropout
A12: =Analyse!AF12 -> Pass | B12: =_xlfn.CONCAT(B11,",",A12) -> Dropout,Dropout,Pass,Pass,Dropout,Pass,Dropout,Pass,Pass,Dropout,Pass
A13: =Analyse!AF13 -> Pass | B13: =_xlfn.CONCAT(B12,",",A13) -> Dropout,Dropout,Pass,Pass,Dropout,Pass,Dropout,Pass,Pass,Dropout,Pass,Pass
A14: =Analyse!AF14 -> Pass | B14: =_xlfn.CONCAT(B13,",",A14) -> Dropout,Dropout,Pass,Pass,Dropout,Pass,Dropout,Pass,Pass,Dropout,Pass,Pass,Pass
... A201: =Analyse!AF201 -> Dropout | B201: =_xlfn.CONCAT(B200,",",A201) -> Dropout,Dropout,Pass,Pass,Dropout,Pass,Dropout,Pass,Pass,Dropout,Pass,Pass,Pass,Dropout,Pass,Dropout,Dropout,Pass,Dropout,Pass,Dropout,Pass,Dropout,Dropout,Pass,Pass,Fail,Dropout,Pass,Dropout,Dropout,Pass,Dropout,Dropout,Pass,Pass,Dropout,Pass,Pass,Dropout,Pass,Dropout,Pass,Pass,Pass,Fail,Dropout,Pass,Dropout,Pass,Dropout,Dropout,Pass,Dropout,Dropout,Pass,Dropout,Pass,Dropout,Pass,Dropout,Pass,Dropout,Dropout,Pass,Pass,Pass,Dropout,Dropout,Dropout,Pass,Dropout,Pass,Dropout,Dropout,Pass,Pass,Dropout,Pass,Pass,Dropout,Pass,Pass,Dropout,Pass,Dropout,Pass,Dropout,Pass,Pass,Pass,Dropout,Dropout,Pass,Dropout,Dropout,Dropout,Pass,Dropout,Pass,Dropout,Pass,Dropout,Pass,Dropout,Dropout,Dropout,Pass,Pass,Dropout,Dropout,Pass,Pass,Dropout,Pass,Pass,Dropout,Dropout,Pass,Pass,Dropout,Pass,Dropout,Dropout,Pass,Dropout,Dropout,Pass,Pass,Dropout,Pass,Dropout,Dropout,Pass,Dropout,Pass,Pass,Dropout,Pass,Dropout,Pass,Dropout,Pass,Dropout,Pass,Dropout,Pass,Pass,Dropout,Pass,Dropout,Pass,Pass,Dropout,Pass,Pass,Dropout,Pass,Dropout,Pass,Pass,Dropout,Pass,Dropout,Pass,Pass,Pass,Dropout,Pass,Dropout,Pass,Dropout,Pass,Pass,Dropout,Dropout,Dropout,Pass,Pass,Pass,Dropout,Pass,Pass,Pass,Dropout,Dropout,Pass,Pass,Dropout,Pass,Pass,Pass,Dropout,Pass,Pass,Dropout,Pass,Dropout,Pass,Dropout
