Workbook

Sheet Sys-Pass_lr
A1: Valeurs (Réel - Vote) | B1: 1 | C1: 2 | D1: 3 | E1: 4 | F1: 5 | G1: 6 | H1: 7 | I1: 8 | J1: 9 | K1: 10 | L1: 11 | M1: 12 | N1: 13 | O1: 14 | P1: 15 | Q1: 16 | R1: 17 | S1: 18 | T1: 19 | U1: 20 | V1: 21 | W1: 22 | X1: 23 | Y1: 24 | Z1: 25 | AA1: 26 | AB1: 27 | AC1: 28 | AD1: 29
A2: Pass - Pass (VP) | B2: 90 | C2: 90 | D2: 90 | E2: 90 | F2: 90 | G2: 90 | H2: 90 | I2: 90 | J2: 91 | K2: 91 | L2: 91 | M2: 91 | N2: 91 | O2: 92 | P2: 94 | Q2: 93 | R2: 92 | S2: 92 | T2: 91 | U2: 92 | V2: 93 | W2: 93 | X2: 93 | Y2: 93 | Z2: 93 | AA2: 93 | AB2: 92 | AC2: 92 | AD2: 92
A3: Pass - Others (FN) | B3: 4 | C3: 4 | D3: 4 | E3: 4 | F3: 4 | G3: 4 | H3: 4 | I3: 4 | J3: 3 | K3: 3 | L3: 3 | M3: 3 | N3: 3 | O3: 2 | P3: 0 | Q3: 1 | R3: 2 | S3: 2 | T3: 3 | U3: 2 | V3: 1 | W3: 1 | X3: 1 | Y3: 1 | Z3: 1 | AA3: 1 | AB3: 2 | AC3: 2 | AD3: 2
A4: Others - Pass (FP) | B4: 16 | C4: 16 | D4: 16 | E4: 16 | F4: 18 | G4: 16 | H4: 17 | I4: 18 | J4: 24 | K4: 23 | L4: 24 | M4: 23 | N4: 19 | O4: 19 | P4: 19 | Q4: 19 | R4: 18 | S4: 19 | T4: 15 | U4: 14 | V4: 14 | W4: 14 | X4: 14 | Y4: 13 | Z4: 13 | AA4: 13 | AB4: 12 | AC4: 12 | AD4: 13
A5: Others - Others (VN) | B5: 90 | C5: 90 | D5: 90 | E5: 90 | F5: 88 | G5: 90 | H5: 89 | I5: 88 | J5: 82 | K5: 83 | L5: 82 | M5: 83 | N5: 87 | O5: 87 | P5: 87 | Q5: 87 | R5: 88 | S5: 87 | T5: 91 | U5: 92 | V5: 92 | W5: 92 | X5: 92 | Y5: 93 | Z5: 93 | AA5: 93 | AB5: 94 | AC5: 94 | AD5: 93
A6: Total | B6: =SUM(B2:B5) -> 200 | C6: =SUM(C2:C5) -> 200 | D6: =SUM(D2:D5) -> 200 | E6: =SUM(E2:E5) -> 200 | F6: =SUM(F2:F5) -> 200 | G6: =SUM(G2:G5) -> 200 | H6: =SUM(H2:H5) -> 200 | I6: =SUM(I2:I5) -> 200 | ... AD6: =SUM(AD2:AD5) -> 200
A7: Accuracy | B7: =(B5+B2)/B6 -> 0.9 | C7: =(C5+C2)/C6 -> 0.9 | D7: =(D5+D2)/D6 -> 0.9 | E7: =(E5+E2)/E6 -> 0.9 | F7: =(F5+F2)/F6 -> 0.89 | G7: =(G5+G2)/G6 -> 0.9 | H7: =(H5+H2)/H6 -> 0.895 | I7: =(I5+I2)/I6 -> 0.89 | ... AD7: =(AD5+AD2)/AD6 -> 0.925
A8: Erreur | B8: =1-B7 -> 0.1 | C8: =1-C7 -> 0.1 | D8: =1-D7 -> 0.1 | E8: =1-E7 -> 0.1 | F8: =1-F7 -> 0.11 | G8: =1-G7 -> 0.1 | H8: =1-H7 -> 0.105 | I8: =1-I7 -> 0.11 | ... AD8: =1-AD7 -> 0.075
A9: Recall | B9: =B2/(B2+B3) -> 0.95744681 | C9: =C2/(C2+C3) -> 0.95744681 | D9: =D2/(D2+D3) -> 0.95744681 | E9: =E2/(E2+E3) -> 0.95744681 | F9: =F2/(F2+F3) -> 0.95744681 | G9: =G2/(G2+G3) -> 0.95744681 | H9: =H2/(H2+H3) -> 0.95744681 | I9: =I2/(I2+I3) -> 0.95744681 | ... AD9: =AD2/(AD2+AD3) -> 0.9787234
A10: Precision | B10: =B2/(B2+B4) -> 0.8490566 | C10: =C2/(C2+C4) -> 0.8490566 | D10: =D2/(D2+D4) -> 0.8490566 | E10: =E2/(E2+E4) -> 0.8490566 | F10: =F2/(F2+F4) -> 0.83333333 | G10: =G2/(G2+G4) -> 0.8490566 | H10: =H2/(H2+H4) -> 0.8411215 | I10: =I2/(I2+I4) -> 0.83333333 | ... AD10: =AD2/(AD2+AD4) -> 0.87619048
A11: F-mesure | B11: =2*B9*B10/(B9+B10) -> 0.9 | C11: =2*C9*C10/(C9+C10) -> 0.9 | D11: =2*D9*D10/(D9+D10) -> 0.9 | E11: =2*E9*E10/(E9+E10) -> 0.9 | F11: =2*F9*F10/(F9+F10) -> 0.89108911 | G11: =2*G9*G10/(G9+G10) -> 0.9 | H11: =2*H9*H10/(H9+H10) -> 0.89552239 | I11: =2*I9*I10/(I9+I10) -> 0.89108911 | ... AD11: =2*AD9*AD10/(AD9+AD10) -> 0.92462312
A12: Specificity | B12: =B5/(B4+B5) -> 0.8490566 | C12: =C5/(C4+C5) -> 0.8490566 | D12: =D5/(D4+D5) -> 0.8490566 | E12: =E5/(E4+E5) -> 0.8490566 | F12: =F5/(F4+F5) -> 0.83018868 | G12: =G5/(G4+G5) -> 0.8490566 | H12: =H5/(H4+H5) -> 0.83962264 | I12: =I5/(I4+I5) -> 0.83018868 | ... AD12: =AD5/(AD4+AD5) -> 0.87735849
A13: Limite | B13: 0.9 | C13: 0.9 | D13: 0.9 | E13: 0.9 | F13: 0.9 | G13: 0.9 | H13: 0.9 | I13: 0.9 | J13: 0.9 | K13: 0.9 | L13: 0.9 | M13: 0.9 | N13: 0.9 | O13: 0.9 | P13: 0.9 | Q13: 0.9 | R13: 0.9 | S13: 0.9 | T13: 0.9 | U13: 0.9 | V13: 0.9 | W13: 0.9 | X13: 0.9 | Y13: 0.9 | Z13: 0.9 | AA13: 0.9 | AB13: 0.9 | AC13: 0.9 | AD13: 0.9

Sheet Sys-Fail_lr
A1: Valeurs (Réel - Vote) | B1: 1 | C1: 2 | D1: 3 | E1: 4 | F1: 5 | G1: 6 | H1: 7 | I1: 8 | J1: 9 | K1: 10 | L1: 11 | M1: 12 | N1: 13 | O1: 14 | P1: 15 | Q1: 16 | R1: 17 | S1: 18 | T1: 19 | U1: 20 | V1: 21 | W1: 22 | X1: 23 | Y1: 24 | Z1: 25 | AA1: 26 | AB1: 27 | AC1: 28 | AD1: 29
A2: Fail - Fail (VP) | B2: 0 | C2: 0 | D2: 0 | E2: 0 | F2: 1 | G2: 3 | H2: 3 | I2: 4 | J2: 4 | K2: 5 | L2: 4 | M2: 4 | N2: 6 | O2: 6 | P2: 4 | Q2: 5 | R2: 4 | S2: 5 | T2: 5 | U2: 6 | V2: 5 | W2: 4 | X2: 3 | Y2: 5 | Z2: 5 | AA2: 3 | AB2: 5 | AC2: 3 | AD2: 5
A3: Fail - Others (FN) | B3: 34 | C3: 34 | D3: 34 | E3: 34 | F3: 33 | G3: 31 | H3: 31 | I3: 30 | J3: 30 | K3: 29 | L3: 30 | M3: 30 | N3: 28 | O3: 28 | P3: 30 | Q3: 29 | R3: 30 | S3: 29 | T3: 29 | U3: 28 | V3: 29 | W3: 30 | X3: 31 | Y3: 29 | Z3: 29 | AA3: 31 | AB3: 29 | AC3: 31 | AD3: 29
A4: Others - Fail (FP) | B4: 0 | C4: 0 | D4: 0 | E4: 0 | F4: 3 | G4: 7 | H4: 7 | I4: 10 | J4: 7 | K4: 8 | L4: 6 | M4: 9 | N4: 14 | O4: 8 | P4: 6 | Q4: 5 | R4: 6 | S4: 5 | T4: 5 | U4: 10 | V4: 7 | W4: 8 | X4: 4 | Y4: 8 | Z4: 8 | AA4: 4 | AB4: 8 | AC4: 6 | AD4: 13
A5: Others - Others (VN) | B5: 166 | C5: 166 | D5: 166 | E5: 166 | F5: 163 | G5: 159 | H5: 159 | I5: 156 | J5: 159 | K5: 158 | L5: 160 | M5: 157 | N5: 152 | O5: 158 | P5: 160 | Q5: 161 | R5: 160 | S5: 161 | T5: 161 | U5: 156 | V5: 159 | W5: 158 | X5: 162 | Y5: 158 | Z5: 158 | AA5: 162 | AB5: 158 | AC5: 160 | AD5: 153
A6: Total | B6: =SUM(B2:B5) -> 200 | C6: =SUM(C2:C5) -> 200 | D6: =SUM(D2:D5) -> 200 | E6: =SUM(E2:E5) -> 200 | F6: =SUM(F2:F5) -> 200 | G6: =SUM(G2:G5) -> 200 | H6: =SUM(H2:H5) -> 200 | I6: =SUM(I2:I5) -> 200 | ... AD6: =SUM(AD2:AD5) -> 200
A7: Accuracy | B7: =(B5+B2)/B6 -> 0.83 | C7: =(C5+C2)/C6 -> 0.83 | D7: =(D5+D2)/D6 -> 0.83 | E7: =(E5+E2)/E6 -> 0.83 | F7: =(F5+F2)/F6 -> 0.82 | G7: =(G5+G2)/G6 -> 0.81 | H7: =(H5+H2)/H6 -> 0.81 | I7: =(I5+I2)/I6 -> 0.8 | ... AD7: =(AD5+AD2)/AD6 -> 0.79
A8: Erreur | B8: =1-B7 -> 0.17 | C8: =1-C7 -> 0.17 | D8: =1-D7 -> 0.17 | E8: =1-E7 -> 0.17 | F8: =1-F7 -> 0.18 | G8: =1-G7 -> 0.19 | H8: =1-H7 -> 0.19 | I8: =1-I7 -> 0.2 | ... AD8: =1-AD7 -> 0.21
A9: Recall | B9: =B2/(B2+B3) -> 0 | C9: =C2/(C2+C3) -> 0 | D9: =D2/(D2+D3) -> 0 | E9: =E2/(E2+E3) -> 0 | F9: =F2/(F2+F3) -> 0.029411765 | G9: =G2/(G2+G3) -> 0.088235294 | H9: =H2/(H2+H3) -> 0.088235294 | I9: =I2/(I2+I3) -> 0.11764706 | ... AD9: =AD2/(AD2+AD3) -> 0.14705882
A10: Precision | B10: =B2/(B2+B4) -> #DIV/0! | C10: =C2/(C2+C4) -> #DIV/0! | D10: =D2/(D2+D4) -> #DIV/0! | E10: =E2/(E2+E4) -> #DIV/0! | F10: =F2/(F2+F4) -> 0.25 | G10: =G2/(G2+G4) -> 0.3 | H10: =H2/(H2+H4) -> 0.3 | I10: =I2/(I2+I4) -> 0.28571429 | ... AD10: =AD2/(AD2+AD4) -> 0.27777778
A11: F-mesure | B11: =2*B9*B10/(B9+B10) -> #DIV/0! | C11: =2*C9*C10/(C9+C10) -> #DIV/0! | D11: =2*D9*D10/(D9+D10) -> #DIV/0! | E11: =2*E9*E10/(E9+E10) -> #DIV/0! | F11: =2*F9*F10/(F9+F10) -> 0.052631579 | G11: =2*G9*G10/(G9+G10) -> 0.13636364 | H11: =2*H9*H10/(H9+H10) -> 0.13636364 | I11: =2*I9*I10/(I9+I10) -> 0.16666667 | ... AD11: =2*AD9*AD10/(AD9+AD10) -> 0.19230769
A12: Specificity | B12: =B5/(B4+B5) -> 1 | C12: =C5/(C4+C5) -> 1 | D12: =D5/(D4+D5) -> 1 | E12: =E5/(E4+E5) -> 1 | F12: =F5/(F4+F5) -> 0.98192771 | G12: =G5/(G4+G5) -> 0.95783133 | H12: =H5/(H4+H5) -> 0.95783133 | I12: =I5/(I4+I5) -> 0.93975904 | ... AD12: =AD5/(AD4+AD5) -> 0.92168675
A13: Limite | B13: 0.9 | C13: 0.9 | D13: 0.9 | E13: 0.9 | F13: 0.9 | G13: 0.9 | H13: 0.9 | I13: 0.9 | J13: 0.9 | K13: 0.9 | L13: 0.9 | M13: 0.9 | N13: 0.9 | O13: 0.9 | P13: 0.9 | Q13: 0.9 | R13: 0.9 | S13: 0.9 | T13: 0.9 | U13: 0.9 | V13: 0.9 | W13: 0.9 | X13: 0.9 | Y13: 0.9 | Z13: 0.9 | AA13: 0.9 | AB13: 0.9 | AC13: 0.9 | AD13: 0.9

Sheet Sys-Dropout_lr
A1: Valeurs (Réel - Vote) | B1: 1 | C1: 2 | D1: 3 | E1: 4 | F1: 5 | G1: 6 | H1: 7 | I1: 8 | J1: 9 | K1: 10 | L1: 11 | M1: 12 | N1: 13 | O1: 14 | P1: 15 | Q1: 16 | R1: 17 | S1: 18 | T1: 19 | U1: 20 | V1: 21 | W1: 22 | X1: 23 | Y1: 24 | Z1: 25 | AA1: 26 | AB1: 27 | AC1: 28 | AD1: 29
A2: Dropout - Dropout (VP) | B2: 68 | C2: 68 | D2: 68 | E2: 68 | F2: 65 | G2: 62 | H2: 62 | I2: 59 | J2: 60 | K2: 59 | L2: 61 | M2: 58 | N2: 56 | O2: 62 | P2: 62 | Q2: 63 | R2: 63 | S2: 63 | T2: 66 | U2: 61 | V2: 64 | W2: 63 | X2: 67 | Y2: 63 | Z2: 63 | AA2: 67 | AB2: 64 | AC2: 66 | AD2: 59
A3: Dropout - Others (FN) | B3: 4 | C3: 4 | D3: 4 | E3: 4 | F3: 7 | G3: 10 | H3: 10 | I3: 13 | J3: 12 | K3: 13 | L3: 11 | M3: 14 | N3: 16 | O3: 10 | P3: 10 | Q3: 9 | R3: 9 | S3: 9 | T3: 6 | U3: 11 | V3: 8 | W3: 9 | X3: 5 | Y3: 9 | Z3: 9 | AA3: 5 | AB3: 8 | AC3: 6 | AD3: 13
A4: Others - Dropout (FP) | B4: 26 | C4: 26 | D4: 26 | E4: 26 | F4: 23 | G4: 22 | H4: 21 | I4: 19 | J4: 14 | K4: 14 | L4: 14 | M4: 15 | N4: 14 | O4: 13 | P4: 15 | Q4: 15 | R4: 17 | S4: 16 | T4: 18 | U4: 17 | V4: 17 | W4: 18 | X4: 19 | Y4: 18 | Z4: 18 | AA4: 20 | AB4: 19 | AC4: 21 | AD4: 18
A5: Others - Others (VN) | B5: 102 | C5: 102 | D5: 102 | E5: 102 | F5: 105 | G5: 106 | H5: 107 | I5: 109 | J5: 114 | K5: 114 | L5: 114 | M5: 113 | N5: 114 | O5: 115 | P5: 113 | Q5: 113 | R5: 111 | S5: 112 | T5: 110 | U5: 111 | V5: 111 | W5: 110 | X5: 109 | Y5: 110 | Z5: 110 | AA5: 108 | AB5: 109 | AC5: 107 | AD5: 110
A6: Total | B6: =SUM(B2:B5) -> 200 | C6: =SUM(C2:C5) -> 200 | D6: =SUM(D2:D5) -> 200 | E6: =SUM(E2:E5) -> 200 | F6: =SUM(F2:F5) -> 200 | G6: =SUM(G2:G5) -> 200 | H6: =SUM(H2:H5) -> 200 | I6: =SUM(I2:I5) -> 200 | ... AD6: =SUM(AD2:AD5) -> 200
A7: Accuracy | B7: =(B5+B2)/B6 -> 0.85 | C7: =(C5+C2)/C6 -> 0.85 | D7: =(D5+D2)/D6 -> 0.85 | E7: =(E5+E2)/E6 -> 0.85 | F7: =(F5+F2)/F6 -> 0.85 | G7: =(G5+G2)/G6 -> 0.84 | H7: =(H5+H2)/H6 -> 0.845 | I7: =(I5+I2)/I6 -> 0.84 | ... AD7: =(AD5+AD2)/AD6 -> 0.845
A8: Erreur | B8: =1-B7 -> 0.15 | C8: =1-C7 -> 0.15 | D8: =1-D7 -> 0.15 | E8: =1-E7 -> 0.15 | F8: =1-F7 -> 0.15 | G8: =1-G7 -> 0.16 | H8: =1-H7 -> 0.155 | I8: =1-I7 -> 0.16 | ... AD8: =1-AD7 -> 0.155
A9: Recall | B9: =B2/(B2+B3) -> 0.94444444 | C9: =C2/(C2+C3) -> 0.94444444 | D9: =D2/(D2+D3) -> 0.94444444 | E9: =E2/(E2+E3) -> 0.94444444 | F9: =F2/(F2+F3) -> 0.90277778 | G9: =G2/(G2+G3) -> 0.86111111 | H9: =H2/(H2+H3) -> 0.86111111 | I9: =I2/(I2+I3) -> 0.81944444 | ... AD9: =AD2/(AD2+AD3) -> 0.81944444
A10: Precision | B10: =B2/(B2+B4) -> 0.72340426 | C10: =C2/(C2+C4) -> 0.72340426 | D10: =D2/(D2+D4) -> 0.72340426 | E10: =E2/(E2+E4) -> 0.72340426 | F10: =F2/(F2+F4) -> 0.73863636 | G10: =G2/(G2+G4) -> 0.73809524 | H10: =H2/(H2+H4) -> 0.74698795 | I10: =I2/(I2+I4) -> 0.75641026 | ... AD10: =AD2/(AD2+AD4) -> 0.76623377
A11: F-mesure | B11: =2*B9*B10/(B9+B10) -> 0.81927711 | C11: =2*C9*C10/(C9+C10) -> 0.81927711 | D11: =2*D9*D10/(D9+D10) -> 0.81927711 | E11: =2*E9*E10/(E9+E10) -> 0.81927711 | F11: =2*F9*F10/(F9+F10) -> 0.8125 | G11: =2*G9*G10/(G9+G10) -> 0.79487179 | H11: =2*H9*H10/(H9+H10) -> 0.8 | I11: =2*I9*I10/(I9+I10) -> 0.78666667 | ... AD11: =2*AD9*AD10/(AD9+AD10) -> 0.79194631
A12: Specificity | B12: =B5/(B4+B5) -> 0.796875 | C12: =C5/(C4+C5) -> 0.796875 | D12: =D5/(D4+D5) -> 0.796875 | E12: =E5/(E4+E5) -> 0.796875 | F12: =F5/(F4+F5) -> 0.8203125 | G12: =G5/(G4+G5) -> 0.828125 | H12: =H5/(H4+H5) -> 0.8359375 | I12: =I5/(I4+I5) -> 0.8515625 | ... AD12: =AD5/(AD4+AD5) -> 0.859375
A13: Limite | B13: 0.9 | C13: 0.9 | D13: 0.9 | E13: 0.9 | F13: 0.9 | G13: 0.9 | H13: 0.9 | I13: 0.9 | J13: 0.9 | K13: 0.9 | L13: 0.9 | M13: 0.9 | N13: 0.9 | O13: 0.9 | P13: 0.9 | Q13: 0.9 | R13: 0.9 | S13: 0.9 | T13: 0.9 | U13: 0.9 | V13: 0.9 | W13: 0.9 | X13: 0.9 | Y13: 0.9 | Z13: 0.9 | AA13: 0.9 | AB13: 0.9 | AC13: 0.9 | AD13: 0.9

Sheet probaPass
A1: ID_Student | B1: 1 | C1: 2 | D1: 3 | E1: 4 | F1: 5 | G1: 6 | H1: 7 | I1: 8 | J1: 9 | K1: 10 | L1: 11 | M1: 12 | N1: 13 | O1: 14 | P1: 15 | Q1: 16 | R1: 17 | S1: 18 | T1: 19 | U1: 20 | V1: 21 | W1: 22 | X1: 23 | Y1: 24 | Z1: 25 | AA1: 26 | AB1: 27 | AC1: 28 | AD1: 29 | AF1: Pass | AG1: Proba_pass | AH1: 0
A2: 0 | B2: Dropout | C2: 1 | D2: 1 | E2: 1 | F2: Dropout | G2: Dropout | H2: Dropout | I2: Dropout | J2: Dropout | K2: Dropout | L2: Dropout | M2: Dropout | N2: Dropout | O2: Dropout | P2: Dropout | Q2: Dropout | R2: Dropout | S2: Dropout | T2: Dropout | U2: Dropout | V2: Dropout | W2: Dropout | X2: Dropout | Y2: Dropout | Z2: Dropout | AA2: Dropout | AB2: Dropout | AC2: Dropout | AD2: Dropout | AF2: =SUM(B2:AD2) -> 3 | AG2: =AF2/29 -> 0.10344828
A3: 1 | B3: Dropout | C3: Dropout | D3: Dropout | E3: Dropout | F3: Dropout | G3: Dropout | H3: Dropout | I3: Dropout | J3: Dropout | K3: Dropout | L3: Dropout | M3: Dropout | N3: Dropout | O3: Dropout | P3: Dropout | Q3: Dropout | R3: Dropout | S3: Dropout | T3: Dropout | U3: Dropout | V3: Dropout | W3: Dropout | X3: Dropout | Y3: Dropout | Z3: Dropout | AA3: Dropout | AB3: Dropout | AC3: Dropout | AD3: Dropout | AF3: =SUM(B3:AD3) -> 0 | AG3: =AF3/29 -> 0
A4: 2 | B4: 1 | C4: 1 | D4: 1 | E4: 1 | F4: 1 | G4: 1 | H4: 1 | I4: 1 | J4: 1 | K4: 1 | L4: 1 | M4: 1 | N4: 1 | O4: 1 | P4: 1 | Q4: 1 | R4: 1 | S4: 1 | T4: 1 | U4: 1 | V4: 1 | W4: 1 | X4: 1 | Y4: 1 | Z4: 1 | AA4: 1 | AB4: 1 | AC4: 1 | AD4: 1 | AF4: =SUM(B4:AD4) -> 29 | AG4: =AF4/29 -> 1
A5: 3 | B5: 1 | C5: 1 | D5: 1 | E5: 1 | F5: 1 | G5: 1 | H5: 1 | I5: 1 | J5: 1 | K5: 1 | L5: 1 | M5: 1 | N5: 1 | O5: 1 | P5: 1 | Q5: 1 | R5: 1 | S5: 1 | T5: 1 | U5: 1 | V5: 1 | W5: 1 | X5: 1 | Y5: 1 | Z5: 1 | AA5: 1 | AB5: 1 | AC5: 1 | AD5: 1 | AF5: =SUM(B5:AD5) -> 29 | AG5: =AF5/29 -> 1
A6: 4 | B6: Dropout | C6: Dropout | D6: Dropout | E6: Dropout | F6: Dropout | G6: Dropout | H6: Dropout | I6: Dropout | J6: Fail | K6: Fail | L6: Fail | M6: Fail | N6: Fail | O6: Fail | P6: Dropout | Q6: Dropout | R6: Dropout | S6: Dropout | T6: Dropout | U6: Dropout | V6: Dropout | W6: Dropout | X6: Dropout | Y6: Dropout | Z6: Dropout | AA6: Dropout | AB6: Dropout | AC6: Dropout | AD6: Dropout | AF6: =SUM(B6:AD6) -> 0 | AG6: =AF6/29 -> 0
A7: 5 | B7: Dropout | C7: Dropout | D7: Dropout | E7: Dropout | F7: Dropout | G7: Dropout | H7: Dropout | I7: Dropout | J7: Dropout | K7: Dropout | L7: Dropout | M7: Dropout | N7: Dropout | O7: Dropout | P7: Dropout | Q7: Dropout | R7: Dropout | S7: Dropout | T7: Dropout | U7: Dropout | V7: 1 | W7: 1 | X7: 1 | Y7: 1 | Z7: 1 | AA7: 1 | AB7: 1 | AC7: 1 | AD7: 1 | AF7: =SUM(B7:AD7) -> 9 | AG7: =AF7/29 -> 0.31034483
A8: 6 | B8: Dropout | C8: Dropout | D8: Dropout | E8: Dropout | F8: Dropout | G8: Dropout | H8: Dropout | I8: Dropout | J8: Dropout | K8: Dropout | L8: Dropout | M8: Dropout | N8: Dropout | O8: Dropout | P8: Dropout | Q8: Dropout | R8: Dropout | S8: Dropout | T8: Dropout | U8: Dropout | V8: Dropout | W8: Dropout | X8: Dropout | Y8: Dropout | Z8: Dropout | AA8: Dropout | AB8: Dropout | AC8: Dropout | AD8: Dropout | AF8: =SUM(B8:AD8) -> 0 | AG8: =AF8/29 -> 0
A9: 7 | B9: 1 | C9: 1 | D9: 1 | E9: 1 | F9: 1 | G9: 1 | H9: 1 | I9: 1 | J9: 1 | K9: 1 | L9: 1 | M9: 1 | N9: 1 | O9: 1 | P9: 1 | Q9: 1 | R9: 1 | S9: 1 | T9: 1 | U9: 1 | V9: 1 | W9: 1 | X9: 1 | Y9: 1 | Z9: 1 | AA9: 1 | AB9: 1 | AC9: 1 | AD9: 1 | AF9: =SUM(B9:AD9) -> 29 | AG9: =AF9/29 -> 1
A10: 8 | B10: 1 | C10: 1 | D10: 1 | E10: 1 | F10: 1 | G10: 1 | H10: 1 | I10: 1 | J10: 1 | K10: 1 | L10: 1 | M10: 1 | N10: 1 | O10: 1 | P10: 1 | Q10: 1 | R10: 1 | S10: 1 | T10: 1 | U10: 1 | V10: 1 | W10: 1 | X10: 1 | Y10: 1 | Z10: 1 | AA10: 1 | AB10: 1 | AC10: 1 | AD10: 1 | AF10: =SUM(B10:AD10) -> 29 | AG10: =AF10/29 -> 1
A11: 9 | B11: Dropout | C11: Dropout | D11: Dropout | E11: Dropout | F11: 1 | G11: Dropout | H11: Dropout | I11: Dropout | J11: Dropout | K11: Dropout | L11: Dropout | M11: Dropout | N11: Dropout | O11: Dropout | P11: Dropout | Q11: Dropout | R11: Dropout | S11: Dropout | T11: Dropout | U11: Dropout | V11: Dropout | W11: Dropout | X11: Dropout | Y11: Dropout | Z11: Dropout | AA11: Dropout | AB11: Dropout | AC11: Dropout | AD11: Dropout | AF11: =SUM(B11:AD11) -> 1 | AG11: =AF11/29 -> 0.034482759
A12: 10 | B12: 1 | C12: 1 | D12: 1 | E12: 1 | F12: 1 | G12: 1 | H12: 1 | I12: 1 | J12: 1 | K12: 1 | L12: 1 | M12: 1 | N12: 1 | O12: 1 | P12: 1 | Q12: 1 | R12: 1 | S12: 1 | T12: 1 | U12: 1 | V12: 1 | W12: 1 | X12: 1 | Y12: 1 | Z12: 1 | AA12: 1 | AB12: 1 | AC12: 1 | AD12: 1 | AF12: =SUM(B12:AD12) -> 29 | AG12: =AF12/29 -> 1
A13: 11 | B13: Dropout | C13: Dropout | D13: Dropout | E13: Dropout | F13: Dropout | G13: Dropout | H13: Dropout | I13: Dropout | J13: 1 | K13: 1 | L13: 1 | M13: 1 | N13: 1 | O13: 1 | P13: 1 | Q13: 1 | R13: 1 | S13: 1 | T13: 1 | U13: 1 | V13: 1 | W13: 1 | X13: 1 | Y13: 1 | Z13: 1 | AA13: 1 | AB13: 1 | AC13: 1 | AD13: 1 | AF13: =SUM(B13:AD13) -> 21 | AG13: =AF13/29 -> 0.72413793
A14: 12 | B14: 1 | C14: 1 | D14: 1 | E14: 1 | F14: 1 | G14: 1 | H14: 1 | I14: 1 | J14: 1 | K14: 1 | L14: 1 | M14: 1 | N14: 1 | O14: 1 | P14: 1 | Q14: 1 | R14: 1 | S14: 1 | T14: 1 | U14: 1 | V14: 1 | W14: 1 | X14: 1 | Y14: 1 | Z14: 1 | AA14: 1 | AB14: 1 | AC14: 1 | AD14: 1 | AF14: =SUM(B14:AD14) -> 29 | AG14: =AF14/29 -> 1
A15: 13 | B15: Dropout | C15: Dropout | D15: Dropout | E15: Dropout | F15: Dropout | G15: Dropout | H15: Dropout | I15: Dropout | J15: Dropout | K15: Dropout | L15: Dropout | M15: Dropout | N15: Dropout | O15: Dropout | P15: Dropout | Q15: Dropout | R15: Dropout | S15: Dropout | T15: Dropout | U15: Dropout | V15: Dropout | W15: Dropout | X15: Dropout | Y15: Dropout | Z15: Dropout | AA15: Dropout | AB15: Dropout | AC15: Dropout | AD15: Dropout | AF15: =SUM(B15:AD15) -> 0 | AG15: =AF15/29 -> 0
A16: 14 | B16: 1 | C16: 1 | D16: 1 | E16: 1 | F16: 1 | G16: 1 | H16: 1 | I16: 1 | J16: 1 | K16: 1 | L16: 1 | M16: 1 | N16: 1 | O16: 1 | P16: 1 | Q16: 1 | R16: 1 | S16: 1 | T16: 1 | U16: 1 | V16: 1 | W16: 1 | X16: 1 | Y16: 1 | Z16: 1 | AA16: 1 | AB16: 1 | AC16: 1 | AD16: 1 | AF16: =SUM(B16:AD16) -> 29 | AG16: =AF16/29 -> 1
A17: 15 | B17: 1 | C17: 1 | D17: 1 | E17: 1 | F17: 1 | G17: 1 | H17: 1 | I17: 1 | J17: 1 | K17: 1 | L17: 1 | M17: 1 | N17: 1 | O17: 1 | P17: 1 | Q17: 1 | R17: 1 | S17: 1 | T17: 1 | U17: 1 | V17: 1 | W17: 1 | X17: Dropout | Y17: Dropout | Z17: Dropout | AA17: Dropout | AB17: Dropout | AC17: Dropout | AD17: Dropout | AF17: =SUM(B17:AD17) -> 22 | AG17: =AF17/29 -> 0.75862069
A18: 16 | B18: Dropout | C18: Dropout | D18: Dropout | E18: Dropout | F18: Dropout | G18: Dropout | H18: Dropout | I18: Dropout | J18: Dropout | K18: Dropout | L18: Dropout | M18: Dropout | N18: Dropout | O18: Dropout | P18: Dropout | Q18: Dropout | R18: Dropout | S18: Dropout | T18: Dropout | U18: Dropout | V18: Dropout | W18: Dropout | X18: Dropout | Y18: Dropout | Z18: Dropout | AA18: Dropout | AB18: Dropout | AC18: Dropout | AD18: Dropout | AF18: =SUM(B18:AD18) -> 0 | AG18: =AF18/29 -> 0
A19: 17 | B19: Dropout | C19: Dropout | D19: Dropout | E19: Dropout | F19: 1 | G19: 1 | H19: 1 | I19: 1 | J19: Fail | K19: Fail | L19: Fail | M19: Fail | N19: 1 | O19: 1 | P19: 1 | Q19: 1 | R19: 1 | S19: 1 | T19: 1 | U19: 1 | V19: 1 | W19: 1 | X19: 1 | Y19: 1 | Z19: 1 | AA19: 1 | AB19: 1 | AC19: 1 | AD19: 1 | AF19: =SUM(B19:AD19) -> 21 | AG19: =AF19/29 -> 0.72413793
A20: 18 | B20: Dropout | C20: Dropout | D20: Dropout | E20: Dropout | F20: Dropout | G20: Dropout | H20: Dropout | I20: Dropout | J20: Dropout | K20: Dropout | L20: Dropout | M20: Dropout | N20: Dropout | O20: Dropout | P20: Dropout | Q20: Dropout | R20: Dropout | S20: Dropout | T20: Dropout | U20: Dropout | V20: Dropout | W20: Dropout | X20: Dropout | Y20: Dropout | Z20: Dropout | AA20: Dropout | AB20: Dropout | AC20: Dropout | AD20: Dropout | AF20: =SUM(B20:AD20) -> 0 | AG20: =AF20/29 -> 0
A21: 19 | B21: 1 | C21: 1 | D21: 1 | E21: 1 | F21: 1 | G21: 1 | H21: 1 | I21: 1 | J21: 1 | K21: 1 | L21: 1 | M21: 1 | N21: 1 | O21: 1 | P21: 1 | Q21: 1 | R21: 1 | S21: 1 | T21: 1 | U21: 1 | V21: 1 | W21: 1 | X21: 1 | Y21: 1 | Z21: 1 | AA21: 1 | AB21: 1 | AC21: 1 | AD21: 1 | AF21: =SUM(B21:AD21) -> 29 | AG21: =AF21/29 -> 1
A22: 20 | B22: Dropout | C22: Dropout | D22: Dropout | E22: Dropout | F22: Dropout | G22: Dropout | H22: Dropout | I22: Dropout | J22: Dropout | K22: Dropout | L22: Dropout | M22: Dropout | N22: Dropout | O22: Dropout | P22: Dropout | Q22: Dropout | R22: Dropout | S22: Dropout | T22: Dropout | U22: Dropout | V22: Dropout | W22: Dropout | X22: Dropout | Y22: Dropout | Z22: Dropout | AA22: Dropout | AB22: Dropout | AC22: Dropout | AD22: Dropout | AF22: =SUM(B22:AD22) -> 0 | AG22: =AF22/29 -> 0
A23: 21 | B23: 1 | C23: 1 | D23: 1 | E23: 1 | F23: 1 | G23: 1 | H23: 1 | I23: 1 | J23: 1 | K23: 1 | L23: 1 | M23: 1 | N23: 1 | O23: 1 | P23: 1 | Q23: 1 | R23: 1 | S23: 1 | T23: 1 | U23: 1 | V23: 1 | W23: 1 | X23: 1 | Y23: 1 | Z23: 1 | AA23: 1 | AB23: 1 | AC23: 1 | AD23: 1 | AF23: =SUM(B23:AD23) -> 29 | AG23: =AF23/29 -> 1
A24: 22 | B24: Dropout | C24: Dropout | D24: Dropout | E24: Dropout | F24: Dropout | G24: Dropout | H24: Dropout | I24: Dropout | J24: Dropout | K24: Dropout | L24: Dropout | M24: Dropout | N24: Dropout | O24: Dropout | P24: Dropout | Q24: Dropout | R24: Dropout | S24: Dropout | T24: Dropout | U24: Dropout | V24: Dropout | W24: Dropout | X24: Dropout | Y24: Dropout | Z24: Dropout | AA24: Dropout | AB24: Dropout | AC24: Dropout | AD24: Dropout | AF24: =SUM(B24:AD24) -> 0 | AG24: =AF24/29 -> 0
A25: 23 | B25: Dropout | C25: Dropout | D25: Dropout | E25: Dropout | F25: Dropout | G25: Dropout | H25: Dropout | I25: Dropout | J25: Dropout | K25: Dropout | L25: Dropout | M25: Dropout | N25: Dropout | O25: Dropout | P25: Dropout | Q25: Dropout | R25: Dropout | S25: Dropout | T25: Dropout | U25: Dropout | V25: Dropout | W25: Dropout | X25: Dropout | Y25: Dropout | Z25: Dropout | AA25: Dropout | AB25: Dropout | AC25: Dropout | AD25: Dropout | AF25: =SUM(B25:AD25) -> 0 | AG25: =AF25/29 -> 0
A26: 24 | B26: 1 | C26: 1 | D26: 1 | E26: 1 | F26: 1 | G26: 1 | H26: 1 | I26: 1 | J26: 1 | K26: 1 | L26: 1 | M26: 1 | N26: 1 | O26: 1 | P26: 1 | Q26: 1 | R26: 1 | S26: 1 | T26: 1 | U26: 1 | V26: 1 | W26: 1 | X26: 1 | Y26: 1 | Z26: 1 | AA26: 1 | AB26: 1 | AC26: 1 | AD26: 1 | AF26: =SUM(B26:AD26) -> 29 | AG26: =AF26/29 -> 1
A27: 25 | B27: 1 | C27: 1 | D27: 1 | E27: 1 | F27: 1 | G27: 1 | H27: 1 | I27: 1 | J27: 1 | K27: 1 | L27: 1 | M27: 1 | N27: 1 | O27: 1 | P27: 1 | Q27: 1 | R27: 1 | S27: 1 | T27: 1 | U27: 1 | V27: 1 | W27: 1 | X27: 1 | Y27: 1 | Z27: 1 | AA27: 1 | AB27: 1 | AC27: 1 | AD27: 1 | AF27: =SUM(B27:AD27) -> 29 | AG27: =AF27/29 -> 1
A28: 26 | B28: Dropout | C28: Dropout | D28: Dropout | E28: Dropout | F28: Dropout | G28: Dropout | H28: Dropout | I28: Dropout | J28: Dropout | K28: Dropout | L28: Dropout | M28: Dropout | N28: Dropout | O28: Dropout | P28: 1 | Q28: 1 | R28: 1 | S28: 1 | T28: 1 | U28: 1 | V28: Dropout | W28: Dropout | X28: Dropout | Y28: Dropout | Z28: Dropout | AA28: Dropout | AB28: Dropout | AC28: Dropout | AD28: Dropout | AF28: =SUM(B28:AD28) -> 6 | AG28: =AF28/29 -> 0.20689655
A29: 27 | B29: Dropout | C29: Dropout | D29: Dropout | E29: Dropout | F29: Dropout | G29: Dropout | H29: Dropout | I29: Dropout | J29: Dropout | K29: Dropout | L29: Dropout | M29: Dropout | N29: Dropout | O29: Dropout | P29: Dropout | Q29: Dropout | R29: Dropout | S29: Dropout | T29: Dropout | U29: Dropout | V29: Dropout | W29: Dropout | X29: Dropout | Y29: Dropout | Z29: Dropout | AA29: Dropout | AB29: Dropout | AC29: Dropout | AD29: Dropout | AF29: =SUM(B29:AD29) -> 0 | AG29: =AF29/29 -> 0
A30: 28 | B30: 1 | C30: 1 | D30: 1 | E30: 1 | F30: 1 | G30: 1 | H30: 1 | I30: 1 | J30: 1 | K30: 1 | L30: 1 | M30: 1 | N30: 1 | O30: 1 | P30: 1 | Q30: 1 | R30: 1 | S30: 1 | T30: 1 | U30: 1 | V30: 1 | W30: 1 | X30: 1 | Y30: 1 | Z30: 1 | AA30: 1 | AB30: 1 | AC30: 1 | AD30: 1 | AF30: =SUM(B30:AD30) -> 29 | AG30: =AF30/29 -> 1
A31: 29 | B31: Dropout | C31: Dropout | D31: Dropout | E31: Dropout | F31: Dropout | G31: Dropout | H31: 1 | I31: Fail | J31: Fail | K31: Fail | L31: Fail | M31: Fail | N31: Fail | O31: Fail | P31: Dropout | Q31: Dropout | R31: Dropout | S31: Dropout | T31: Dropout | U31: Dropout | V31: Dropout | W31: Dropout | X31: Dropout | Y31: Dropout | Z31: Dropout | AA31: Dropout | AB31: Dropout | AC31: Dropout | AD31: Dropout | AF31: =SUM(B31:AD31) -> 1 | AG31: =AF31/29 -> 0.034482759
A32: 30 | B32: Dropout | C32: Dropout | D32: Dropout | E32: Dropout | F32: Dropout | G32: Dropout | H32: Dropout | I32: Dropout | J32: Dropout | K32: Dropout | L32: Dropout | M32: Dropout | N32: Dropout | O32: Dropout | P32: Dropout | Q32: Dropout | R32: Dropout | S32: Dropout | T32: Dropout | U32: Dropout | V32: Dropout | W32: Dropout | X32: Dropout | Y32: Dropout | Z32: Dropout | AA32: Dropout | AB32: Dropout | AC32: Dropout | AD32: Dropout | AF32: =SUM(B32:AD32) -> 0 | AG32: =AF32/29 -> 0
A33: 31 | B33: 1 | C33: 1 | D33: 1 | E33: 1 | F33: 1 | G33: 1 | H33: 1 | I33: 1 | J33: 1 | K33: 1 | L33: 1 | M33: 1 | N33: 1 | O33: 1 | P33: 1 | Q33: 1 | R33: 1 | S33: 1 | T33: 1 | U33: 1 | V33: 1 | W33: 1 | X33: 1 | Y33: 1 | Z33: 1 | AA33: 1 | AB33: 1 | AC33: 1 | AD33: 1 | AF33: =SUM(B33:AD33) -> 29 | AG33: =AF33/29 -> 1
A34: 32 | B34: Dropout | C34: Dropout | D34: Dropout | E34: Dropout | F34: Dropout | G34: Dropout | H34: Dropout | I34: Dropout | J34: Dropout | K34: Dropout | L34: Dropout | M34: Dropout | N34: Dropout | O34: Dropout | P34: Dropout | Q34: Dropout | R34: Dropout | S34: Dropout | T34: Dropout | U34: Dropout | V34: Dropout | W34: Dropout | X34: Dropout | Y34: Dropout | Z34: Dropout | AA34: Dropout | AB34: Dropout | AC34: Dropout | AD34: Dropout | AF34: =SUM(B34:AD34) -> 0 | AG34: =AF34/29 -> 0
A35: 33 | B35: Dropout | C35: Dropout | D35: Dropout | E35: Dropout | F35: Dropout | G35: Dropout | H35: Dropout | I35: Dropout | J35: Dropout | K35: Dropout | L35: Dropout | M35: Dropout | N35: Dropout | O35: Dropout | P35: Dropout | Q35: Dropout | R35: Dropout | S35: Dropout | T35: Dropout | U35: Dropout | V35: Dropout | W35: Dropout | X35: Dropout | Y35: Dropout | Z35: Dropout | AA35: Dropout | AB35: Dropout | AC35: Dropout | AD35: Dropout | AF35: =SUM(B35:AD35) -> 0 | AG35: =AF35/29 -> 0
A36: 34 | B36: 1 | C36: 1 | D36: 1 | E36: 1 | F36: 1 | G36: 1 | H36: 1 | I36: 1 | J36: 1 | K36: 1 | L36: 1 | M36: 1 | N36: 1 | O36: 1 | P36: 1 | Q36: 1 | R36: 1 | S36: 1 | T36: 1 | U36: 1 | V36: 1 | W36: 1 | X36: 1 | Y36: 1 | Z36: 1 | AA36: 1 | AB36: 1 | AC36: 1 | AD36: 1 | AF36: =SUM(B36:AD36) -> 29 | AG36: =AF36/29 -> 1
A37: 35 | B37: 1 | C37: 1 | D37: 1 | E37: 1 | F37: 1 | G37: 1 | H37: 1 | I37: 1 | J37: 1 | K37: 1 | L37: 1 | M37: 1 | N37: 1 | O37: 1 | P37: 1 | Q37: 1 | R37: 1 | S37: 1 | T37: 1 | U37: 1 | V37: 1 | W37: 1 | X37: 1 | Y37: 1 | Z37: 1 | AA37: 1 | AB37: 1 | AC37: 1 | AD37: 1 | AF37: =SUM(B37:AD37) -> 29 | AG37: =AF37/29 -> 1
A38: 36 | B38: Dropout | C38: Dropout | D38: Dropout | E38: Dropout | F38: Dropout | G38: Dropout | H38: Dropout | I38: Dropout | J38: Dropout | K38: Dropout | L38: Dropout | M38: Dropout | N38: Dropout | O38: Dropout | P38: Dropout | Q38: Dropout | R38: Dropout | S38: Dropout | T38: Dropout | U38: Dropout | V38: Dropout | W38: Dropout | X38: Dropout | Y38: Dropout | Z38: Dropout | AA38: Dropout | AB38: Dropout | AC38: Dropout | AD38: Dropout | AF38: =SUM(B38:AD38) -> 0 | AG38: =AF38/29 -> 0
A39: 37 | B39: Dropout | C39: Dropout | D39: Dropout | E39: Dropout | F39: Dropout | G39: Dropout | H39: Dropout | I39: Dropout | J39: Dropout | K39: Dropout | L39: Dropout | M39: Dropout | N39: Dropout | O39: Dropout | P39: 1 | Q39: 1 | R39: Dropout | S39: Dropout | T39: 1 | U39: 1 | V39: 1 | W39: 1 | X39: 1 | Y39: 1 | Z39: 1 | AA39: 1 | AB39: 1 | AC39: 1 | AD39: 1 | AF39: =SUM(B39:AD39) -> 13 | AG39: =AF39/29 -> 0.44827586
A40: 38 | B40: 1 | C40: 1 | D40: 1 | E40: 1 | F40: 1 | G40: 1 | H40: 1 | I40: 1 | J40: 1 | K40: 1 | L40: 1 | M40: 1 | N40: 1 | O40: 1 | P40: 1 | Q40: 1 | R40: 1 | S40: 1 | T40: 1 | U40: 1 | V40: 1 | W40: 1 | X40: 1 | Y40: 1 | Z40: 1 | AA40: 1 | AB40: 1 | AC40: 1 | AD40: 1 | AF40: =SUM(B40:AD40) -> 29 | AG40: =AF40/29 -> 1
...

Sheet probaFail
A1: ID_Student | B1: 1 | C1: 2 | D1: 3 | E1: 4 | F1: 5 | G1: 6 | H1: 7 | I1: 8 | J1: 9 | K1: 10 | L1: 11 | M1: 12 | N1: 13 | O1: 14 | P1: 15 | Q1: 16 | R1: 17 | S1: 18 | T1: 19 | U1: 20 | V1: 21 | W1: 22 | X1: 23 | Y1: 24 | Z1: 25 | AA1: 26 | AB1: 27 | AC1: 28 | AD1: 29 | AF1: 0 | AG1: Fail | AH1: Proba_fail
A2: 0 | B2: Dropout | C2: Pass | D2: Pass | E2: Pass | F2: Dropout | G2: Dropout | H2: Dropout | I2: Dropout | J2: Dropout | K2: Dropout | L2: Dropout | M2: Dropout | N2: Dropout | O2: Dropout | P2: Dropout | Q2: Dropout | R2: Dropout | S2: Dropout | T2: Dropout | U2: Dropout | V2: Dropout | W2: Dropout | X2: Dropout | Y2: Dropout | Z2: Dropout | AA2: Dropout | AB2: Dropout | AC2: Dropout | AD2: Dropout | AG2: =SUM(B2:AD2) -> 0 | AH2: =AG2/29 -> 0
A3: 1 | B3: Dropout | C3: Dropout | D3: Dropout | E3: Dropout | F3: Dropout | G3: Dropout | H3: Dropout | I3: Dropout | J3: Dropout | K3: Dropout | L3: Dropout | M3: Dropout | N3: Dropout | O3: Dropout | P3: Dropout | Q3: Dropout | R3: Dropout | S3: Dropout | T3: Dropout | U3: Dropout | V3: Dropout | W3: Dropout | X3: Dropout | Y3: Dropout | Z3: Dropout | AA3: Dropout | AB3: Dropout | AC3: Dropout | AD3: Dropout | AG3: =SUM(B3:AD3) -> 0 | AH3: =AG3/29 -> 0
A4: 2 | B4: Pass | C4: Pass | D4: Pass | E4: Pass | F4: Pass | G4: Pass | H4: Pass | I4: Pass | J4: Pass | K4: Pass | L4: Pass | M4: Pass | N4: Pass | O4: Pass | P4: Pass | Q4: Pass | R4: Pass | S4: Pass | T4: Pass | U4: Pass | V4: Pass | W4: Pass | X4: Pass | Y4: Pass | Z4: Pass | AA4: Pass | AB4: Pass | AC4: Pass | AD4: Pass | AG4: =SUM(B4:AD4) -> 0 | AH4: =AG4/29 -> 0
A5: 3 | B5: Pass | C5: Pass | D5: Pass | E5: Pass | F5: Pass | G5: Pass | H5: Pass | I5: Pass | J5: Pass | K5: Pass | L5: Pass | M5: Pass | N5: Pass | O5: Pass | P5: Pass | Q5: Pass | R5: Pass | S5: Pass | T5: Pass | U5: Pass | V5: Pass | W5: Pass | X5: Pass | Y5: Pass | Z5: Pass | AA5: Pass | AB5: Pass | AC5: Pass | AD5: Pass | AG5: =SUM(B5:AD5) -> 0 | AH5: =AG5/29 -> 0
A6: 4 | B6: Dropout | C6: Dropout | D6: Dropout | E6: Dropout | F6: Dropout | G6: Dropout | H6: Dropout | I6: Dropout | J6: 1 | K6: 1 | L6: 1 | M6: 1 | N6: 1 | O6: 1 | P6: Dropout | Q6: Dropout | R6: Dropout | S6: Dropout | T6: Dropout | U6: Dropout | V6: Dropout | W6: Dropout | X6: Dropout | Y6: Dropout | Z6: Dropout | AA6: Dropout | AB6: Dropout | AC6: Dropout | AD6: Dropout | AG6: =SUM(B6:AD6) -> 6 | AH6: =AG6/29 -> 0.20689655
A7: 5 | B7: Dropout | C7: Dropout | D7: Dropout | E7: Dropout | F7: Dropout | G7: Dropout | H7: Dropout | I7: Dropout | J7: Dropout | K7: Dropout | L7: Dropout | M7: Dropout | N7: Dropout | O7: Dropout | P7: Dropout | Q7: Dropout | R7: Dropout | S7: Dropout | T7: Dropout | U7: Dropout | V7: Pass | W7: Pass | X7: Pass | Y7: Pass | Z7: Pass | AA7: Pass | AB7: Pass | AC7: Pass | AD7: Pass | AG7: =SUM(B7:AD7) -> 0 | AH7: =AG7/29 -> 0
A8: 6 | B8: Dropout | C8: Dropout | D8: Dropout | E8: Dropout | F8: Dropout | G8: Dropout | H8: Dropout | I8: Dropout | J8: Dropout | K8: Dropout | L8: Dropout | M8: Dropout | N8: Dropout | O8: Dropout | P8: Dropout | Q8: Dropout | R8: Dropout | S8: Dropout | T8: Dropout | U8: Dropout | V8: Dropout | W8: Dropout | X8: Dropout | Y8: Dropout | Z8: Dropout | AA8: Dropout | AB8: Dropout | AC8: Dropout | AD8: Dropout | AG8: =SUM(B8:AD8) -> 0 | AH8: =AG8/29 -> 0
A9: 7 | B9: Pass | C9: Pass | D9: Pass | E9: Pass | F9: Pass | G9: Pass | H9: Pass | I9: Pass | J9: Pass | K9: Pass | L9: Pass | M9: Pass | N9: Pass | O9: Pass | P9: Pass | Q9: Pass | R9: Pass | S9: Pass | T9: Pass | U9: Pass | V9: Pass | W9: Pass | X9: Pass | Y9: Pass | Z9: Pass | AA9: Pass | AB9: Pass | AC9: Pass | AD9: Pass | AG9: =SUM(B9:AD9) -> 0 | AH9: =AG9/29 -> 0
A10: 8 | B10: Pass | C10: Pass | D10: Pass | E10: Pass | F10: Pass | G10: Pass | H10: Pass | I10: Pass | J10: Pass | K10: Pass | L10: Pass | M10: Pass | N10: Pass | O10: Pass | P10: Pass | Q10: Pass | R10: Pass | S10: Pass | T10: Pass | U10: Pass | V10: Pass | W10: Pass | X10: Pass | Y10: Pass | Z10: Pass | AA10: Pass | AB10: Pass | AC10: Pass | AD10: Pass | AG10: =SUM(B10:AD10) -> 0 | AH10: =AG10/29 -> 0
A11: 9 | B11: Dropout | C11: Dropout | D11: Dropout | E11: Dropout | F11: Pass | G11: Dropout | H11: Dropout | I11: Dropout | J11: Dropout | K11: Dropout | L11: Dropout | M11: Dropout | N11: Dropout | O11: Dropout | P11: Dropout | Q11: Dropout | R11: Dropout | S11: Dropout | T11: Dropout | U11: Dropout | V11: Dropout | W11: Dropout | X11: Dropout | Y11: Dropout | Z11: Dropout | AA11: Dropout | AB11: Dropout | AC11: Dropout | AD11: Dropout | AG11: =SUM(B11:AD11) -> 0 | AH11: =AG11/29 -> 0
A12: 10 | B12: Pass | C12: Pass | D12: Pass | E12: Pass | F12: Pass | G12: Pass | H12: Pass | I12: Pass | J12: Pass | K12: Pass | L12: Pass | M12: Pass | N12: Pass | O12: Pass | P12: Pass | Q12: Pass | R12: Pass | S12: Pass | T12: Pass | U12: Pass | V12: Pass | W12: Pass | X12: Pass | Y12: Pass | Z12: Pass | AA12: Pass | AB12: Pass | AC12: Pass | AD12: Pass | AG12: =SUM(B12:AD12) -> 0 | AH12: =AG12/29 -> 0
A13: 11 | B13: Dropout | C13: Dropout | D13: Dropout | E13: Dropout | F13: Dropout | G13: Dropout | H13: Dropout | I13: Dropout | J13: Pass | K13: Pass | L13: Pass | M13: Pass | N13: Pass | O13: Pass | P13: Pass | Q13: Pass | R13: Pass | S13: Pass | T13: Pass | U13: Pass | V13: Pass | W13: Pass | X13: Pass | Y13: Pass | Z13: Pass | AA13: Pass | AB13: Pass | AC13: Pass | AD13: Pass | AG13: =SUM(B13:AD13) -> 0 | AH13: =AG13/29 -> 0
A14: 12 | B14: Pass | C14: Pass | D14: Pass | E14: Pass | F14: Pass | G14: Pass | H14: Pass | I14: Pass | J14: Pass | K14: Pass | L14: Pass | M14: Pass | N14: Pass | O14: Pass | P14: Pass | Q14: Pass | R14: Pass | S14: Pass | T14: Pass | U14: Pass | V14: Pass | W14: Pass | X14: Pass | Y14: Pass | Z14: Pass | AA14: Pass | AB14: Pass | AC14: Pass | AD14: Pass | AG14: =SUM(B14:AD14) -> 0 | AH14: =AG14/29 -> 0
A15: 13 | B15: Dropout | C15: Dropout | D15: Dropout | E15: Dropout | F15: Dropout | G15: Dropout | H15: Dropout | I15: Dropout | J15: Dropout | K15: Dropout | L15: Dropout | M15: Dropout | N15: Dropout | O15: Dropout | P15: Dropout | Q15: Dropout | R15: Dropout | S15: Dropout | T15: Dropout | U15: Dropout | V15: Dropout | W15: Dropout | X15: Dropout | Y15: Dropout | Z15: Dropout | AA15: Dropout | AB15: Dropout | AC15: Dropout | AD15: Dropout | AG15: =SUM(B15:AD15) -> 0 | AH15: =AG15/29 -> 0
A16: 14 | B16: Pass | C16: Pass | D16: Pass | E16: Pass | F16: Pass | G16: Pass | H16: Pass | I16: Pass | J16: Pass | K16: Pass | L16: Pass | M16: Pass | N16: Pass | O16: Pass | P16: Pass | Q16: Pass | R16: Pass | S16: Pass | T16: Pass | U16: Pass | V16: Pass | W16: Pass | X16: Pass | Y16: Pass | Z16: Pass | AA16: Pass | AB16: Pass | AC16: Pass | AD16: Pass | AG16: =SUM(B16:AD16) -> 0 | AH16: =AG16/29 -> 0
A17: 15 | B17: Pass | C17: Pass | D17: Pass | E17: Pass | F17: Pass | G17: Pass | H17: Pass | I17: Pass | J17: Pass | K17: Pass | L17: Pass | M17: Pass | N17: Pass | O17: Pass | P17: Pass | Q17: Pass | R17: Pass | S17: Pass | T17: Pass | U17: Pass | V17: Pass | W17: Pass | X17: Dropout | Y17: Dropout | Z17: Dropout | AA17: Dropout | AB17: Dropout | AC17: Dropout | AD17: Dropout | AG17: =SUM(B17:AD17) -> 0 | AH17: =AG17/29 -> 0
A18: 16 | B18: Dropout | C18: Dropout | D18: Dropout | E18: Dropout | F18: Dropout | G18: Dropout | H18: Dropout | I18: Dropout | J18: Dropout | K18: Dropout | L18: Dropout | M18: Dropout | N18: Dropout | O18: Dropout | P18: Dropout | Q18: Dropout | R18: Dropout | S18: Dropout | T18: Dropout | U18: Dropout | V18: Dropout | W18: Dropout | X18: Dropout | Y18: Dropout | Z18: Dropout | AA18: Dropout | AB18: Dropout | AC18: Dropout | AD18: Dropout | AG18: =SUM(B18:AD18) -> 0 | AH18: =AG18/29 -> 0
A19: 17 | B19: Dropout | C19: Dropout | D19: Dropout | E19: Dropout | F19: Pass | G19: Pass | H19: Pass | I19: Pass | J19: 1 | K19: 1 | L19: 1 | M19: 1 | N19: Pass | O19: Pass | P19: Pass | Q19: Pass | R19: Pass | S19: Pass | T19: Pass | U19: Pass | V19: Pass | W19: Pass | X19: Pass | Y19: Pass | Z19: Pass | AA19: Pass | AB19: Pass | AC19: Pass | AD19: Pass | AG19: =SUM(B19:AD19) -> 4 | AH19: =AG19/29 -> 0.13793103
A20: 18 | B20: Dropout | C20: Dropout | D20: Dropout | E20: Dropout | F20: Dropout | G20: Dropout | H20: Dropout | I20: Dropout | J20: Dropout | K20: Dropout | L20: Dropout | M20: Dropout | N20: Dropout | O20: Dropout | P20: Dropout | Q20: Dropout | R20: Dropout | S20: Dropout | T20: Dropout | U20: Dropout | V20: Dropout | W20: Dropout | X20: Dropout | Y20: Dropout | Z20: Dropout | AA20: Dropout | AB20: Dropout | AC20: Dropout | AD20: Dropout | AG20: =SUM(B20:AD20) -> 0 | AH20: =AG20/29 -> 0
A21: 19 | B21: Pass | C21: Pass | D21: Pass | E21: Pass | F21: Pass | G21: Pass | H21: Pass | I21: Pass | J21: Pass | K21: Pass | L21: Pass | M21: Pass | N21: Pass | O21: Pass | P21: Pass | Q21: Pass | R21: Pass | S21: Pass | T21: Pass | U21: Pass | V21: Pass | W21: Pass | X21: Pass | Y21: Pass | Z21: Pass | AA21: Pass | AB21: Pass | AC21: Pass | AD21: Pass | AG21: =SUM(B21:AD21) -> 0 | AH21: =AG21/29 -> 0
A22: 20 | B22: Dropout | C22: Dropout | D22: Dropout | E22: Dropout | F22: Dropout | G22: Dropout | H22: Dropout | I22: Dropout | J22: Dropout | K22: Dropout | L22: Dropout | M22: Dropout | N22: Dropout | O22: Dropout | P22: Dropout | Q22: Dropout | R22: Dropout | S22: Dropout | T22: Dropout | U22: Dropout | V22: Dropout | W22: Dropout | X22: Dropout | Y22: Dropout | Z22: Dropout | AA22: Dropout | AB22: Dropout | AC22: Dropout | AD22: Dropout | AG22: =SUM(B22:AD22) -> 0 | AH22: =AG22/29 -> 0
A23: 21 | B23: Pass | C23: Pass | D23: Pass | E23: Pass | F23: Pass | G23: Pass | H23: Pass | I23: Pass | J23: Pass | K23: Pass | L23: Pass | M23: Pass | N23: Pass | O23: Pass | P23: Pass | Q23: Pass | R23: Pass | S23: Pass | T23: Pass | U23: Pass | V23: Pass | W23: Pass | X23: Pass | Y23: Pass | Z23: Pass | AA23: Pass | AB23: Pass | AC23: Pass | AD23: Pass | AG23: =SUM(B23:AD23) -> 0 | AH23: =AG23/29 -> 0
A24: 22 | B24: Dropout | C24: Dropout | D24: Dropout | E24: Dropout | F24: Dropout | G24: Dropout | H24: Dropout | I24: Dropout | J24: Dropout | K24: Dropout | L24: Dropout | M24: Dropout | N24: Dropout | O24: Dropout | P24: Dropout | Q24: Dropout | R24: Dropout | S24: Dropout | T24: Dropout | U24: Dropout | V24: Dropout | W24: Dropout | X24: Dropout | Y24: Dropout | Z24: Dropout | AA24: Dropout | AB24: Dropout | AC24: Dropout | AD24: Dropout | AG24: =SUM(B24:AD24) -> 0 | AH24: =AG24/29 -> 0
A25: 23 | B25: Dropout | C25: Dropout | D25: Dropout | E25: Dropout | F25: Dropout | G25: Dropout | H25: Dropout | I25: Dropout | J25: Dropout | K25: Dropout | L25: Dropout | M25: Dropout | N25: Dropout | O25: Dropout | P25: Dropout | Q25: Dropout | R25: Dropout | S25: Dropout | T25: Dropout | U25: Dropout | V25: Dropout | W25: Dropout | X25: Dropout | Y25: Dropout | Z25: Dropout | AA25: Dropout | AB25: Dropout | AC25: Dropout | AD25: Dropout | AG25: =SUM(B25:AD25) -> 0 | AH25: =AG25/29 -> 0
A26: 24 | B26: Pass | C26: Pass | D26: Pass | E26: Pass | F26: Pass | G26: Pass | H26: Pass | I26: Pass | J26: Pass | K26: Pass | L26: Pass | M26: Pass | N26: Pass | O26: Pass | P26: Pass | Q26: Pass | R26: Pass | S26: Pass | T26: Pass | U26: Pass | V26: Pass | W26: Pass | X26: Pass | Y26: Pass | Z26: Pass | AA26: Pass | AB26: Pass | AC26: Pass | AD26: Pass | AG26: =SUM(B26:AD26) -> 0 | AH26: =AG26/29 -> 0
A27: 25 | B27: Pass | C27: Pass | D27: Pass | E27: Pass | F27: Pass | G27: Pass | H27: Pass | I27: Pass | J27: Pass | K27: Pass | L27: Pass | M27: Pass | N27: Pass | O27: Pass | P27: Pass | Q27: Pass | R27: Pass | S27: Pass | T27: Pass | U27: Pass | V27: Pass | W27: Pass | X27: Pass | Y27: Pass | Z27: Pass | AA27: Pass | AB27: Pass | AC27: Pass | AD27: Pass | AG27: =SUM(B27:AD27) -> 0 | AH27: =AG27/29 -> 0
A28: 26 | B28: Dropout | C28: Dropout | D28: Dropout | E28: Dropout | F28: Dropout | G28: Dropout | H28: Dropout | I28: Dropout | J28: Dropout | K28: Dropout | L28: Dropout | M28: Dropout | N28: Dropout | O28: Dropout | P28: Pass | Q28: Pass | R28: Pass | S28: Pass | T28: Pass | U28: Pass | V28: Dropout | W28: Dropout | X28: Dropout | Y28: Dropout | Z28: Dropout | AA28: Dropout | AB28: Dropout | AC28: Dropout | AD28: Dropout | AG28: =SUM(B28:AD28) -> 0 | AH28: =AG28/29 -> 0
A29: 27 | B29: Dropout | C29: Dropout | D29: Dropout | E29: Dropout | F29: Dropout | G29: Dropout | H29: Dropout | I29: Dropout | J29: Dropout | K29: Dropout | L29: Dropout | M29: Dropout | N29: Dropout | O29: Dropout | P29: Dropout | Q29: Dropout | R29: Dropout | S29: Dropout | T29: Dropout | U29: Dropout | V29: Dropout | W29: Dropout | X29: Dropout | Y29: Dropout | Z29: Dropout | AA29: Dropout | AB29: Dropout | AC29: Dropout | AD29: Dropout | AG29: =SUM(B29:AD29) -> 0 | AH29: =AG29/29 -> 0
A30: 28 | B30: Pass | C30: Pass | D30: Pass | E30: Pass | F30: Pass | G30: Pass | H30: Pass | I30: Pass | J30: Pass | K30: Pass | L30: Pass | M30: Pass | N30: Pass | O30: Pass | P30: Pass | Q30: Pass | R30: Pass | S30: Pass | T30: Pass | U30: Pass | V30: Pass | W30: Pass | X30: Pass | Y30: Pass | Z30: Pass | AA30: Pass | AB30: Pass | AC30: Pass | AD30: Pass | AG30: =SUM(B30:AD30) -> 0 | AH30: =AG30/29 -> 0
A31: 29 | B31: Dropout | C31: Dropout | D31: Dropout | E31: Dropout | F31: Dropout | G31: Dropout | H31: Pass | I31: 1 | J31: 1 | K31: 1 | L31: 1 | M31: 1 | N31: 1 | O31: 1 | P31: Dropout | Q31: Dropout | R31: Dropout | S31: Dropout | T31: Dropout | U31: Dropout | V31: Dropout | W31: Dropout | X31: Dropout | Y31: Dropout | Z31: Dropout | AA31: Dropout | AB31: Dropout | AC31: Dropout | AD31: Dropout | AG31: =SUM(B31:AD31) -> 7 | AH31: =AG31/29 -> 0.24137931
A32: 30 | B32: Dropout | C32: Dropout | D32: Dropout | E32: Dropout | F32: Dropout | G32: Dropout | H32: Dropout | I32: Dropout | J32: Dropout | K32: Dropout | L32: Dropout | M32: Dropout | N32: Dropout | O32: Dropout | P32: Dropout | Q32: Dropout | R32: Dropout | S32: Dropout | T32: Dropout | U32: Dropout | V32: Dropout | W32: Dropout | X32: Dropout | Y32: Dropout | Z32: Dropout | AA32: Dropout | AB32: Dropout | AC32: Dropout | AD32: Dropout | AG32: =SUM(B32:AD32) -> 0 | AH32: =AG32/29 -> 0
A33: 31 | B33: Pass | C33: Pass | D33: Pass | E33: Pass | F33: Pass | G33: Pass | H33: Pass | I33: Pass | J33: Pass | K33: Pass | L33: Pass | M33: Pass | N33: Pass | O33: Pass | P33: Pass | Q33: Pass | R33: Pass | S33: Pass | T33: Pass | U33: Pass | V33: Pass | W33: Pass | X33: Pass | Y33: Pass | Z33: Pass | AA33: Pass | AB33: Pass | AC33: Pass | AD33: Pass | AG33: =SUM(B33:AD33) -> 0 | AH33: =AG33/29 -> 0
A34: 32 | B34: Dropout | C34: Dropout | D34: Dropout | E34: Dropout | F34: Dropout | G34: Dropout | H34: Dropout | I34: Dropout | J34: Dropout | K34: Dropout | L34: Dropout | M34: Dropout | N34: Dropout | O34: Dropout | P34: Dropout | Q34: Dropout | R34: Dropout | S34: Dropout | T34: Dropout | U34: Dropout | V34: Dropout | W34: Dropout | X34: Dropout | Y34: Dropout | Z34: Dropout | AA34: Dropout | AB34: Dropout | AC34: Dropout | AD34: Dropout | AG34: =SUM(B34:AD34) -> 0 | AH34: =AG34/29 -> 0
A35: 33 | B35: Dropout | C35: Dropout | D35: Dropout | E35: Dropout | F35: Dropout | G35: Dropout | H35: Dropout | I35: Dropout | J35: Dropout | K35: Dropout | L35: Dropout | M35: Dropout | N35: Dropout | O35: Dropout | P35: Dropout | Q35: Dropout | R35: Dropout | S35: Dropout | T35: Dropout | U35: Dropout | V35: Dropout | W35: Dropout | X35: Dropout | Y35: Dropout | Z35: Dropout | AA35: Dropout | AB35: Dropout | AC35: Dropout | AD35: Dropout | AG35: =SUM(B35:AD35) -> 0 | AH35: =AG35/29 -> 0
A36: 34 | B36: Pass | C36: Pass | D36: Pass | E36: Pass | F36: Pass | G36: Pass | H36: Pass | I36: Pass | J36: Pass | K36: Pass | L36: Pass | M36: Pass | N36: Pass | O36: Pass | P36: Pass | Q36: Pass | R36: Pass | S36: Pass | T36: Pass | U36: Pass | V36: Pass | W36: Pass | X36: Pass | Y36: Pass | Z36: Pass | AA36: Pass | AB36: Pass | AC36: Pass | AD36: Pass | AG36: =SUM(B36:AD36) -> 0 | AH36: =AG36/29 -> 0
A37: 35 | B37: Pass | C37: Pass | D37: Pass | E37: Pass | F37: Pass | G37: Pass | H37: Pass | I37: Pass | J37: Pass | K37: Pass | L37: Pass | M37: Pass | N37: Pass | O37: Pass | P37: Pass | Q37: Pass | R37: Pass | S37: Pass | T37: Pass | U37: Pass | V37: Pass | W37: Pass | X37: Pass | Y37: Pass | Z37: Pass | AA37: Pass | AB37: Pass | AC37: Pass | AD37: Pass | AG37: =SUM(B37:AD37) -> 0 | AH37: =AG37/29 -> 0
A38: 36 | B38: Dropout | C38: Dropout | D38: Dropout | E38: Dropout | F38: Dropout | G38: Dropout | H38: Dropout | I38: Dropout | J38: Dropout | K38: Dropout | L38: Dropout | M38: Dropout | N38: Dropout | O38: Dropout | P38: Dropout | Q38: Dropout | R38: Dropout | S38: Dropout | T38: Dropout | U38: Dropout | V38: Dropout | W38: Dropout | X38: Dropout | Y38: Dropout | Z38: Dropout | AA38: Dropout | AB38: Dropout | AC38: Dropout | AD38: Dropout | AG38: =SUM(B38:AD38) -> 0 | AH38: =AG38/29 -> 0
A39: 37 | B39: Dropout | C39: Dropout | D39: Dropout | E39: Dropout | F39: Dropout | G39: Dropout | H39: Dropout | I39: Dropout | J39: Dropout | K39: Dropout | L39: Dropout | M39: Dropout | N39: Dropout | O39: Dropout | P39: Pass | Q39: Pass | R39: Dropout | S39: Dropout | T39: Pass | U39: Pass | V39: Pass | W39: Pass | X39: Pass | Y39: Pass | Z39: Pass | AA39: Pass | AB39: Pass | AC39: Pass | AD39: Pass | AG39: =SUM(B39:AD39) -> 0 | AH39: =AG39/29 -> 0
A40: 38 | B40: Pass | C40: Pass | D40: Pass | E40: Pass | F40: Pass | G40: Pass | H40: Pass | I40: Pass | J40: Pass | K40: Pass | L40: Pass | M40: Pass | N40: Pass | O40: Pass | P40: Pass | Q40: Pass | R40: Pass | S40: Pass | T40: Pass | U40: Pass | V40: Pass | W40: Pass | X40: Pass | Y40: Pass | Z40: Pass | AA40: Pass | AB40: Pass | AC40: Pass | AD40: Pass | AG40: =SUM(B40:AD40) -> 0 | AH40: =AG40/29 -> 0
...

Sheet probaDropout
A1: ID_Student | B1: 1 | C1: 2 | D1: 3 | E1: 4 | F1: 5 | G1: 6 | H1: 7 | I1: 8 | J1: 9 | K1: 10 | L1: 11 | M1: 12 | N1: 13 | O1: 14 | P1: 15 | Q1: 16 | R1: 17 | S1: 18 | T1: 19 | U1: 20 | V1: 21 | W1: 22 | X1: 23 | Y1: 24 | Z1: 25 | AA1: 26 | AB1: 27 | AC1: 28 | AD1: 29 | AF1: 0 | AG1: 0 | AH1: Dropout | AI1: Proba_dropout
A2: 0 | B2: 1 | C2: Pass | D2: Pass | E2: Pass | F2: 1 | G2: 1 | H2: 1 | I2: 1 | J2: 1 | K2: 1 | L2: 1 | M2: 1 | N2: 1 | O2: 1 | P2: 1 | Q2: 1 | R2: 1 | S2: 1 | T2: 1 | U2: 1 | V2: 1 | W2: 1 | X2: 1 | Y2: 1 | Z2: 1 | AA2: 1 | AB2: 1 | AC2: 1 | AD2: 1 | AH2: =SUM(B2:AD2) -> 26 | AI2: =AH2/29 -> 0.89655172
A3: 1 | B3: 1 | C3: 1 | D3: 1 | E3: 1 | F3: 1 | G3: 1 | H3: 1 | I3: 1 | J3: 1 | K3: 1 | L3: 1 | M3: 1 | N3: 1 | O3: 1 | P3: 1 | Q3: 1 | R3: 1 | S3: 1 | T3: 1 | U3: 1 | V3: 1 | W3: 1 | X3: 1 | Y3: 1 | Z3: 1 | AA3: 1 | AB3: 1 | AC3: 1 | AD3: 1 | AH3: =SUM(B3:AD3) -> 29 | AI3: =AH3/29 -> 1
A4: 2 | B4: Pass | C4: Pass | D4: Pass | E4: Pass | F4: Pass | G4: Pass | H4: Pass | I4: Pass | J4: Pass | K4: Pass | L4: Pass | M4: Pass | N4: Pass | O4: Pass | P4: Pass | Q4: Pass | R4: Pass | S4: Pass | T4: Pass | U4: Pass | V4: Pass | W4: Pass | X4: Pass | Y4: Pass | Z4: Pass | AA4: Pass | AB4: Pass | AC4: Pass | AD4: Pass | AH4: =SUM(B4:AD4) -> 0 | AI4: =AH4/29 -> 0
A5: 3 | B5: Pass | C5: Pass | D5: Pass | E5: Pass | F5: Pass | G5: Pass | H5: Pass | I5: Pass | J5: Pass | K5: Pass | L5: Pass | M5: Pass | N5: Pass | O5: Pass | P5: Pass | Q5: Pass | R5: Pass | S5: Pass | T5: Pass | U5: Pass | V5: Pass | W5: Pass | X5: Pass | Y5: Pass | Z5: Pass | AA5: Pass | AB5: Pass | AC5: Pass | AD5: Pass | AH5: =SUM(B5:AD5) -> 0 | AI5: =AH5/29 -> 0
A6: 4 | B6: 1 | C6: 1 | D6: 1 | E6: 1 | F6: 1 | G6: 1 | H6: 1 | I6: 1 | J6: Fail | K6: Fail | L6: Fail | M6: Fail | N6: Fail | O6: Fail | P6: 1 | Q6: 1 | R6: 1 | S6: 1 | T6: 1 | U6: 1 | V6: 1 | W6: 1 | X6: 1 | Y6: 1 | Z6: 1 | AA6: 1 | AB6: 1 | AC6: 1 | AD6: 1 | AH6: =SUM(B6:AD6) -> 23 | AI6: =AH6/29 -> 0.79310345
A7: 5 | B7: 1 | C7: 1 | D7: 1 | E7: 1 | F7: 1 | G7: 1 | H7: 1 | I7: 1 | J7: 1 | K7: 1 | L7: 1 | M7: 1 | N7: 1 | O7: 1 | P7: 1 | Q7: 1 | R7: 1 | S7: 1 | T7: 1 | U7: 1 | V7: Pass | W7: Pass | X7: Pass | Y7: Pass | Z7: Pass | AA7: Pass | AB7: Pass | AC7: Pass | AD7: Pass | AH7: =SUM(B7:AD7) -> 20 | AI7: =AH7/29 -> 0.68965517
A8: 6 | B8: 1 | C8: 1 | D8: 1 | E8: 1 | F8: 1 | G8: 1 | H8: 1 | I8: 1 | J8: 1 | K8: 1 | L8: 1 | M8: 1 | N8: 1 | O8: 1 | P8: 1 | Q8: 1 | R8: 1 | S8: 1 | T8: 1 | U8: 1 | V8: 1 | W8: 1 | X8: 1 | Y8: 1 | Z8: 1 | AA8: 1 | AB8: 1 | AC8: 1 | AD8: 1 | AH8: =SUM(B8:AD8) -> 29 | AI8: =AH8/29 -> 1
A9: 7 | B9: Pass | C9: Pass | D9: Pass | E9: Pass | F9: Pass | G9: Pass | H9: Pass | I9: Pass | J9: Pass | K9: Pass | L9: Pass | M9: Pass | N9: Pass | O9: Pass | P9: Pass | Q9: Pass | R9: Pass | S9: Pass | T9: Pass | U9: Pass | V9: Pass | W9: Pass | X9: Pass | Y9: Pass | Z9: Pass | AA9: Pass | AB9: Pass | AC9: Pass | AD9: Pass | AH9: =SUM(B9:AD9) -> 0 | AI9: =AH9/29 -> 0
A10: 8 | B10: Pass | C10: Pass | D10: Pass | E10: Pass | F10: Pass | G10: Pass | H10: Pass | I10: Pass | J10: Pass | K10: Pass | L10: Pass | M10: Pass | N10: Pass | O10: Pass | P10: Pass | Q10: Pass | R10: Pass | S10: Pass | T10: Pass | U10: Pass | V10: Pass | W10: Pass | X10: Pass | Y10: Pass | Z10: Pass | AA10: Pass | AB10: Pass | AC10: Pass | AD10: Pass | AH10: =SUM(B10:AD10) -> 0 | AI10: =AH10/29 -> 0
A11: 9 | B11: 1 | C11: 1 | D11: 1 | E11: 1 | F11: Pass | G11: 1 | H11: 1 | I11: 1 | J11: 1 | K11: 1 | L11: 1 | M11: 1 | N11: 1 | O11: 1 | P11: 1 | Q11: 1 | R11: 1 | S11: 1 | T11: 1 | U11: 1 | V11: 1 | W11: 1 | X11: 1 | Y11: 1 | Z11: 1 | AA11: 1 | AB11: 1 | AC11: 1 | AD11: 1 | AH11: =SUM(B11:AD11) -> 28 | AI11: =AH11/29 -> 0.96551724
A12: 10 | B12: Pass | C12: Pass | D12: Pass | E12: Pass | F12: Pass | G12: Pass | H12: Pass | I12: Pass | J12: Pass | K12: Pass | L12: Pass | M12: Pass | N12: Pass | O12: Pass | P12: Pass | Q12: Pass | R12: Pass | S12: Pass | T12: Pass | U12: Pass | V12: Pass | W12: Pass | X12: Pass | Y12: Pass | Z12: Pass | AA12: Pass | AB12: Pass | AC12: Pass | AD12: Pass | AH12: =SUM(B12:AD12) -> 0 | AI12: =AH12/29 -> 0
A13: 11 | B13: 1 | C13: 1 | D13: 1 | E13: 1 | F13: 1 | G13: 1 | H13: 1 | I13: 1 | J13: Pass | K13: Pass | L13: Pass | M13: Pass | N13: Pass | O13: Pass | P13: Pass | Q13: Pass | R13: Pass | S13: Pass | T13: Pass | U13: Pass | V13: Pass | W13: Pass | X13: Pass | Y13: Pass | Z13: Pass | AA13: Pass | AB13: Pass | AC13: Pass | AD13: Pass | AH13: =SUM(B13:AD13) -> 8 | AI13: =AH13/29 -> 0.27586207
A14: 12 | B14: Pass | C14: Pass | D14: Pass | E14: Pass | F14: Pass | G14: Pass | H14: Pass | I14: Pass | J14: Pass | K14: Pass | L14: Pass | M14: Pass | N14: Pass | O14: Pass | P14: Pass | Q14: Pass | R14: Pass | S14: Pass | T14: Pass | U14: Pass | V14: Pass | W14: Pass | X14: Pass | Y14: Pass | Z14: Pass | AA14: Pass | AB14: Pass | AC14: Pass | AD14: Pass | AH14: =SUM(B14:AD14) -> 0 | AI14: =AH14/29 -> 0
A15: 13 | B15: 1 | C15: 1 | D15: 1 | E15: 1 | F15: 1 | G15: 1 | H15: 1 | I15: 1 | J15: 1 | K15: 1 | L15: 1 | M15: 1 | N15: 1 | O15: 1 | P15: 1 | Q15: 1 | R15: 1 | S15: 1 | T15: 1 | U15: 1 | V15: 1 | W15: 1 | X15: 1 | Y15: 1 | Z15: 1 | AA15: 1 | AB15: 1 | AC15: 1 | AD15: 1 | AH15: =SUM(B15:AD15) -> 29 | AI15: =AH15/29 -> 1
A16: 14 | B16: Pass | C16: Pass | D16: Pass | E16: Pass | F16: Pass | G16: Pass | H16: Pass | I16: Pass | J16: Pass | K16: Pass | L16: Pass | M16: Pass | N16: Pass | O16: Pass | P16: Pass | Q16: Pass | R16: Pass | S16: Pass | T16: Pass | U16: Pass | V16: Pass | W16: Pass | X16: Pass | Y16: Pass | Z16: Pass | AA16: Pass | AB16: Pass | AC16: Pass | AD16: Pass | AH16: =SUM(B16:AD16) -> 0 | AI16: =AH16/29 -> 0
A17: 15 | B17: Pass | C17: Pass | D17: Pass | E17: Pass | F17: Pass | G17: Pass | H17: Pass | I17: Pass | J17: Pass | K17: Pass | L17: Pass | M17: Pass | N17: Pass | O17: Pass | P17: Pass | Q17: Pass | R17: Pass | S17: Pass | T17: Pass | U17: Pass | V17: Pass | W17: Pass | X17: 1 | Y17: 1 | Z17: 1 | AA17: 1 | AB17: 1 | AC17: 1 | AD17: 1 | AH17: =SUM(B17:AD17) -> 7 | AI17: =AH17/29 -> 0.24137931
A18: 16 | B18: 1 | C18: 1 | D18: 1 | E18: 1 | F18: 1 | G18: 1 | H18: 1 | I18: 1 | J18: 1 | K18: 1 | L18: 1 | M18: 1 | N18: 1 | O18: 1 | P18: 1 | Q18: 1 | R18: 1 | S18: 1 | T18: 1 | U18: 1 | V18: 1 | W18: 1 | X18: 1 | Y18: 1 | Z18: 1 | AA18: 1 | AB18: 1 | AC18: 1 | AD18: 1 | AH18: =SUM(B18:AD18) -> 29 | AI18: =AH18/29 -> 1
A19: 17 | B19: 1 | C19: 1 | D19: 1 | E19: 1 | F19: Pass | G19: Pass | H19: Pass | I19: Pass | J19: Fail | K19: Fail | L19: Fail | M19: Fail | N19: Pass | O19: Pass | P19: Pass | Q19: Pass | R19: Pass | S19: Pass | T19: Pass | U19: Pass | V19: Pass | W19: Pass | X19: Pass | Y19: Pass | Z19: Pass | AA19: Pass | AB19: Pass | AC19: Pass | AD19: Pass | AH19: =SUM(B19:AD19) -> 4 | AI19: =AH19/29 -> 0.13793103
A20: 18 | B20: 1 | C20: 1 | D20: 1 | E20: 1 | F20: 1 | G20: 1 | H20: 1 | I20: 1 | J20: 1 | K20: 1 | L20: 1 | M20: 1 | N20: 1 | O20: 1 | P20: 1 | Q20: 1 | R20: 1 | S20: 1 | T20: 1 | U20: 1 | V20: 1 | W20: 1 | X20: 1 | Y20: 1 | Z20: 1 | AA20: 1 | AB20: 1 | AC20: 1 | AD20: 1 | AH20: =SUM(B20:AD20) -> 29 | AI20: =AH20/29 -> 1
A21: 19 | B21: Pass | C21: Pass | D21: Pass | E21: Pass | F21: Pass | G21: Pass | H21: Pass | I21: Pass | J21: Pass | K21: Pass | L21: Pass | M21: Pass | N21: Pass | O21: Pass | P21: Pass | Q21: Pass | R21: Pass | S21: Pass | T21: Pass | U21: Pass | V21: Pass | W21: Pass | X21: Pass | Y21: Pass | Z21: Pass | AA21: Pass | AB21: Pass | AC21: Pass | AD21: Pass | AH21: =SUM(B21:AD21) -> 0 | AI21: =AH21/29 -> 0
A22: 20 | B22: 1 | C22: 1 | D22: 1 | E22: 1 | F22: 1 | G22: 1 | H22: 1 | I22: 1 | J22: 1 | K22: 1 | L22: 1 | M22: 1 | N22: 1 | O22: 1 | P22: 1 | Q22: 1 | R22: 1 | S22: 1 | T22: 1 | U22: 1 | V22: 1 | W22: 1 | X22: 1 | Y22: 1 | Z22: 1 | AA22: 1 | AB22: 1 | AC22: 1 | AD22: 1 | AH22: =SUM(B22:AD22) -> 29 | AI22: =AH22/29 -> 1
A23: 21 | B23: Pass | C23: Pass | D23: Pass | E23: Pass | F23: Pass | G23: Pass | H23: Pass | I23: Pass | J23: Pass | K23: Pass | L23: Pass | M23: Pass | N23: Pass | O23: Pass | P23: Pass | Q23: Pass | R23: Pass | S23: Pass | T23: Pass | U23: Pass | V23: Pass | W23: Pass | X23: Pass | Y23: Pass | Z23: Pass | AA23: Pass | AB23: Pass | AC23: Pass | AD23: Pass | AH23: =SUM(B23:AD23) -> 0 | AI23: =AH23/29 -> 0
A24: 22 | B24: 1 | C24: 1 | D24: 1 | E24: 1 | F24: 1 | G24: 1 | H24: 1 | I24: 1 | J24: 1 | K24: 1 | L24: 1 | M24: 1 | N24: 1 | O24: 1 | P24: 1 | Q24: 1 | R24: 1 | S24: 1 | T24: 1 | U24: 1 | V24: 1 | W24: 1 | X24: 1 | Y24: 1 | Z24: 1 | AA24: 1 | AB24: 1 | AC24: 1 | AD24: 1 | AH24: =SUM(B24:AD24) -> 29 | AI24: =AH24/29 -> 1
A25: 23 | B25: 1 | C25: 1 | D25: 1 | E25: 1 | F25: 1 | G25: 1 | H25: 1 | I25: 1 | J25: 1 | K25: 1 | L25: 1 | M25: 1 | N25: 1 | O25: 1 | P25: 1 | Q25: 1 | R25: 1 | S25: 1 | T25: 1 | U25: 1 | V25: 1 | W25: 1 | X25: 1 | Y25: 1 | Z25: 1 | AA25: 1 | AB25: 1 | AC25: 1 | AD25: 1 | AH25: =SUM(B25:AD25) -> 29 | AI25: =AH25/29 -> 1
A26: 24 | B26: Pass | C26: Pass | D26: Pass | E26: Pass | F26: Pass | G26: Pass | H26: Pass | I26: Pass | J26: Pass | K26: Pass | L26: Pass | M26: Pass | N26: Pass | O26: Pass | P26: Pass | Q26: Pass | R26: Pass | S26: Pass | T26: Pass | U26: Pass | V26: Pass | W26: Pass | X26: Pass | Y26: Pass | Z26: Pass | AA26: Pass | AB26: Pass | AC26: Pass | AD26: Pass | AH26: =SUM(B26:AD26) -> 0 | AI26: =AH26/29 -> 0
A27: 25 | B27: Pass | C27: Pass | D27: Pass | E27: Pass | F27: Pass | G27: Pass | H27: Pass | I27: Pass | J27: Pass | K27: Pass | L27: Pass | M27: Pass | N27: Pass | O27: Pass | P27: Pass | Q27: Pass | R27: Pass | S27: Pass | T27: Pass | U27: Pass | V27: Pass | W27: Pass | X27: Pass | Y27: Pass | Z27: Pass | AA27: Pass | AB27: Pass | AC27: Pass | AD27: Pass | AH27: =SUM(B27:AD27) -> 0 | AI27: =AH27/29 -> 0
A28: 26 | B28: 1 | C28: 1 | D28: 1 | E28: 1 | F28: 1 | G28: 1 | H28: 1 | I28: 1 | J28: 1 | K28: 1 | L28: 1 | M28: 1 | N28: 1 | O28: 1 | P28: Pass | Q28: Pass | R28: Pass | S28: Pass | T28: Pass | U28: Pass | V28: 1 | W28: 1 | X28: 1 | Y28: 1 | Z28: 1 | AA28: 1 | AB28: 1 | AC28: 1 | AD28: 1 | AH28: =SUM(B28:AD28) -> 23 | AI28: =AH28/29 -> 0.79310345
A29: 27 | B29: 1 | C29: 1 | D29: 1 | E29: 1 | F29: 1 | G29: 1 | H29: 1 | I29: 1 | J29: 1 | K29: 1 | L29: 1 | M29: 1 | N29: 1 | O29: 1 | P29: 1 | Q29: 1 | R29: 1 | S29: 1 | T29: 1 | U29: 1 | V29: 1 | W29: 1 | X29: 1 | Y29: 1 | Z29: 1 | AA29: 1 | AB29: 1 | AC29: 1 | AD29: 1 | AH29: =SUM(B29:AD29) -> 29 | AI29: =AH29/29 -> 1
A30: 28 | B30: Pass | C30: Pass | D30: Pass | E30: Pass | F30: Pass | G30: Pass | H30: Pass | I30: Pass | J30: Pass | K30: Pass | L30: Pass | M30: Pass | N30: Pass | O30: Pass | P30: Pass | Q30: Pass | R30: Pass | S30: Pass | T30: Pass | U30: Pass | V30: Pass | W30: Pass | X30: Pass | Y30: Pass | Z30: Pass | AA30: Pass | AB30: Pass | AC30: Pass | AD30: Pass | AH30: =SUM(B30:AD30) -> 0 | AI30: =AH30/29 -> 0
A31: 29 | B31: 1 | C31: 1 | D31: 1 | E31: 1 | F31: 1 | G31: 1 | H31: Pass | I31: Fail | J31: Fail | K31: Fail | L31: Fail | M31: Fail | N31: Fail | O31: Fail | P31: 1 | Q31: 1 | R31: 1 | S31: 1 | T31: 1 | U31: 1 | V31: 1 | W31: 1 | X31: 1 | Y31: 1 | Z31: 1 | AA31: 1 | AB31: 1 | AC31: 1 | AD31: 1 | AH31: =SUM(B31:AD31) -> 21 | AI31: =AH31/29 -> 0.72413793
A32: 30 | B32: 1 | C32: 1 | D32: 1 | E32: 1 | F32: 1 | G32: 1 | H32: 1 | I32: 1 | J32: 1 | K32: 1 | L32: 1 | M32: 1 | N32: 1 | O32: 1 | P32: 1 | Q32: 1 | R32: 1 | S32: 1 | T32: 1 | U32: 1 | V32: 1 | W32: 1 | X32: 1 | Y32: 1 | Z32: 1 | AA32: 1 | AB32: 1 | AC32: 1 | AD32: 1 | AH32: =SUM(B32:AD32) -> 29 | AI32: =AH32/29 -> 1
A33: 31 | B33: Pass | C33: Pass | D33: Pass | E33: Pass | F33: Pass | G33: Pass | H33: Pass | I33: Pass | J33: Pass | K33: Pass | L33: Pass | M33: Pass | N33: Pass | O33: Pass | P33: Pass | Q33: Pass | R33: Pass | S33: Pass | T33: Pass | U33: Pass | V33: Pass | W33: Pass | X33: Pass | Y33: Pass | Z33: Pass | AA33: Pass | AB33: Pass | AC33: Pass | AD33: Pass | AH33: =SUM(B33:AD33) -> 0 | AI33: =AH33/29 -> 0
A34: 32 | B34: 1 | C34: 1 | D34: 1 | E34: 1 | F34: 1 | G34: 1 | H34: 1 | I34: 1 | J34: 1 | K34: 1 | L34: 1 | M34: 1 | N34: 1 | O34: 1 | P34: 1 | Q34: 1 | R34: 1 | S34: 1 | T34: 1 | U34: 1 | V34: 1 | W34: 1 | X34: 1 | Y34: 1 | Z34: 1 | AA34: 1 | AB34: 1 | AC34: 1 | AD34: 1 | AH34: =SUM(B34:AD34) -> 29 | AI34: =AH34/29 -> 1
A35: 33 | B35: 1 | C35: 1 | D35: 1 | E35: 1 | F35: 1 | G35: 1 | H35: 1 | I35: 1 | J35: 1 | K35: 1 | L35: 1 | M35: 1 | N35: 1 | O35: 1 | P35: 1 | Q35: 1 | R35: 1 | S35: 1 | T35: 1 | U35: 1 | V35: 1 | W35: 1 | X35: 1 | Y35: 1 | Z35: 1 | AA35: 1 | AB35: 1 | AC35: 1 | AD35: 1 | AH35: =SUM(B35:AD35) -> 29 | AI35: =AH35/29 -> 1
A36: 34 | B36: Pass | C36: Pass | D36: Pass | E36: Pass | F36: Pass | G36: Pass | H36: Pass | I36: Pass | J36: Pass | K36: Pass | L36: Pass | M36: Pass | N36: Pass | O36: Pass | P36: Pass | Q36: Pass | R36: Pass | S36: Pass | T36: Pass | U36: Pass | V36: Pass | W36: Pass | X36: Pass | Y36: Pass | Z36: Pass | AA36: Pass | AB36: Pass | AC36: Pass | AD36: Pass | AH36: =SUM(B36:AD36) -> 0 | AI36: =AH36/29 -> 0
A37: 35 | B37: Pass | C37: Pass | D37: Pass | E37: Pass | F37: Pass | G37: Pass | H37: Pass | I37: Pass | J37: Pass | K37: Pass | L37: Pass | M37: Pass | N37: Pass | O37: Pass | P37: Pass | Q37: Pass | R37: Pass | S37: Pass | T37: Pass | U37: Pass | V37: Pass | W37: Pass | X37: Pass | Y37: Pass | Z37: Pass | AA37: Pass | AB37: Pass | AC37: Pass | AD37: Pass | AH37: =SUM(B37:AD37) -> 0 | AI37: =AH37/29 -> 0
A38: 36 | B38: 1 | C38: 1 | D38: 1 | E38: 1 | F38: 1 | G38: 1 | H38: 1 | I38: 1 | J38: 1 | K38: 1 | L38: 1 | M38: 1 | N38: 1 | O38: 1 | P38: 1 | Q38: 1 | R38: 1 | S38: 1 | T38: 1 | U38: 1 | V38: 1 | W38: 1 | X38: 1 | Y38: 1 | Z38: 1 | AA38: 1 | AB38: 1 | AC38: 1 | AD38: 1 | AH38: =SUM(B38:AD38) -> 29 | AI38: =AH38/29 -> 1
A39: 37 | B39: 1 | C39: 1 | D39: 1 | E39: 1 | F39: 1 | G39: 1 | H39: 1 | I39: 1 | J39: 1 | K39: 1 | L39: 1 | M39: 1 | N39: 1 | O39: 1 | P39: Pass | Q39: Pass | R39: 1 | S39: 1 | T39: Pass | U39: Pass | V39: Pass | W39: Pass | X39: Pass | Y39: Pass | Z39: Pass | AA39: Pass | AB39: Pass | AC39: Pass | AD39: Pass | AH39: =SUM(B39:AD39) -> 16 | AI39: =AH39/29 -> 0.55172414
A40: 38 | B40: Pass | C40: Pass | D40: Pass | E40: Pass | F40: Pass | G40: Pass | H40: Pass | I40: Pass | J40: Pass | K40: Pass | L40: Pass | M40: Pass | N40: Pass | O40: Pass | P40: Pass | Q40: Pass | R40: Pass | S40: Pass | T40: Pass | U40: Pass | V40: Pass | W40: Pass | X40: Pass | Y40: Pass | Z40: Pass | AA40: Pass | AB40: Pass | AC40: Pass | AD40: Pass | AH40: =SUM(B40:AD40) -> 0 | AI40: =AH40/29 -> 0
...

Sheet Proba
A1: =probaPass!AG1 -> Proba_pass | B1: =probaFail!AH1 -> Proba_fail | C1: =probaDropout!AI1 -> Proba_dropout | E1: Result_proba | J1: Final_proba
A2: =probaPass!AG2 -> 0.10344828 | B2: =probaFail!AH2 -> 0 | C2: =probaDropout!AI2 -> 0.89655172 | E2: =_xlfn.CONCAT("[",A2,";",B2,";",C2,"]") -> [0,103448275862069;0;0,896551724137931] | J2: =E2 -> [0,103448275862069;0;0,896551724137931]
