Workbook

Sheet AnalyseTCD
A3: Nombre de 29 | B3: 29
A4: Resultat_reel | B4: Dropout | C4: Fail | D4: Pass | E4: (vide) | F4: Total général
A5: Dropout | B5: 59 | C5: 12 | D5: 1 | F5: 72
A6: Fail | B6: 17 | C6: 5 | D6: 12 | F6: 34
A7: Pass | B7: 1 | C7: 1 | D7: 92 | F7: 94
A8: (vide)
A9: Total général | B9: 77 | C9: 18 | D9: 105 | F9: 200

Sheet ResultsPass
A2: 29 | B2: Resultat_reel | C2: Dropout | D2: Fail | E2: Pass | F2: Pass - Pass (VP) | G2: =E5 -> 92 | H2: 9 | I2: Resultat_reel | J2: Dropout | K2: Fail | L2: Pass | M2: Pass - Pass (VP) | N2: =L5 -> 91 | O2: 18 | P2: Resultat_reel | Q2: Dropout | R2: Fail | S2: Pass | T2: Pass - Pass (VP) | U2: =S5 -> 92 | V2: 27 | W2: Resultat_reel | X2: Dropout | Y2: Fail | Z2: Pass | AA2: Pass - Pass (VP) | AB2: =Z5 -> 92
B3: Dropout | C3: 59 | D3: 12 | E3: 1 | F3: Pass - Others (FN) | G3: =D5+C5 -> 2 | I3: Dropout | J3: 60 | K3: 5 | L3: 7 | M3: Pass - Others (FN) | N3: =K5+J5 -> 3 | P3: Dropout | Q3: 63 | R3: 5 | S3: 4 | T3: Pass - Others (FN) | U3: =R5+Q5 -> 2 | W3: Dropout | X3: 64 | Y3: 7 | Z3: 1 | AA3: Pass - Others (FN) | AB3: =Y5+X5 -> 2
B4: Fail | C4: 17 | D4: 5 | E4: 12 | F4: Others - Pass (FP) | G4: =E4+E3 -> 13 | I4: Fail | J4: 13 | K4: 4 | L4: 17 | M4: Others - Pass (FP) | N4: =L4+L3 -> 24 | P4: Fail | Q4: 14 | R4: 5 | S4: 15 | T4: Others - Pass (FP) | U4: =S4+S3 -> 19 | W4: Fail | X4: 18 | Y4: 5 | Z4: 11 | AA4: Others - Pass (FP) | AB4: =Z4+Z3 -> 12
B5: Pass | C5: 1 | D5: 1 | E5: 92 | F5: Others - Others(VN) | G5: =C3+C4+D3+D4 -> 93 | I5: Pass | J5: 1 | K5: 2 | L5: 91 | M5: Others - Others(VN) | N5: =J3+J4+K3+K4 -> 82 | P5: Pass | Q5: 2 | S5: 92 | T5: Others - Others(VN) | U5: =Q3+Q4+R3+R4 -> 87 | W5: Pass | X5: 1 | Y5: 1 | Z5: 92 | AA5: Others - Others(VN) | AB5: =X3+X4+Y3+Y4 -> 94
A7: 1 | B7: Resultat_reel | C7: Dropout | D7: Fail | E7: Pass | F7: Pass - Pass (VP) | G7: =E10 -> 90 | H7: 10 | I7: Resultat_reel | J7: Dropout | K7: Fail | L7: Pass | M7: Pass - Pass (VP) | N7: =L10 -> 91 | O7: 19 | P7: Resultat_reel | Q7: Dropout | R7: Fail | S7: Pass | T7: Pass - Pass (VP) | U7: =S10 -> 91 | V7: 28 | W7: Resultat_reel | X7: Dropout | Y7: Fail | Z7: Pass | AA7: Pass - Pass (VP) | AB7: =Z10 -> 92
B8: Dropout | C8: 68 | E8: 4 | F8: Pass - Others (FN) | G8: =D10+C10 -> 4 | I8: Dropout | J8: 59 | K8: 6 | L8: 7 | M8: Pass - Others (FN) | N8: =K10+J10 -> 3 | P8: Dropout | Q8: 66 | R8: 5 | S8: 1 | T8: Pass - Others (FN) | U8: =R10+Q10 -> 3 | W8: Dropout | X8: 66 | Y8: 5 | Z8: 1 | AA8: Pass - Others (FN) | AB8: =Y10+X10 -> 2
B9: Fail | C9: 22 | E9: 12 | F9: Others - Pass (FP) | G9: =E9+E8 -> 16 | I9: Fail | J9: 13 | K9: 5 | L9: 16 | M9: Others - Pass (FP) | N9: =L9+L8 -> 23 | P9: Fail | Q9: 15 | R9: 5 | S9: 14 | T9: Others - Pass (FP) | U9: =S9+S8 -> 15 | W9: Fail | X9: 20 | Y9: 3 | Z9: 11 | AA9: Others - Pass (FP) | AB9: =Z9+Z8 -> 12
B10: Pass | C10: 4 | E10: 90 | F10: Others - Others(VN) | G10: =C8+C9+D8+D9 -> 90 | I10: Pass | J10: 1 | K10: 2 | L10: 91 | M10: Others - Others(VN) | N10: =J8+J9+K8+K9 -> 83 | P10: Pass | Q10: 3 | S10: 91 | T10: Others - Others(VN) | U10: =Q8+Q9+R8+R9 -> 91 | W10: Pass | X10: 1 | Y10: 1 | Z10: 92 | AA10: Others - Others(VN) | AB10: =X8+X9+Y8+Y9 -> 94
A12: 2 | B12: Resultat_reel | C12: Dropout | D12: Fail | E12: Pass | F12: Pass - Pass (VP) | G12: =E15 -> 90 | H12: 11 | I12: Resultat_reel | J12: Dropout | K12: Fail | L12: Pass | M12: Pass - Pass (VP) | N12: =L15 -> 91 | O12: 20 | P12: Resultat_reel | Q12: Dropout | R12: Fail | S12: Pass | T12: Pass - Pass (VP) | U12: =S15 -> 92
B13: Dropout | C13: 68 | E13: 4 | F13: Pass - Others (FN) | G13: =D15+C15 -> 4 | I13: Dropout | J13: 61 | K13: 4 | L13: 7 | M13: Pass - Others (FN) | N13: =K15+J15 -> 3 | P13: Dropout | Q13: 61 | R13: 10 | S13: 1 | T13: Pass - Others (FN) | U13: =R15+Q15 -> 2
B14: Fail | C14: 22 | E14: 12 | F14: Others - Pass (FP) | G14: =E14+E13 -> 16 | I14: Fail | J14: 13 | K14: 4 | L14: 17 | M14: Others - Pass (FP) | N14: =L14+L13 -> 24 | P14: Fail | Q14: 15 | R14: 6 | S14: 13 | T14: Others - Pass (FP) | U14: =S14+S13 -> 14
B15: Pass | C15: 4 | E15: 90 | F15: Others - Others(VN) | G15: =C13+C14+D13+D14 -> 90 | I15: Pass | J15: 1 | K15: 2 | L15: 91 | M15: Others - Others(VN) | N15: =J13+J14+K13+K14 -> 82 | P15: Pass | Q15: 2 | S15: 92 | T15: Others - Others(VN) | U15: =Q13+Q14+R13+R14 -> 92
A17: 3 | B17: Resultat_reel | C17: Dropout | D17: Fail | E17: Pass | F17: Pass - Pass (VP) | G17: =E20 -> 90 | H17: 12 | I17: Resultat_reel | J17: Dropout | K17: Fail | L17: Pass | M17: Pass - Pass (VP) | N17: =L20 -> 91 | O17: 21 | P17: Resultat_reel | Q17: Dropout | R17: Fail | S17: Pass | T17: Pass - Pass (VP) | U17: =S20 -> 93
B18: Dropout | C18: 68 | E18: 4 | F18: Pass - Others (FN) | G18: =D20+C20 -> 4 | I18: Dropout | J18: 58 | K18: 7 | L18: 7 | M18: Pass - Others (FN) | N18: =K20+J20 -> 3 | P18: Dropout | Q18: 64 | R18: 7 | S18: 1 | T18: Pass - Others (FN) | U18: =R20+Q20 -> 1
B19: Fail | C19: 22 | E19: 12 | F19: Others - Pass (FP) | G19: =E19+E18 -> 16 | I19: Fail | J19: 14 | K19: 4 | L19: 16 | M19: Others - Pass (FP) | N19: =L19+L18 -> 23 | P19: Fail | Q19: 16 | R19: 5 | S19: 13 | T19: Others - Pass (FP) | U19: =S19+S18 -> 14
B20: Pass | C20: 4 | E20: 90 | F20: Others - Others(VN) | G20: =C18+C19+D18+D19 -> 90 | I20: Pass | J20: 1 | K20: 2 | L20: 91 | M20: Others - Others(VN) | N20: =J18+J19+K18+K19 -> 83 | P20: Pass | Q20: 1 | S20: 93 | T20: Others - Others(VN) | U20: =Q18+Q19+R18+R19 -> 92
A22: 4 | B22: Resultat_reel | C22: Dropout | D22: Fail | E22: Pass | F22: Pass - Pass (VP) | G22: =E25 -> 90 | H22: 13 | I22: Resultat_reel | J22: Dropout | K22: Fail | L22: Pass | M22: Pass - Pass (VP) | N22: =L25 -> 91 | O22: 22 | P22: Resultat_reel | Q22: Dropout | R22: Fail | S22: Pass | T22: Pass - Pass (VP) | U22: =S25 -> 93
B23: Dropout | C23: 68 | E23: 4 | F23: Pass - Others (FN) | G23: =D25+C25 -> 4 | I23: Dropout | J23: 56 | K23: 12 | L23: 4 | M23: Pass - Others (FN) | N23: =K25+J25 -> 3 | P23: Dropout | Q23: 63 | R23: 8 | S23: 1 | T23: Pass - Others (FN) | U23: =R25+Q25 -> 1
B24: Fail | C24: 22 | E24: 12 | F24: Others - Pass (FP) | G24: =E24+E23 -> 16 | I24: Fail | J24: 13 | K24: 6 | L24: 15 | M24: Others - Pass (FP) | N24: =L24+L23 -> 19 | P24: Fail | Q24: 17 | R24: 4 | S24: 13 | T24: Others - Pass (FP) | U24: =S24+S23 -> 14
B25: Pass | C25: 4 | E25: 90 | F25: Others - Others(VN) | G25: =C23+C24+D23+D24 -> 90 | I25: Pass | J25: 1 | K25: 2 | L25: 91 | M25: Others - Others(VN) | N25: =J23+J24+K23+K24 -> 87 | P25: Pass | Q25: 1 | S25: 93 | T25: Others - Others(VN) | U25: =Q23+Q24+R23+R24 -> 92
A27: 5 | B27: Resultat_reel | C27: Dropout | D27: Fail | E27: Pass | F27: Pass - Pass (VP) | G27: =E30 -> 90 | H27: 14 | I27: Resultat_reel | J27: Dropout | K27: Fail | L27: Pass | M27: Pass - Pass (VP) | N27: =L30 -> 92 | O27: 23 | P27: Resultat_reel | Q27: Dropout | R27: Fail | S27: Pass | T27: Pass - Pass (VP) | U27: =S30 -> 93
B28: Dropout | C28: 65 | D28: 2 | E28: 5 | F28: Pass - Others (FN) | G28: =D30+C30 -> 4 | I28: Dropout | J28: 62 | K28: 6 | L28: 4 | M28: Pass - Others (FN) | N28: =K30+J30 -> 2 | P28: Dropout | Q28: 67 | R28: 4 | S28: 1 | T28: Pass - Others (FN) | U28: =R30+Q30 -> 1
B29: Fail | C29: 20 | D29: 1 | E29: 13 | F29: Others - Pass (FP) | G29: =E29+E28 -> 18 | I29: Fail | J29: 13 | K29: 6 | L29: 15 | M29: Others - Pass (FP) | N29: =L29+L28 -> 19 | P29: Fail | Q29: 18 | R29: 3 | S29: 13 | T29: Others - Pass (FP) | U29: =S29+S28 -> 14
B30: Pass | C30: 3 | D30: 1 | E30: 90 | F30: Others - Others(VN) | G30: =C28+C29+D28+D29 -> 88 | I30: Pass | K30: 2 | L30: 92 | M30: Others - Others(VN) | N30: =J28+J29+K28+K29 -> 87 | P30: Pass | Q30: 1 | S30: 93 | T30: Others - Others(VN) | U30: =Q28+Q29+R28+R29 -> 92
A32: 6 | B32: Resultat_reel | C32: Dropout | D32: Fail | E32: Pass | F32: Pass - Pass (VP) | G32: =E35 -> 90 | H32: 15 | I32: Resultat_reel | J32: Dropout | K32: Fail | L32: Pass | M32: Pass - Pass (VP) | N32: =L35 -> 94 | O32: 24 | P32: Resultat_reel | Q32: Dropout | R32: Fail | S32: Pass | T32: Pass - Pass (VP) | U32: =S35 -> 93
B33: Dropout | C33: 62 | D33: 6 | E33: 4 | F33: Pass - Others (FN) | G33: =D35+C35 -> 4 | I33: Dropout | J33: 62 | K33: 6 | L33: 4 | M33: Pass - Others (FN) | N33: =K35+J35 -> 0 | P33: Dropout | Q33: 63 | R33: 8 | S33: 1 | T33: Pass - Others (FN) | U33: =R35+Q35 -> 1
B34: Fail | C34: 19 | D34: 3 | E34: 12 | F34: Others - Pass (FP) | G34: =E34+E33 -> 16 | I34: Fail | J34: 15 | K34: 4 | L34: 15 | M34: Others - Pass (FP) | N34: =L34+L33 -> 19 | P34: Fail | Q34: 17 | R34: 5 | S34: 12 | T34: Others - Pass (FP) | U34: =S34+S33 -> 13
B35: Pass | C35: 3 | D35: 1 | E35: 90 | F35: Others - Others(VN) | G35: =C33+C34+D33+D34 -> 90 | I35: Pass | L35: 94 | M35: Others - Others(VN) | N35: =J33+J34+K33+K34 -> 87 | P35: Pass | Q35: 1 | S35: 93 | T35: Others - Others(VN) | U35: =Q33+Q34+R33+R34 -> 93
A37: 7 | B37: Resultat_reel | C37: Dropout | D37: Fail | E37: Pass | F37: Pass - Pass (VP) | G37: =E40 -> 90 | H37: 16 | I37: Resultat_reel | J37: Dropout | K37: Fail | L37: Pass | M37: Pass - Pass (VP) | N37: =L40 -> 93 | O37: 25 | P37: Resultat_reel | Q37: Dropout | R37: Fail | S37: Pass | T37: Pass - Pass (VP) | U37: =S40 -> 93
B38: Dropout | C38: 62 | D38: 6 | E38: 4 | F38: Pass - Others (FN) | G38: =D40+C40 -> 4 | I38: Dropout | J38: 63 | K38: 5 | L38: 4 | M38: Pass - Others (FN) | N38: =K40+J40 -> 1 | P38: Dropout | Q38: 63 | R38: 8 | S38: 1 | T38: Pass - Others (FN) | U38: =R40+Q40 -> 1
B39: Fail | C39: 18 | D39: 3 | E39: 13 | F39: Others - Pass (FP) | G39: =E39+E38 -> 17 | I39: Fail | J39: 14 | K39: 5 | L39: 15 | M39: Others - Pass (FP) | N39: =L39+L38 -> 19 | P39: Fail | Q39: 17 | R39: 5 | S39: 12 | T39: Others - Pass (FP) | U39: =S39+S38 -> 13
B40: Pass | C40: 3 | D40: 1 | E40: 90 | F40: Others - Others(VN) | G40: =C38+C39+D38+D39 -> 89 | I40: Pass | J40: 1 | L40: 93 | M40: Others - Others(VN) | N40: =J38+J39+K38+K39 -> 87 | P40: Pass | Q40: 1 | S40: 93 | T40: Others - Others(VN) | U40: =Q38+Q39+R38+R39 -> 93
A42: 8 | B42: Resultat_reel | C42: Dropout | D42: Fail | E42: Pass | F42: Pass - Pass (VP) | G42: =E45 -> 90 | H42: 17 | I42: Resultat_reel | J42: Dropout | K42: Fail | L42: Pass | M42: Pass - Pass (VP) | N42: =L45 -> 92 | O42: 26 | P42: Resultat_reel | Q42: Dropout | R42: Fail | S42: Pass | T42: Pass - Pass (VP) | U42: =S45 -> 93
B43: Dropout | C43: 59 | D43: 9 | E43: 4 | F43: Pass - Others (FN) | G43: =D45+C45 -> 4 | I43: Dropout | J43: 63 | K43: 6 | L43: 3 | M43: Pass - Others (FN) | N43: =K45+J45 -> 2 | P43: Dropout | Q43: 67 | R43: 4 | S43: 1 | T43: Pass - Others (FN) | U43: =R45+Q45 -> 1
B44: Fail | C44: 16 | D44: 4 | E44: 14 | F44: Others - Pass (FP) | G44: =E44+E43 -> 18 | I44: Fail | J44: 15 | K44: 4 | L44: 15 | M44: Others - Pass (FP) | N44: =L44+L43 -> 18 | P44: Fail | Q44: 19 | R44: 3 | S44: 12 | T44: Others - Pass (FP) | U44: =S44+S43 -> 13
B45: Pass | C45: 3 | D45: 1 | E45: 90 | F45: Others - Others(VN) | G45: =C43+C44+D43+D44 -> 88 | I45: Pass | J45: 2 | L45: 92 | M45: Others - Others(VN) | N45: =J43+J44+K43+K44 -> 88 | P45: Pass | Q45: 1 | S45: 93 | T45: Others - Others(VN) | U45: =Q43+Q44+R43+R44 -> 93
B47: 1 | C47: 2 | D47: 3 | E47: 4 | F47: 5 | G47: 6 | H47: 7 | I47: 8 | J47: 9 | K47: 10 | L47: 11 | M47: 12 | N47: 13 | O47: 14 | P47: 15 | Q47: 16 | R47: 17 | S47: 18 | T47: 19 | U47: 20 | V47: 21 | W47: 22 | X47: 23 | Y47: 24 | Z47: 25 | AA47: 26 | AB47: 27 | AC47: 28 | AD47: 29
A48: Pass - Pass (VP) | B48: =G7 -> 90 | C48: =G12 -> 90 | D48: =G17 -> 90 | E48: =G22 -> 90 | F48: =G27 -> 90 | G48: =G32 -> 90 | H48: =G37 -> 90 | I48: =G42 -> 90 | J48: =N2 -> 91 | K48: =N7 -> 91 | L48: =N12 -> 91 | M48: =N17 -> 91 | N48: =N22 -> 91 | O48: =N27 -> 92 | P48: =N32 -> 94 | Q48: =N37 -> 93 | R48: =N42 -> 92 | S48: =U2 -> 92 | T48: =U7 -> 91 | U48: =U12 -> 92 | V48: =U17 -> 93 | W48: =U22 -> 93 | X48: =U27 -> 93 | Y48: =U32 -> 93 | Z48: =U37 -> 93 | AA48: =U42 -> 93 | AB48: =AB2 -> 92 | AC48: =AB7 -> 92 | AD48: =G2 -> 92
A49: Pass - Others (FN) | B49: =G8 -> 4 | C49: =G13 -> 4 | D49: =G18 -> 4 | E49: =G23 -> 4 | F49: =G28 -> 4 | G49: =G33 -> 4 | H49: =G38 -> 4 | I49: =G43 -> 4 | J49: =N3 -> 3 | K49: =N8 -> 3 | L49: =N13 -> 3 | M49: =N18 -> 3 | N49: =N23 -> 3 | O49: =N28 -> 2 | P49: =N33 -> 0 | Q49: =N38 -> 1 | R49: =N43 -> 2 | S49: =U3 -> 2 | T49: =U8 -> 3 | U49: =U13 -> 2 | V49: =U18 -> 1 | W49: =U23 -> 1 | X49: =U28 -> 1 | Y49: =U33 -> 1 | Z49: =U38 -> 1 | AA49: =U43 -> 1 | AB49: =AB3 -> 2 | AC49: =AB8 -> 2 | AD49: =G3 -> 2
A50: Others - Pass (FP) | B50: =G9 -> 16 | C50: =G14 -> 16 | D50: =G19 -> 16 | E50: =G24 -> 16 | F50: =G29 -> 18 | G50: =G34 -> 16 | H50: =G39 -> 17 | I50: =G44 -> 18 | J50: =N4 -> 24 | K50: =N9 -> 23 | L50: =N14 -> 24 | M50: =N19 -> 23 | N50: =N24 -> 19 | O50: =N29 -> 19 | P50: =N34 -> 19 | Q50: =N39 -> 19 | R50: =N44 -> 18 | S50: =U4 -> 19 | T50: =U9 -> 15 | U50: =U14 -> 14 | V50: =U19 -> 14 | W50: =U24 -> 14 | X50: =U29 -> 14 | Y50: =U34 -> 13 | Z50: =U39 -> 13 | AA50: =U44 -> 13 | AB50: =AB4 -> 12 | AC50: =AB9 -> 12 | AD50: =G4 -> 13
...

Sheet ResultsFail
A2: 29 | B2: Resultat_reel | C2: Dropout | D2: Fail | E2: Pass | F2: Fail - Fail (VP) | G2: =D4 -> 5 | H2: 9 | I2: Resultat_reel | J2: Dropout | K2: Fail | L2: Pass | M2: Fail - Fail (VP) | N2: =K4 -> 4 | O2: 18 | P2: Resultat_reel | Q2: Dropout | R2: Fail | S2: Pass | T2: Fail - Fail (VP) | U2: =R4 -> 5 | V2: 27 | W2: Resultat_reel | X2: Dropout | Y2: Fail | Z2: Pass | AA2: Fail - Fail (VP) | AB2: =Y4 -> 5
B3: Dropout | C3: 59 | D3: 12 | E3: 1 | F3: Fail - Others (FN) | G3: =C4+E4 -> 29 | I3: Dropout | J3: 60 | K3: 5 | L3: 7 | M3: Fail - Others (FN) | N3: =J4+L4 -> 30 | P3: Dropout | Q3: 63 | R3: 5 | S3: 4 | T3: Fail - Others (FN) | U3: =Q4+S4 -> 29 | W3: Dropout | X3: 64 | Y3: 7 | Z3: 1 | AA3: Fail - Others (FN) | AB3: =X4+Z4 -> 29
B4: Fail | C4: 17 | D4: 5 | E4: 12 | F4: Others - Fail (FP) | G4: =D3+D5 -> 13 | I4: Fail | J4: 13 | K4: 4 | L4: 17 | M4: Others - Fail (FP) | N4: =K3+K5 -> 7 | P4: Fail | Q4: 14 | R4: 5 | S4: 15 | T4: Others - Fail (FP) | U4: =R3+R5 -> 5 | W4: Fail | X4: 18 | Y4: 5 | Z4: 11 | AA4: Others - Fail (FP) | AB4: =Y3+Y5 -> 8
B5: Pass | C5: 1 | D5: 1 | E5: 92 | F5: Others - Others(VN) | G5: =C3+E3+C5+E5 -> 153 | I5: Pass | J5: 1 | K5: 2 | L5: 91 | M5: Others - Others(VN) | N5: =J3+L3+J5+L5 -> 159 | P5: Pass | Q5: 2 | S5: 92 | T5: Others - Others(VN) | U5: =Q3+S3+Q5+S5 -> 161 | W5: Pass | X5: 1 | Y5: 1 | Z5: 92 | AA5: Others - Others(VN) | AB5: =X3+Z3+X5+Z5 -> 158
A7: 1 | B7: Resultat_reel | C7: Dropout | D7: Fail | E7: Pass | F7: Fail - Fail (VP) | G7: =D9 -> 0 | H7: 10 | I7: Resultat_reel | J7: Dropout | K7: Fail | L7: Pass | M7: Fail - Fail (VP) | N7: =K9 -> 5 | O7: 19 | P7: Resultat_reel | Q7: Dropout | R7: Fail | S7: Pass | T7: Fail - Fail (VP) | U7: =R9 -> 5 | V7: 28 | W7: Resultat_reel | X7: Dropout | Y7: Fail | Z7: Pass | AA7: Fail - Fail (VP) | AB7: =Y9 -> 3
B8: Dropout | C8: 68 | E8: 4 | F8: Fail - Others (FN) | G8: =C9+E9 -> 34 | I8: Dropout | J8: 59 | K8: 6 | L8: 7 | M8: Fail - Others (FN) | N8: =J9+L9 -> 29 | P8: Dropout | Q8: 66 | R8: 5 | S8: 1 | T8: Fail - Others (FN) | U8: =Q9+S9 -> 29 | W8: Dropout | X8: 66 | Y8: 5 | Z8: 1 | AA8: Fail - Others (FN) | AB8: =X9+Z9 -> 31
B9: Fail | C9: 22 | E9: 12 | F9: Others - Fail (FP) | G9: =D8+D10 -> 0 | I9: Fail | J9: 13 | K9: 5 | L9: 16 | M9: Others - Fail (FP) | N9: =K8+K10 -> 8 | P9: Fail | Q9: 15 | R9: 5 | S9: 14 | T9: Others - Fail (FP) | U9: =R8+R10 -> 5 | W9: Fail | X9: 20 | Y9: 3 | Z9: 11 | AA9: Others - Fail (FP) | AB9: =Y8+Y10 -> 6
B10: Pass | C10: 4 | E10: 90 | F10: Others - Others(VN) | G10: =C8+E8+C10+E10 -> 166 | I10: Pass | J10: 1 | K10: 2 | L10: 91 | M10: Others - Others(VN) | N10: =J8+L8+J10+L10 -> 158 | P10: Pass | Q10: 3 | S10: 91 | T10: Others - Others(VN) | U10: =Q8+S8+Q10+S10 -> 161 | W10: Pass | X10: 1 | Y10: 1 | Z10: 92 | AA10: Others - Others(VN) | AB10: =X8+Z8+X10+Z10 -> 160
A12: 2 | B12: Resultat_reel | C12: Dropout | D12: Fail | E12: Pass | F12: Fail - Fail (VP) | G12: =D14 -> 0 | H12: 11 | I12: Resultat_reel | J12: Dropout | K12: Fail | L12: Pass | M12: Fail - Fail (VP) | N12: =K14 -> 4 | O12: 20 | P12: Resultat_reel | Q12: Dropout | R12: Fail | S12: Pass | T12: Fail - Fail (VP) | U12: =R14 -> 6
B13: Dropout | C13: 68 | E13: 4 | F13: Fail - Others (FN) | G13: =C14+E14 -> 34 | I13: Dropout | J13: 61 | K13: 4 | L13: 7 | M13: Fail - Others (FN) | N13: =J14+L14 -> 30 | P13: Dropout | Q13: 61 | R13: 10 | S13: 1 | T13: Fail - Others (FN) | U13: =Q14+S14 -> 28
B14: Fail | C14: 22 | E14: 12 | F14: Others - Fail (FP) | G14: =D13+D15 -> 0 | I14: Fail | J14: 13 | K14: 4 | L14: 17 | M14: Others - Fail (FP) | N14: =K13+K15 -> 6 | P14: Fail | Q14: 15 | R14: 6 | S14: 13 | T14: Others - Fail (FP) | U14: =R13+R15 -> 10
B15: Pass | C15: 4 | E15: 90 | F15: Others - Others(VN) | G15: =C13+E13+C15+E15 -> 166 | I15: Pass | J15: 1 | K15: 2 | L15: 91 | M15: Others - Others(VN) | N15: =J13+L13+J15+L15 -> 160 | P15: Pass | Q15: 2 | S15: 92 | T15: Others - Others(VN) | U15: =Q13+S13+Q15+S15 -> 156
A17: 3 | B17: Resultat_reel | C17: Dropout | D17: Fail | E17: Pass | F17: Fail - Fail (VP) | G17: =D19 -> 0 | H17: 12 | I17: Resultat_reel | J17: Dropout | K17: Fail | L17: Pass | M17: Fail - Fail (VP) | N17: =K19 -> 4 | O17: 21 | P17: Resultat_reel | Q17: Dropout | R17: Fail | S17: Pass | T17: Fail - Fail (VP) | U17: =R19 -> 5
B18: Dropout | C18: 68 | E18: 4 | F18: Fail - Others (FN) | G18: =C19+E19 -> 34 | I18: Dropout | J18: 58 | K18: 7 | L18: 7 | M18: Fail - Others (FN) | N18: =J19+L19 -> 30 | P18: Dropout | Q18: 64 | R18: 7 | S18: 1 | T18: Fail - Others (FN) | U18: =Q19+S19 -> 29
B19: Fail | C19: 22 | E19: 12 | F19: Others - Fail (FP) | G19: =D18+D20 -> 0 | I19: Fail | J19: 14 | K19: 4 | L19: 16 | M19: Others - Fail (FP) | N19: =K18+K20 -> 9 | P19: Fail | Q19: 16 | R19: 5 | S19: 13 | T19: Others - Fail (FP) | U19: =R18+R20 -> 7
B20: Pass | C20: 4 | E20: 90 | F20: Others - Others(VN) | G20: =C18+E18+C20+E20 -> 166 | I20: Pass | J20: 1 | K20: 2 | L20: 91 | M20: Others - Others(VN) | N20: =J18+L18+J20+L20 -> 157 | P20: Pass | Q20: 1 | S20: 93 | T20: Others - Others(VN) | U20: =Q18+S18+Q20+S20 -> 159
A22: 4 | B22: Resultat_reel | C22: Dropout | D22: Fail | E22: Pass | F22: Fail - Fail (VP) | G22: =D24 -> 0 | H22: 13 | I22: Resultat_reel | J22: Dropout | K22: Fail | L22: Pass | M22: Fail - Fail (VP) | N22: =K24 -> 6 | O22: 22 | P22: Resultat_reel | Q22: Dropout | R22: Fail | S22: Pass | T22: Fail - Fail (VP) | U22: =R24 -> 4
B23: Dropout | C23: 68 | E23: 4 | F23: Fail - Others (FN) | G23: =C24+E24 -> 34 | I23: Dropout | J23: 56 | K23: 12 | L23: 4 | M23: Fail - Others (FN) | N23: =J24+L24 -> 28 | P23: Dropout | Q23: 63 | R23: 8 | S23: 1 | T23: Fail - Others (FN) | U23: =Q24+S24 -> 30
B24: Fail | C24: 22 | E24: 12 | F24: Others - Fail (FP) | G24: =D23+D25 -> 0 | I24: Fail | J24: 13 | K24: 6 | L24: 15 | M24: Others - Fail (FP) | N24: =K23+K25 -> 14 | P24: Fail | Q24: 17 | R24: 4 | S24: 13 | T24: Others - Fail (FP) | U24: =R23+R25 -> 8
B25: Pass | C25: 4 | E25: 90 | F25: Others - Others(VN) | G25: =C23+E23+C25+E25 -> 166 | I25: Pass | J25: 1 | K25: 2 | L25: 91 | M25: Others - Others(VN) | N25: =J23+L23+J25+L25 -> 152 | P25: Pass | Q25: 1 | S25: 93 | T25: Others - Others(VN) | U25: =Q23+S23+Q25+S25 -> 158
A27: 5 | B27: Resultat_reel | C27: Dropout | D27: Fail | E27: Pass | F27: Fail - Fail (VP) | G27: =D29 -> 1 | H27: 14 | I27: Resultat_reel | J27: Dropout | K27: Fail | L27: Pass | M27: Fail - Fail (VP) | N27: =K29 -> 6 | O27: 23 | P27: Resultat_reel | Q27: Dropout | R27: Fail | S27: Pass | T27: Fail - Fail (VP) | U27: =R29 -> 3
B28: Dropout | C28: 65 | D28: 2 | E28: 5 | F28: Fail - Others (FN) | G28: =C29+E29 -> 33 | I28: Dropout | J28: 62 | K28: 6 | L28: 4 | M28: Fail - Others (FN) | N28: =J29+L29 -> 28 | P28: Dropout | Q28: 67 | R28: 4 | S28: 1 | T28: Fail - Others (FN) | U28: =Q29+S29 -> 31
B29: Fail | C29: 20 | D29: 1 | E29: 13 | F29: Others - Fail (FP) | G29: =D28+D30 -> 3 | I29: Fail | J29: 13 | K29: 6 | L29: 15 | M29: Others - Fail (FP) | N29: =K28+K30 -> 8 | P29: Fail | Q29: 18 | R29: 3 | S29: 13 | T29: Others - Fail (FP) | U29: =R28+R30 -> 4
B30: Pass | C30: 3 | D30: 1 | E30: 90 | F30: Others - Others(VN) | G30: =C28+E28+C30+E30 -> 163 | I30: Pass | K30: 2 | L30: 92 | M30: Others - Others(VN) | N30: =J28+L28+J30+L30 -> 158 | P30: Pass | Q30: 1 | S30: 93 | T30: Others - Others(VN) | U30: =Q28+S28+Q30+S30 -> 162
A32: 6 | B32: Resultat_reel | C32: Dropout | D32: Fail | E32: Pass | F32: Fail - Fail (VP) | G32: =D34 -> 3 | H32: 15 | I32: Resultat_reel | J32: Dropout | K32: Fail | L32: Pass | M32: Fail - Fail (VP) | N32: =K34 -> 4 | O32: 24 | P32: Resultat_reel | Q32: Dropout | R32: Fail | S32: Pass | T32: Fail - Fail (VP) | U32: =R34 -> 5
B33: Dropout | C33: 62 | D33: 6 | E33: 4 | F33: Fail - Others (FN) | G33: =C34+E34 -> 31 | I33: Dropout | J33: 62 | K33: 6 | L33: 4 | M33: Fail - Others (FN) | N33: =J34+L34 -> 30 | P33: Dropout | Q33: 63 | R33: 8 | S33: 1 | T33: Fail - Others (FN) | U33: =Q34+S34 -> 29
B34: Fail | C34: 19 | D34: 3 | E34: 12 | F34: Others - Fail (FP) | G34: =D33+D35 -> 7 | I34: Fail | J34: 15 | K34: 4 | L34: 15 | M34: Others - Fail (FP) | N34: =K33+K35 -> 6 | P34: Fail | Q34: 17 | R34: 5 | S34: 12 | T34: Others - Fail (FP) | U34: =R33+R35 -> 8
B35: Pass | C35: 3 | D35: 1 | E35: 90 | F35: Others - Others(VN) | G35: =C33+E33+C35+E35 -> 159 | I35: Pass | L35: 94 | M35: Others - Others(VN) | N35: =J33+L33+J35+L35 -> 160 | P35: Pass | Q35: 1 | S35: 93 | T35: Others - Others(VN) | U35: =Q33+S33+Q35+S35 -> 158
A37: 7 | B37: Resultat_reel | C37: Dropout | D37: Fail | E37: Pass | F37: Fail - Fail (VP) | G37: =D39 -> 3 | H37: 16 | I37: Resultat_reel | J37: Dropout | K37: Fail | L37: Pass | M37: Fail - Fail (VP) | N37: =K39 -> 5 | O37: 25 | P37: Resultat_reel | Q37: Dropout | R37: Fail | S37: Pass | T37: Fail - Fail (VP) | U37: =R39 -> 5
B38: Dropout | C38: 62 | D38: 6 | E38: 4 | F38: Fail - Others (FN) | G38: =C39+E39 -> 31 | I38: Dropout | J38: 63 | K38: 5 | L38: 4 | M38: Fail - Others (FN) | N38: =J39+L39 -> 29 | P38: Dropout | Q38: 63 | R38: 8 | S38: 1 | T38: Fail - Others (FN) | U38: =Q39+S39 -> 29
B39: Fail | C39: 18 | D39: 3 | E39: 13 | F39: Others - Fail (FP) | G39: =D38+D40 -> 7 | I39: Fail | J39: 14 | K39: 5 | L39: 15 | M39: Others - Fail (FP) | N39: =K38+K40 -> 5 | P39: Fail | Q39: 17 | R39: 5 | S39: 12 | T39: Others - Fail (FP) | U39: =R38+R40 -> 8
B40: Pass | C40: 3 | D40: 1 | E40: 90 | F40: Others - Others(VN) | G40: =C38+E38+C40+E40 -> 159 | I40: Pass | J40: 1 | L40: 93 | M40: Others - Others(VN) | N40: =J38+L38+J40+L40 -> 161 | P40: Pass | Q40: 1 | S40: 93 | T40: Others - Others(VN) | U40: =Q38+S38+Q40+S40 -> 158
A42: 8 | B42: Resultat_reel | C42: Dropout | D42: Fail | E42: Pass | F42: Fail - Fail (VP) | G42: =D44 -> 4 | H42: 17 | I42: Resultat_reel | J42: Dropout | K42: Fail | L42: Pass | M42: Fail - Fail (VP) | N42: =K44 -> 4 | O42: 26 | P42: Resultat_reel | Q42: Dropout | R42: Fail | S42: Pass | T42: Fail - Fail (VP) | U42: =R44 -> 3
B43: Dropout | C43: 59 | D43: 9 | E43: 4 | F43: Fail - Others (FN) | G43: =C44+E44 -> 30 | I43: Dropout | J43: 63 | K43: 6 | L43: 3 | M43: Fail - Others (FN) | N43: =J44+L44 -> 30 | P43: Dropout | Q43: 67 | R43: 4 | S43: 1 | T43: Fail - Others (FN) | U43: =Q44+S44 -> 31
B44: Fail | C44: 16 | D44: 4 | E44: 14 | F44: Others - Fail (FP) | G44: =D43+D45 -> 10 | I44: Fail | J44: 15 | K44: 4 | L44: 15 | M44: Others - Fail (FP) | N44: =K43+K45 -> 6 | P44: Fail | Q44: 19 | R44: 3 | S44: 12 | T44: Others - Fail (FP) | U44: =R43+R45 -> 4
B45: Pass | C45: 3 | D45: 1 | E45: 90 | F45: Others - Others(VN) | G45: =C43+E43+C45+E45 -> 156 | I45: Pass | J45: 2 | L45: 92 | M45: Others - Others(VN) | N45: =J43+L43+J45+L45 -> 160 | P45: Pass | Q45: 1 | S45: 93 | T45: Others - Others(VN) | U45: =Q43+S43+Q45+S45 -> 162
B47: 1 | C47: 2 | D47: 3 | E47: 4 | F47: 5 | G47: 6 | H47: 7 | I47: 8 | J47: 9 | K47: 10 | L47: 11 | M47: 12 | N47: 13 | O47: 14 | P47: 15 | Q47: 16 | R47: 17 | S47: 18 | T47: 19 | U47: 20 | V47: 21 | W47: 22 | X47: 23 | Y47: 24 | Z47: 25 | AA47: 26 | AB47: 27 | AC47: 28 | AD47: 29
A48: Pass - Pass (VP) | B48: =G7 -> 0 | C48: =G12 -> 0 | D48: =G17 -> 0 | E48: =G22 -> 0 | F48: =G27 -> 1 | G48: =G32 -> 3 | H48: =G37 -> 3 | I48: =G42 -> 4 | J48: =N2 -> 4 | K48: =N7 -> 5 | L48: =N12 -> 4 | M48: =N17 -> 4 | N48: =N22 -> 6 | O48: =N27 -> 6 | P48: =N32 -> 4 | Q48: =N37 -> 5 | R48: =N42 -> 4 | S48: =U2 -> 5 | T48: =U7 -> 5 | U48: =U12 -> 6 | V48: =U17 -> 5 | W48: =U22 -> 4 | X48: =U27 -> 3 | Y48: =U32 -> 5 | Z48: =U37 -> 5 | AA48: =U42 -> 3 | AB48: =AB2 -> 5 | AC48: =AB7 -> 3 | AD48: =G2 -> 5
A49: Pass - Others (FN) | B49: =G8 -> 34 | C49: =G13 -> 34 | D49: =G18 -> 34 | E49: =G23 -> 34 | F49: =G28 -> 33 | G49: =G33 -> 31 | H49: =G38 -> 31 | I49: =G43 -> 30 | J49: =N3 -> 30 | K49: =N8 -> 29 | L49: =N13 -> 30 | M49: =N18 -> 30 | N49: =N23 -> 28 | O49: =N28 -> 28 | P49: =N33 -> 30 | Q49: =N38 -> 29 | R49: =N43 -> 30 | S49: =U3 -> 29 | T49: =U8 -> 29 | U49: =U13 -> 28 | V49: =U18 -> 29 | W49: =U23 -> 30 | X49: =U28 -> 31 | Y49: =U33 -> 29 | Z49: =U38 -> 29 | AA49: =U43 -> 31 | AB49: =AB3 -> 29 | AC49: =AB8 -> 31 | AD49: =G3 -> 29
A50: Others - Pass (FP) | B50: =G9 -> 0 | C50: =G14 -> 0 | D50: =G19 -> 0 | E50: =G24 -> 0 | F50: =G29 -> 3 | G50: =G34 -> 7 | H50: =G39 -> 7 | I50: =G44 -> 10 | J50: =N4 -> 7 | K50: =N9 -> 8 | L50: =N14 -> 6 | M50: =N19 -> 9 | N50: =N24 -> 14 | O50: =N29 -> 8 | P50: =N34 -> 6 | Q50: =N39 -> 5 | R50: =N44 -> 6 | S50: =U4 -> 5 | T50: =U9 -> 5 | U50: =U14 -> 10 | V50: =U19 -> 7 | W50: =U24 -> 8 | X50: =U29 -> 4 | Y50: =U34 -> 8 | Z50: =U39 -> 8 | AA50: =U44 -> 4 | AB50: =AB4 -> 8 | AC50: =AB9 -> 6 | AD50: =G4 -> 13
...

Sheet ResultsDropout
A2: 29 | B2: Resultat_reel | C2: Dropout | D2: Fail | E2: Pass | F2: Do - Do (VP) | G2: =C3 -> 59 | H2: 9 | I2: Resultat_reel | J2: Dropout | K2: Fail | L2: Pass | M2: Do - Do (VP) | N2: =J3 -> 60 | O2: 18 | P2: Resultat_reel | Q2: Dropout | R2: Fail | S2: Pass | T2: Do - Do (VP) | U2: =Q3 -> 63 | V2: 27 | W2: Resultat_reel | X2: Dropout | Y2: Fail | Z2: Pass | AA2: Do - Do (VP) | AB2: =X3 -> 64
B3: Dropout | C3: 59 | D3: 12 | E3: 1 | F3: Do - Others (FN) | G3: =D3+E3 -> 13 | I3: Dropout | J3: 60 | K3: 5 | L3: 7 | M3: Do - Others (FN) | N3: =K3+L3 -> 12 | P3: Dropout | Q3: 63 | R3: 5 | S3: 4 | T3: Do - Others (FN) | U3: =R3+S3 -> 9 | W3: Dropout | X3: 64 | Y3: 7 | Z3: 1 | AA3: Do - Others (FN) | AB3: =Y3+Z3 -> 8
B4: Fail | C4: 17 | D4: 5 | E4: 12 | F4: Others - Do (FP) | G4: =C4+C5 -> 18 | I4: Fail | J4: 13 | K4: 4 | L4: 17 | M4: Others - Do (FP) | N4: =J4+J5 -> 14 | P4: Fail | Q4: 14 | R4: 5 | S4: 15 | T4: Others - Do (FP) | U4: =Q4+Q5 -> 16 | W4: Fail | X4: 18 | Y4: 5 | Z4: 11 | AA4: Others - Do (FP) | AB4: =X4+X5 -> 19
B5: Pass | C5: 1 | D5: 1 | E5: 92 | F5: Others - Others(VN) | G5: =D4+E4+D5+E5 -> 110 | I5: Pass | J5: 1 | K5: 2 | L5: 91 | M5: Others - Others(VN) | N5: =K4+L4+K5+L5 -> 114 | P5: Pass | Q5: 2 | S5: 92 | T5: Others - Others(VN) | U5: =R4+S4+R5+S5 -> 112 | W5: Pass | X5: 1 | Y5: 1 | Z5: 92 | AA5: Others - Others(VN) | AB5: =Y4+Z4+Y5+Z5 -> 109
A7: 1 | B7: Resultat_reel | C7: Dropout | D7: Fail | E7: Pass | F7: Do - Do (VP) | G7: =C8 -> 68 | H7: 10 | I7: Resultat_reel | J7: Dropout | K7: Fail | L7: Pass | M7: Do - Do (VP) | N7: =J8 -> 59 | O7: 19 | P7: Resultat_reel | Q7: Dropout | R7: Fail | S7: Pass | T7: Do - Do (VP) | U7: =Q8 -> 66 | V7: 28 | W7: Resultat_reel | X7: Dropout | Y7: Fail | Z7: Pass | AA7: Do - Do (VP) | AB7: =X8 -> 66
B8: Dropout | C8: 68 | E8: 4 | F8: Do - Others (FN) | G8: =D8+E8 -> 4 | I8: Dropout | J8: 59 | K8: 6 | L8: 7 | M8: Do - Others (FN) | N8: =K8+L8 -> 13 | P8: Dropout | Q8: 66 | R8: 5 | S8: 1 | T8: Do - Others (FN) | U8: =R8+S8 -> 6 | W8: Dropout | X8: 66 | Y8: 5 | Z8: 1 | AA8: Do - Others (FN) | AB8: =Y8+Z8 -> 6
B9: Fail | C9: 22 | E9: 12 | F9: Others - Do (FP) | G9: =C9+C10 -> 26 | I9: Fail | J9: 13 | K9: 5 | L9: 16 | M9: Others - Do (FP) | N9: =J9+J10 -> 14 | P9: Fail | Q9: 15 | R9: 5 | S9: 14 | T9: Others - Do (FP) | U9: =Q9+Q10 -> 18 | W9: Fail | X9: 20 | Y9: 3 | Z9: 11 | AA9: Others - Do (FP) | AB9: =X9+X10 -> 21
B10: Pass | C10: 4 | E10: 90 | F10: Others - Others(VN) | G10: =D9+E9+D10+E10 -> 102 | I10: Pass | J10: 1 | K10: 2 | L10: 91 | M10: Others - Others(VN) | N10: =K9+L9+K10+L10 -> 114 | P10: Pass | Q10: 3 | S10: 91 | T10: Others - Others(VN) | U10: =R9+S9+R10+S10 -> 110 | W10: Pass | X10: 1 | Y10: 1 | Z10: 92 | AA10: Others - Others(VN) | AB10: =Y9+Z9+Y10+Z10 -> 107
A12: 2 | B12: Resultat_reel | C12: Dropout | D12: Fail | E12: Pass | F12: Do - Do (VP) | G12: =C13 -> 68 | H12: 11 | I12: Resultat_reel | J12: Dropout | K12: Fail | L12: Pass | M12: Do - Do (VP) | N12: =J13 -> 61 | O12: 20 | P12: Resultat_reel | Q12: Dropout | R12: Fail | S12: Pass | T12: Do - Do (VP) | U12: =Q13 -> 61
B13: Dropout | C13: 68 | E13: 4 | F13: Do - Others (FN) | G13: =D13+E13 -> 4 | I13: Dropout | J13: 61 | K13: 4 | L13: 7 | M13: Do - Others (FN) | N13: =K13+L13 -> 11 | P13: Dropout | Q13: 61 | R13: 10 | S13: 1 | T13: Do - Others (FN) | U13: =R13+S13 -> 11
B14: Fail | C14: 22 | E14: 12 | F14: Others - Do (FP) | G14: =C14+C15 -> 26 | I14: Fail | J14: 13 | K14: 4 | L14: 17 | M14: Others - Do (FP) | N14: =J14+J15 -> 14 | P14: Fail | Q14: 15 | R14: 6 | S14: 13 | T14: Others - Do (FP) | U14: =Q14+Q15 -> 17
B15: Pass | C15: 4 | E15: 90 | F15: Others - Others(VN) | G15: =D14+E14+D15+E15 -> 102 | I15: Pass | J15: 1 | K15: 2 | L15: 91 | M15: Others - Others(VN) | N15: =K14+L14+K15+L15 -> 114 | P15: Pass | Q15: 2 | S15: 92 | T15: Others - Others(VN) | U15: =R14+S14+R15+S15 -> 111
A17: 3 | B17: Resultat_reel | C17: Dropout | D17: Fail | E17: Pass | F17: Do - Do (VP) | G17: =C18 -> 68 | H17: 12 | I17: Resultat_reel | J17: Dropout | K17: Fail | L17: Pass | M17: Do - Do (VP) | N17: =J18 -> 58 | O17: 21 | P17: Resultat_reel | Q17: Dropout | R17: Fail | S17: Pass | T17: Do - Do (VP) | U17: =Q18 -> 64
B18: Dropout | C18: 68 | E18: 4 | F18: Do - Others (FN) | G18: =D18+E18 -> 4 | I18: Dropout | J18: 58 | K18: 7 | L18: 7 | M18: Do - Others (FN) | N18: =K18+L18 -> 14 | P18: Dropout | Q18: 64 | R18: 7 | S18: 1 | T18: Do - Others (FN) | U18: =R18+S18 -> 8
B19: Fail | C19: 22 | E19: 12 | F19: Others - Do (FP) | G19: =C19+C20 -> 26 | I19: Fail | J19: 14 | K19: 4 | L19: 16 | M19: Others - Do (FP) | N19: =J19+J20 -> 15 | P19: Fail | Q19: 16 | R19: 5 | S19: 13 | T19: Others - Do (FP) | U19: =Q19+Q20 -> 17
B20: Pass | C20: 4 | E20: 90 | F20: Others - Others(VN) | G20: =D19+E19+D20+E20 -> 102 | I20: Pass | J20: 1 | K20: 2 | L20: 91 | M20: Others - Others(VN) | N20: =K19+L19+K20+L20 -> 113 | P20: Pass | Q20: 1 | S20: 93 | T20: Others - Others(VN) | U20: =R19+S19+R20+S20 -> 111
A22: 4 | B22: Resultat_reel | C22: Dropout | D22: Fail | E22: Pass | F22: Do - Do (VP) | G22: =C23 -> 68 | H22: 13 | I22: Resultat_reel | J22: Dropout | K22: Fail | L22: Pass | M22: Do - Do (VP) | N22: =J23 -> 56 | O22: 22 | P22: Resultat_reel | Q22: Dropout | R22: Fail | S22: Pass | T22: Do - Do (VP) | U22: =Q23 -> 63
B23: Dropout | C23: 68 | E23: 4 | F23: Do - Others (FN) | G23: =D23+E23 -> 4 | I23: Dropout | J23: 56 | K23: 12 | L23: 4 | M23: Do - Others (FN) | N23: =K23+L23 -> 16 | P23: Dropout | Q23: 63 | R23: 8 | S23: 1 | T23: Do - Others (FN) | U23: =R23+S23 -> 9
B24: Fail | C24: 22 | E24: 12 | F24: Others - Do (FP) | G24: =C24+C25 -> 26 | I24: Fail | J24: 13 | K24: 6 | L24: 15 | M24: Others - Do (FP) | N24: =J24+J25 -> 14 | P24: Fail | Q24: 17 | R24: 4 | S24: 13 | T24: Others - Do (FP) | U24: =Q24+Q25 -> 18
B25: Pass | C25: 4 | E25: 90 | F25: Others - Others(VN) | G25: =D24+E24+D25+E25 -> 102 | I25: Pass | J25: 1 | K25: 2 | L25: 91 | M25: Others - Others(VN) | N25: =K24+L24+K25+L25 -> 114 | P25: Pass | Q25: 1 | S25: 93 | T25: Others - Others(VN) | U25: =R24+S24+R25+S25 -> 110
A27: 5 | B27: Resultat_reel | C27: Dropout | D27: Fail | E27: Pass | F27: Do - Do (VP) | G27: =C28 -> 65 | H27: 14 | I27: Resultat_reel | J27: Dropout | K27: Fail | L27: Pass | M27: Do - Do (VP) | N27: =J28 -> 62 | O27: 23 | P27: Resultat_reel | Q27: Dropout | R27: Fail | S27: Pass | T27: Do - Do (VP) | U27: =Q28 -> 67
B28: Dropout | C28: 65 | D28: 2 | E28: 5 | F28: Do - Others (FN) | G28: =D28+E28 -> 7 | I28: Dropout | J28: 62 | K28: 6 | L28: 4 | M28: Do - Others (FN) | N28: =K28+L28 -> 10 | P28: Dropout | Q28: 67 | R28: 4 | S28: 1 | T28: Do - Others (FN) | U28: =R28+S28 -> 5
B29: Fail | C29: 20 | D29: 1 | E29: 13 | F29: Others - Do (FP) | G29: =C29+C30 -> 23 | I29: Fail | J29: 13 | K29: 6 | L29: 15 | M29: Others - Do (FP) | N29: =J29+J30 -> 13 | P29: Fail | Q29: 18 | R29: 3 | S29: 13 | T29: Others - Do (FP) | U29: =Q29+Q30 -> 19
B30: Pass | C30: 3 | D30: 1 | E30: 90 | F30: Others - Others(VN) | G30: =D29+E29+D30+E30 -> 105 | I30: Pass | K30: 2 | L30: 92 | M30: Others - Others(VN) | N30: =K29+L29+K30+L30 -> 115 | P30: Pass | Q30: 1 | S30: 93 | T30: Others - Others(VN) | U30: =R29+S29+R30+S30 -> 109
A32: 6 | B32: Resultat_reel | C32: Dropout | D32: Fail | E32: Pass | F32: Do - Do (VP) | G32: =C33 -> 62 | H32: 15 | I32: Resultat_reel | J32: Dropout | K32: Fail | L32: Pass | M32: Do - Do (VP) | N32: =J33 -> 62 | O32: 24 | P32: Resultat_reel | Q32: Dropout | R32: Fail | S32: Pass | T32: Do - Do (VP) | U32: =Q33 -> 63
B33: Dropout | C33: 62 | D33: 6 | E33: 4 | F33: Do - Others (FN) | G33: =D33+E33 -> 10 | I33: Dropout | J33: 62 | K33: 6 | L33: 4 | M33: Do - Others (FN) | N33: =K33+L33 -> 10 | P33: Dropout | Q33: 63 | R33: 8 | S33: 1 | T33: Do - Others (FN) | U33: =R33+S33 -> 9
B34: Fail | C34: 19 | D34: 3 | E34: 12 | F34: Others - Do (FP) | G34: =C34+C35 -> 22 | I34: Fail | J34: 15 | K34: 4 | L34: 15 | M34: Others - Do (FP) | N34: =J34+J35 -> 15 | P34: Fail | Q34: 17 | R34: 5 | S34: 12 | T34: Others - Do (FP) | U34: =Q34+Q35 -> 18
B35: Pass | C35: 3 | D35: 1 | E35: 90 | F35: Others - Others(VN) | G35: =D34+E34+D35+E35 -> 106 | I35: Pass | L35: 94 | M35: Others - Others(VN) | N35: =K34+L34+K35+L35 -> 113 | P35: Pass | Q35: 1 | S35: 93 | T35: Others - Others(VN) | U35: =R34+S34+R35+S35 -> 110
A37: 7 | B37: Resultat_reel | C37: Dropout | D37: Fail | E37: Pass | F37: Do - Do (VP) | G37: =C38 -> 62 | H37: 16 | I37: Resultat_reel | J37: Dropout | K37: Fail | L37: Pass | M37: Do - Do (VP) | N37: =J38 -> 63 | O37: 25 | P37: Resultat_reel | Q37: Dropout | R37: Fail | S37: Pass | T37: Do - Do (VP) | U37: =Q38 -> 63
B38: Dropout | C38: 62 | D38: 6 | E38: 4 | F38: Do - Others (FN) | G38: =D38+E38 -> 10 | I38: Dropout | J38: 63 | K38: 5 | L38: 4 | M38: Do - Others (FN) | N38: =K38+L38 -> 9 | P38: Dropout | Q38: 63 | R38: 8 | S38: 1 | T38: Do - Others (FN) | U38: =R38+S38 -> 9
B39: Fail | C39: 18 | D39: 3 | E39: 13 | F39: Others - Do (FP) | G39: =C39+C40 -> 21 | I39: Fail | J39: 14 | K39: 5 | L39: 15 | M39: Others - Do (FP) | N39: =J39+J40 -> 15 | P39: Fail | Q39: 17 | R39: 5 | S39: 12 | T39: Others - Do (FP) | U39: =Q39+Q40 -> 18
B40: Pass | C40: 3 | D40: 1 | E40: 90 | F40: Others - Others(VN) | G40: =D39+E39+D40+E40 -> 107 | I40: Pass | J40: 1 | L40: 93 | M40: Others - Others(VN) | N40: =K39+L39+K40+L40 -> 113 | P40: Pass | Q40: 1 | S40: 93 | T40: Others - Others(VN) | U40: =R39+S39+R40+S40 -> 110
A42: 8 | B42: Resultat_reel | C42: Dropout | D42: Fail | E42: Pass | F42: Do - Do (VP) | G42: =C43 -> 59 | H42: 17 | I42: Resultat_reel | J42: Dropout | K42: Fail | L42: Pass | M42: Do - Do (VP) | N42: =J43 -> 63 | O42: 26 | P42: Resultat_reel | Q42: Dropout | R42: Fail | S42: Pass | T42: Do - Do (VP) | U42: =Q43 -> 67
B43: Dropout | C43: 59 | D43: 9 | E43: 4 | F43: Do - Others (FN) | G43: =D43+E43 -> 13 | I43: Dropout | J43: 63 | K43: 6 | L43: 3 | M43: Do - Others (FN) | N43: =K43+L43 -> 9 | P43: Dropout | Q43: 67 | R43: 4 | S43: 1 | T43: Do - Others (FN) | U43: =R43+S43 -> 5
B44: Fail | C44: 16 | D44: 4 | E44: 14 | F44: Others - Do (FP) | G44: =C44+C45 -> 19 | I44: Fail | J44: 15 | K44: 4 | L44: 15 | M44: Others - Do (FP) | N44: =J44+J45 -> 17 | P44: Fail | Q44: 19 | R44: 3 | S44: 12 | T44: Others - Do (FP) | U44: =Q44+Q45 -> 20
B45: Pass | C45: 3 | D45: 1 | E45: 90 | F45: Others - Others(VN) | G45: =D44+E44+D45+E45 -> 109 | I45: Pass | J45: 2 | L45: 92 | M45: Others - Others(VN) | N45: =K44+L44+K45+L45 -> 111 | P45: Pass | Q45: 1 | S45: 93 | T45: Others - Others(VN) | U45: =R44+S44+R45+S45 -> 108
B47: 1 | C47: 2 | D47: 3 | E47: 4 | F47: 5 | G47: 6 | H47: 7 | I47: 8 | J47: 9 | K47: 10 | L47: 11 | M47: 12 | N47: 13 | O47: 14 | P47: 15 | Q47: 16 | R47: 17 | S47: 18 | T47: 19 | U47: 20 | V47: 21 | W47: 22 | X47: 23 | Y47: 24 | Z47: 25 | AA47: 26 | AB47: 27 | AC47: 28 | AD47: 29
A48: Pass - Pass (VP) | B48: =G7 -> 68 | C48: =G12 -> 68 | D48: =G17 -> 68 | E48: =G22 -> 68 | F48: =G27 -> 65 | G48: =G32 -> 62 | H48: =G37 -> 62 | I48: =G42 -> 59 | J48: =N2 -> 60 | K48: =N7 -> 59 | L48: =N12 -> 61 | M48: =N17 -> 58 | N48: =N22 -> 56 | O48: =N27 -> 62 | P48: =N32 -> 62 | Q48: =N37 -> 63 | R48: =N42 -> 63 | S48: =U2 -> 63 | T48: =U7 -> 66 | U48: =U12 -> 61 | V48: =U17 -> 64 | W48: =U22 -> 63 | X48: =U27 -> 67 | Y48: =U32 -> 63 | Z48: =U37 -> 63 | AA48: =U42 -> 67 | AB48: =AB2 -> 64 | AC48: =AB7 -> 66 | AD48: =G2 -> 59
A49: Pass - Others (FN) | B49: =G8 -> 4 | C49: =G13 -> 4 | D49: =G18 -> 4 | E49: =G23 -> 4 | F49: =G28 -> 7 | G49: =G33 -> 10 | H49: =G38 -> 10 | I49: =G43 -> 13 | J49: =N3 -> 12 | K49: =N8 -> 13 | L49: =N13 -> 11 | M49: =N18 -> 14 | N49: =N23 -> 16 | O49: =N28 -> 10 | P49: =N33 -> 10 | Q49: =N38 -> 9 | R49: =N43 -> 9 | S49: =U3 -> 9 | T49: =U8 -> 6 | U49: =U13 -> 11 | V49: =U18 -> 8 | W49: =U23 -> 9 | X49: =U28 -> 5 | Y49: =U33 -> 9 | Z49: =U38 -> 9 | AA49: =U43 -> 5 | AB49: =AB3 -> 8 | AC49: =AB8 -> 6 | AD49: =G3 -> 13
A50: Others - Pass (FP) | B50: =G9 -> 26 | C50: =G14 -> 26 | D50: =G19 -> 26 | E50: =G24 -> 26 | F50: =G29 -> 23 | G50: =G34 -> 22 | H50: =G39 -> 21 | I50: =G44 -> 19 | J50: =N4 -> 14 | K50: =N9 -> 14 | L50: =N14 -> 14 | M50: =N19 -> 15 | N50: =N24 -> 14 | O50: =N29 -> 13 | P50: =N34 -> 15 | Q50: =N39 -> 15 | R50: =N44 -> 17 | S50: =U4 -> 16 | T50: =U9 -> 18 | U50: =U14 -> 17 | V50: =U19 -> 17 | W50: =U24 -> 18 | X50: =U29 -> 19 | Y50: =U34 -> 18 | Z50: =U39 -> 18 | AA50: =U44 -> 20 | AB50: =AB4 -> 19 | AC50: =AB9 -> 21 | AD50: =G4 -> 18
...

Sheet Analyse
A1: ID_Student | B1: code_etudiant | C1: Resultat_reel | D1: 1 | E1: 2 | F1: 3 | G1: 4 | H1: 5 | I1: 6 | J1: 7 | K1: 8 | L1: 9 | M1: 10 | N1: 11 | O1: 12 | P1: 13 | Q1: 14 | R1: 15 | S1: 16 | T1: 17 | U1: 18 | V1: 19 | W1: 20 | X1: 21 | Y1: 22 | Z1: 23 | AA1: 24 | AB1: 25 | AC1: 26 | AD1: 27 | AE1: 28 | AF1: 29
A2: 0 | B2: 3 | C2: Fail | D2: Dropout | E2: Dropout | F2: Dropout | G2: Dropout | H2: Dropout | I2: Dropout | J2: Dropout | K2: Dropout | L2: Dropout | M2: Dropout | N2: Dropout | O2: Dropout | P2: Dropout | Q2: Dropout | R2: Dropout | S2: Dropout | T2: Dropout | U2: Dropout | V2: Dropout | W2: Dropout | X2: Dropout | Y2: Dropout | Z2: Dropout | AA2: Dropout | AB2: Dropout | AC2: Dropout | AD2: Dropout | AE2: Dropout | AF2: Dropout
A3: 1 | B3: 4 | C3: Dropout | D3: Dropout | E3: Dropout | F3: Dropout | G3: Dropout | H3: Dropout | I3: Dropout | J3: Dropout | K3: Dropout | L3: Dropout | M3: Dropout | N3: Dropout | O3: Dropout | P3: Dropout | Q3: Dropout | R3: Dropout | S3: Dropout | T3: Dropout | U3: Dropout | V3: Dropout | W3: Dropout | X3: Dropout | Y3: Dropout | Z3: Dropout | AA3: Dropout | AB3: Dropout | AC3: Dropout | AD3: Dropout | AE3: Dropout | AF3: Dropout
A4: 2 | B4: 5 | C4: Pass | D4: Pass | E4: Pass | F4: Pass | G4: Pass | H4: Pass | I4: Pass | J4: Pass | K4: Pass | L4: Pass | M4: Pass | N4: Pass | O4: Pass | P4: Pass | Q4: Pass | R4: Pass | S4: Pass | T4: Pass | U4: Pass | V4: Pass | W4: Pass | X4: Pass | Y4: Pass | Z4: Pass | AA4: Pass | AB4: Pass | AC4: Pass | AD4: Pass | AE4: Pass | AF4: Pass
A5: 3 | B5: 12 | C5: Pass | D5: Pass | E5: Pass | F5: Pass | G5: Pass | H5: Pass | I5: Pass | J5: Pass | K5: Pass | L5: Pass | M5: Pass | N5: Pass | O5: Pass | P5: Pass | Q5: Pass | R5: Pass | S5: Pass | T5: Pass | U5: Pass | V5: Pass | W5: Pass | X5: Pass | Y5: Pass | Z5: Pass | AA5: Pass | AB5: Pass | AC5: Pass | AD5: Pass | AE5: Pass | AF5: Pass
A6: 4 | B6: 13 | C6: Fail | D6: Dropout | E6: Dropout | F6: Dropout | G6: Dropout | H6: Fail | I6: Fail | J6: Fail | K6: Fail | L6: Fail | M6: Fail | N6: Fail | O6: Fail | P6: Fail | Q6: Fail | R6: Fail | S6: Fail | T6: Fail | U6: Fail | V6: Fail | W6: Fail | X6: Fail | Y6: Fail | Z6: Fail | AA6: Fail | AB6: Fail | AC6: Fail | AD6: Fail | AE6: Dropout | AF6: Dropout
A7: 5 | B7: 25 | C7: Pass | D7: Dropout | E7: Dropout | F7: Dropout | G7: Dropout | H7: Dropout | I7: Dropout | J7: Dropout | K7: Dropout | L7: Fail | M7: Fail | N7: Fail | O7: Fail | P7: Fail | Q7: Fail | R7: Pass | S7: Pass | T7: Dropout | U7: Dropout | V7: Dropout | W7: Dropout | X7: Dropout | Y7: Dropout | Z7: Dropout | AA7: Dropout | AB7: Dropout | AC7: Dropout | AD7: Dropout | AE7: Dropout | AF7: Dropout
A8: 6 | B8: 40 | C8: Dropout | D8: Dropout | E8: Dropout | F8: Dropout | G8: Dropout | H8: Dropout | I8: Dropout | J8: Dropout | K8: Dropout | L8: Dropout | M8: Dropout | N8: Dropout | O8: Dropout | P8: Dropout | Q8: Dropout | R8: Dropout | S8: Dropout | T8: Dropout | U8: Dropout | V8: Dropout | W8: Dropout | X8: Dropout | Y8: Dropout | Z8: Dropout | AA8: Dropout | AB8: Dropout | AC8: Dropout | AD8: Dropout | AE8: Dropout | AF8: Dropout
A9: 7 | B9: 55 | C9: Pass | D9: Pass | E9: Pass | F9: Pass | G9: Pass | H9: Pass | I9: Pass | J9: Pass | K9: Pass | L9: Pass | M9: Pass | N9: Pass | O9: Pass | P9: Pass | Q9: Pass | R9: Pass | S9: Pass | T9: Pass | U9: Pass | V9: Pass | W9: Pass | X9: Pass | Y9: Pass | Z9: Pass | AA9: Pass | AB9: Pass | AC9: Pass | AD9: Pass | AE9: Pass | AF9: Pass
A10: 8 | B10: 60 | C10: Pass | D10: Pass | E10: Pass | F10: Pass | G10: Pass | H10: Pass | I10: Pass | J10: Pass | K10: Pass | L10: Pass | M10: Pass | N10: Pass | O10: Pass | P10: Pass | Q10: Pass | R10: Pass | S10: Pass | T10: Pass | U10: Pass | V10: Pass | W10: Pass | X10: Pass | Y10: Pass | Z10: Pass | AA10: Pass | AB10: Pass | AC10: Pass | AD10: Pass | AE10: Pass | AF10: Pass
A11: 9 | B11: 70 | C11: Dropout | D11: Dropout | E11: Dropout | F11: Dropout | G11: Dropout | H11: Pass | I11: Dropout | J11: Dropout | K11: Dropout | L11: Dropout | M11: Dropout | N11: Dropout | O11: Dropout | P11: Dropout | Q11: Dropout | R11: Dropout | S11: Dropout | T11: Dropout | U11: Dropout | V11: Dropout | W11: Dropout | X11: Dropout | Y11: Dropout | Z11: Dropout | AA11: Dropout | AB11: Dropout | AC11: Dropout | AD11: Dropout | AE11: Dropout | AF11: Dropout
A12: 10 | B12: 72 | C12: Fail | D12: Pass | E12: Pass | F12: Pass | G12: Pass | H12: Pass | I12: Pass | J12: Pass | K12: Pass | L12: Pass | M12: Pass | N12: Pass | O12: Pass | P12: Pass | Q12: Pass | R12: Pass | S12: Pass | T12: Pass | U12: Pass | V12: Pass | W12: Pass | X12: Pass | Y12: Pass | Z12: Pass | AA12: Pass | AB12: Pass | AC12: Pass | AD12: Pass | AE12: Pass | AF12: Pass
A13: 11 | B13: 85 | C13: Pass | D13: Dropout | E13: Dropout | F13: Dropout | G13: Dropout | H13: Dropout | I13: Dropout | J13: Dropout | K13: Dropout | L13: Pass | M13: Pass | N13: Pass | O13: Pass | P13: Pass | Q13: Pass | R13: Pass | S13: Pass | T13: Pass | U13: Pass | V13: Pass | W13: Pass | X13: Pass | Y13: Pass | Z13: Pass | AA13: Pass | AB13: Pass | AC13: Pass | AD13: Pass | AE13: Pass | AF13: Pass
... A201: 199 | B201: 2365 | C201: Dropout | D201: Dropout | E201: Dropout | F201: Dropout | G201: Dropout | H201: Dropout | I201: Dropout | J201: Dropout | K201: Dropout | L201: Dropout | M201: Dropout | N201: Dropout | O201: Dropout | P201: Dropout | Q201: Dropout | R201: Dropout | S201: Dropout | T201: Dropout | U201: Dropout | V201: Dropout | W201: Dropout | X201: Dropout | Y201: Dropout | Z201: Dropout | AA201: Dropout | AB201: Dropout | AC201: Dropout | AD201: Dropout | AE201: Dropout | AF201: Dropout

Sheet Frame_sys_results
A1: =Analyse!AF1 -> 29 | B1: Final_frame
A2: =Analyse!AF2 -> Dropout | B2: =A2 -> Dropout
A3: =Analyse!AF3 -> Dropout | B3: =_xlfn.CONCAT(B2,",",A3) -> Dropout,Dropout
A4: =Analyse!AF4 -> Pass | B4: =_xlfn.CONCAT(B3,",",A4) -> Dropout,Dropout,Pass
A5: =Analyse!AF5 -> Pass | B5: =_xlfn.CONCAT(B4,",",A5) -> Dropout,Dropout,Pass,Pass
A6: =Analyse!AF6 -> Dropout | B6: =_xlfn.CONCAT(B5,",",A6) -> Dropout,Dropout,Pass,Pass,Dropout
A7: =Analyse!AF7 -> Dropout | B7: =_xlfn.CONCAT(B6,",",A7) -> Dropout,Dropout,Pass,Pass,Dropout,Dropout
A8: =Analyse!AF8 -> Dropout | B8: =_xlfn.CONCAT(B7,",",A8) -> Dropout,Dropout,Pass,Pass,Dropout,Dropout,Dropout
A9: =Analyse!AF9 -> Pass | B9: =_xlfn.CONCAT(B8,",",A9) -> Dropout,Dropout,Pass,Pass,Dropout,Dropout,Dropout,Pass
A10: =Analyse!AF10 -> Pass | B10: =_xlfn.CONCAT(B9,",",A10) -> Dropout,Dropout,Pass,Pass,Dropout,Dropout,Dropout,Pass,Pass
A11: =Analyse!AF11 -> Dropout | B11: =_xlfn.CONCAT(B10,",",A11) -> Dropout,Dropout,Pass,Pass,Dropout,Dropout,Dropout,Pass,Pass,Dropout
A12: =Analyse!AF12 -> Pass | B12: =_xlfn.CONCAT(B11,",",A12) -> Dropout,Dropout,Pass,Pass,Dropout,Dropout,Dropout,Pass,Pass,Dropout,Pass
A13: =Analyse!AF13 -> Pass | B13: =_xlfn.CONCAT(B12,",",A13) -> Dropout,Dropout,Pass,Pass,Dropout,Dropout,Dropout,Pass,Pass,Dropout,Pass,Pass
A14: =Analyse!AF14 -> Pass | B14: =_xlfn.CONCAT(B13,",",A14) -> Dropout,Dropout,Pass,Pass,Dropout,Dropout,Dropout,Pass,Pass,Dropout,Pass,Pass,Pass
... A201: =Analyse!AF201 -> Dropout | B201: =_xlfn.CONCAT(B200,",",A201) -> Dropout,Dropout,Pass,Pass,Dropout,Dropout,Dropout,Pass,Pass,Dropout,Pass,Pass,Pass,Dropout,Pass,Pass,Dropout,Pass,Dropout,Pass,Dropout,Pass,Dropout,Dropout,Pass,Pass,Fail,Dropout,Pass,Fail,Dropout,Pass,Dropout,Dropout,Pass,Pass,Dropout,Pass,Pass,Fail,Pass,Dropout,Pass,Pass,Pass,Fail,Fail,Pass,Fail,Pass,Dropout,Dropout,Pass,Dropout,Dropout,Pass,Dropout,Pass,Dropout,Pass,Dropout,Pass,Fail,Dropout,Pass,Pass,Pass,Dropout,Dropout,Dropout,Pass,Dropout,Pass,Dropout,Dropout,Pass,Pass,Dropout,Pass,Pass,Dropout,Pass,Pass,Dropout,Pass,Dropout,Pass,Dropout,Pass,Pass,Pass,Fail,Dropout,Pass,Dropout,Fail,Dropout,Pass,Fail,Pass,Dropout,Pass,Dropout,Pass,Fail,Dropout,Dropout,Pass,Pass,Dropout,Fail,Pass,Pass,Fail,Pass,Pass,Fail,Dropout,Pass,Pass,Dropout,Pass,Dropout,Dropout,Pass,Dropout,Dropout,Pass,Pass,Dropout,Pass,Dropout,Dropout,Pass,Dropout,Pass,Pass,Dropout,Pass,Dropout,Pass,Dropout,Pass,Dropout,Pass,Dropout,Pass,Pass,Dropout,Pass,Dropout,Pass,Pass,Fail,Pass,Pass,Fail,Pass,Dropout,Fail,Pass,Dropout,Pass,Dropout,Pass,Pass,Pass,Dropout,Pass,Dropout,Pass,Dropout,Pass,Pass,Dropout,Dropout,Dropout,Pass,Pass,Pass,Dropout,Pass,Pass,Pass,Fail,Dropout,Pass,Pass,Dropout,Pass,Pass,Pass,Dropout,Pass,Pass,Pass,Pass,Dropout,Pass,Dropout

Sheet Analyse (2)
A1: ID_Student | B1: code_etudiant | C1: Resultat_reel | D1: 1 | E1: 2 | F1: 3 | G1: 4 | H1: 5 | I1: 6 | J1: 7 | K1: 8 | L1: 9 | M1: 10 | N1: 11 | O1: 12 | P1: 13 | Q1: 14 | R1: 15 | S1: 16 | T1: 17 | U1: 18 | V1: 19 | W1: 20 | X1: 21 | Y1: 22 | Z1: 23 | AA1: 24 | AB1: 25 | AC1: 26 | AD1: 27 | AE1: 28 | AF1: 29 | AH1: Module | AI1: EcartModule
A2: 0 | B2: 3 | C2: Fail | D2: Dropout | E2: Dropout | F2: Dropout | G2: Dropout | H2: Dropout | I2: Dropout | J2: Dropout | K2: Dropout | L2: Dropout | M2: Dropout | N2: Dropout | O2: Dropout | P2: Dropout | Q2: Dropout | R2: Dropout | S2: Dropout | T2: Dropout | U2: Dropout | V2: Dropout | W2: Dropout | X2: Dropout | Y2: Dropout | Z2: Dropout | AA2: Dropout | AB2: Dropout | AC2: Dropout | AD2: Dropout | AE2: Dropout | AF2: Dropout
A3: 1 | B3: 4 | C3: Dropout | D3: Dropout | E3: Dropout | F3: Dropout | G3: Dropout | H3: Dropout | I3: Dropout | J3: Dropout | K3: Dropout | L3: Dropout | M3: Dropout | N3: Dropout | O3: Dropout | P3: Dropout | Q3: Dropout | R3: Dropout | S3: Dropout | T3: Dropout | U3: Dropout | V3: Dropout | W3: Dropout | X3: Dropout | Y3: Dropout | Z3: Dropout | AA3: Dropout | AB3: Dropout | AC3: Dropout | AD3: Dropout | AE3: Dropout | AF3: Dropout | AH3: 1
A4: 2 | B4: 5 | C4: Pass | D4: Pass | E4: Pass | F4: Pass | G4: Pass | H4: Pass | I4: Pass | J4: Pass | K4: Pass | L4: Pass | M4: Pass | N4: Pass | O4: Pass | P4: Pass | Q4: Pass | R4: Pass | S4: Pass | T4: Pass | U4: Pass | V4: Pass | W4: Pass | X4: Pass | Y4: Pass | Z4: Pass | AA4: Pass | AB4: Pass | AC4: Pass | AD4: Pass | AE4: Pass | AF4: Pass | AH4: 1
A5: 3 | B5: 12 | C5: Pass | D5: Pass | E5: Pass | F5: Pass | G5: Pass | H5: Pass | I5: Pass | J5: Pass | K5: Pass | L5: Pass | M5: Pass | N5: Pass | O5: Pass | P5: Pass | Q5: Pass | R5: Pass | S5: Pass | T5: Pass | U5: Pass | V5: Pass | W5: Pass | X5: Pass | Y5: Pass | Z5: Pass | AA5: Pass | AB5: Pass | AC5: Pass | AD5: Pass | AE5: Pass | AF5: Pass | AH5: 1
A6: 4 | B6: 13 | C6: Fail | D6: Dropout | E6: Dropout | F6: Dropout | G6: Dropout | H6: Fail | I6: Fail | J6: Fail | K6: Fail | L6: Fail | M6: Fail | N6: Fail | O6: Fail | P6: Fail | Q6: Fail | R6: Fail | S6: Fail | T6: Fail | U6: Fail | V6: Fail | W6: Fail | X6: Fail | Y6: Fail | Z6: Fail | AA6: Fail | AB6: Fail | AC6: Fail | AD6: Fail | AE6: Dropout | AF6: Dropout
A7: 5 | B7: 25 | C7: Pass | D7: Dropout | E7: Dropout | F7: Dropout | G7: Dropout | H7: Dropout | I7: Dropout | J7: Dropout | K7: Dropout | L7: Fail | M7: Fail | N7: Fail | O7: Fail | P7: Fail | Q7: Fail | R7: Pass | S7: Pass | T7: Dropout | U7: Dropout | V7: Dropout | W7: Dropout | X7: Dropout | Y7: Dropout | Z7: Dropout | AA7: Dropout | AB7: Dropout | AC7: Dropout | AD7: Dropout | AE7: Dropout | AF7: Dropout
A8: 6 | B8: 40 | C8: Dropout | D8: Dropout | E8: Dropout | F8: Dropout | G8: Dropout | H8: Dropout | I8: Dropout | J8: Dropout | K8: Dropout | L8: Dropout | M8: Dropout | N8: Dropout | O8: Dropout | P8: Dropout | Q8: Dropout | R8: Dropout | S8: Dropout | T8: Dropout | U8: Dropout | V8: Dropout | W8: Dropout | X8: Dropout | Y8: Dropout | Z8: Dropout | AA8: Dropout | AB8: Dropout | AC8: Dropout | AD8: Dropout | AE8: Dropout | AF8: Dropout | AH8: 1
A9: 7 | B9: 55 | C9: Pass | D9: Pass | E9: Pass | F9: Pass | G9: Pass | H9: Pass | I9: Pass | J9: Pass | K9: Pass | L9: Pass | M9: Pass | N9: Pass | O9: Pass | P9: Pass | Q9: Pass | R9: Pass | S9: Pass | T9: Pass | U9: Pass | V9: Pass | W9: Pass | X9: Pass | Y9: Pass | Z9: Pass | AA9: Pass | AB9: Pass | AC9: Pass | AD9: Pass | AE9: Pass | AF9: Pass | AH9: 1
A10: 8 | B10: 60 | C10: Pass | D10: Pass | E10: Pass | F10: Pass | G10: Pass | H10: Pass | I10: Pass | J10: Pass | K10: Pass | L10: Pass | M10: Pass | N10: Pass | O10: Pass | P10: Pass | Q10: Pass | R10: Pass | S10: Pass | T10: Pass | U10: Pass | V10: Pass | W10: Pass | X10: Pass | Y10: Pass | Z10: Pass | AA10: Pass | AB10: Pass | AC10: Pass | AD10: Pass | AE10: Pass | AF10: Pass | AH10: 1
A11: 9 | B11: 70 | C11: Dropout | D11: Dropout | E11: Dropout | F11: Dropout | G11: Dropout | H11: Pass | I11: Dropout | J11: Dropout | K11: Dropout | L11: Dropout | M11: Dropout | N11: Dropout | O11: Dropout | P11: Dropout | Q11: Dropout | R11: Dropout | S11: Dropout | T11: Dropout | U11: Dropout | V11: Dropout | W11: Dropout | X11: Dropout | Y11: Dropout | Z11: Dropout | AA11: Dropout | AB11: Dropout | AC11: Dropout | AD11: Dropout | AE11: Dropout | AF11: Dropout | AH11: 1
A12: 10 | B12: 72 | C12: Fail | D12: Pass | E12: Pass | F12: Pass | G12: Pass | H12: Pass | I12: Pass | J12: Pass | K12: Pass | L12: Pass | M12: Pass | N12: Pass | O12: Pass | P12: Pass | Q12: Pass | R12: Pass | S12: Pass | T12: Pass | U12: Pass | V12: Pass | W12: Pass | X12: Pass | Y12: Pass | Z12: Pass | AA12: Pass | AB12: Pass | AC12: Pass | AD12: Pass | AE12: Pass | AF12: Pass
A13: 11 | B13: 85 | C13: Pass | D13: Dropout | E13: Dropout | F13: Dropout | G13: Dropout | H13: Dropout | I13: Dropout | J13: Dropout | K13: Dropout | L13: Pass | M13: Pass | N13: Pass | O13: Pass | P13: Pass | Q13: Pass | R13: Pass | S13: Pass | T13: Pass | U13: Pass | V13: Pass | W13: Pass | X13: Pass | Y13: Pass | Z13: Pass | AA13: Pass | AB13: Pass | AC13: Pass | AD13: Pass | AE13: Pass | AF13: Pass | AH13: 9
A14: 12 | B14: 106 | C14: Fail | D14: Pass | E14: Pass | F14: Pass | G14: Pass | H14: Pass | I14: Pass | J14: Pass | K14: Pass | L14: Pass | M14: Pass | N14: Pass | O14: Pass | P14: Pass | Q14: Pass | R14: Pass | S14: Pass | T14: Pass | U14: Pass | V14: Pass | W14: Pass | X14: Pass | Y14: Pass | Z14: Pass | AA14: Pass | AB14: Pass | AC14: Pass | AD14: Pass | AE14: Pass | AF14: Pass
A15: 13 | B15: 113 | C15: Dropout | D15: Dropout | E15: Dropout | F15: Dropout | G15: Dropout | H15: Dropout | I15: Dropout | J15: Dropout | K15: Dropout | L15: Dropout | M15: Dropout | N15: Dropout | O15: Dropout | P15: Dropout | Q15: Dropout | R15: Dropout | S15: Dropout | T15: Dropout | U15: Dropout | V15: Dropout | W15: Dropout | X15: Dropout | Y15: Dropout | Z15: Dropout | AA15: Dropout | AB15: Dropout | AC15: Dropout | AD15: Dropout | AE15: Dropout | AF15: Dropout | AH15: 1
A16: 14 | B16: 131 | C16: Pass | D16: Pass | E16: Pass | F16: Pass | G16: Pass | H16: Pass | I16: Pass | J16: Pass | K16: Pass | L16: Pass | M16: Pass | N16: Pass | O16: Pass | P16: Pass | Q16: Pass | R16: Pass | S16: Pass | T16: Pass | U16: Pass | V16: Pass | W16: Pass | X16: Pass | Y16: Pass | Z16: Pass | AA16: Pass | AB16: Pass | AC16: Pass | AD16: Pass | AE16: Pass | AF16: Pass | AH16: 1
A17: 15 | B17: 154 | C17: Fail | D17: Pass | E17: Pass | F17: Pass | G17: Pass | H17: Pass | I17: Pass | J17: Pass | K17: Pass | L17: Pass | M17: Pass | N17: Pass | O17: Pass | P17: Pass | Q17: Pass | R17: Pass | S17: Pass | T17: Pass | U17: Pass | V17: Pass | W17: Pass | X17: Pass | Y17: Pass | Z17: Pass | AA17: Dropout | AB17: Pass | AC17: Dropout | AD17: Dropout | AE17: Dropout | AF17: Pass
A18: 16 | B18: 161 | C18: Dropout | D18: Dropout | E18: Dropout | F18: Dropout | G18: Dropout | H18: Dropout | I18: Dropout | J18: Dropout | K18: Dropout | L18: Dropout | M18: Dropout | N18: Dropout | O18: Dropout | P18: Dropout | Q18: Dropout | R18: Dropout | S18: Dropout | T18: Dropout | U18: Dropout | V18: Dropout | W18: Dropout | X18: Dropout | Y18: Dropout | Z18: Dropout | AA18: Dropout | AB18: Dropout | AC18: Dropout | AD18: Dropout | AE18: Dropout | AF18: Dropout | AH18: 1
A19: 17 | B19: 172 | C19: Pass | D19: Pass | E19: Pass | F19: Pass | G19: Pass | H19: Pass | I19: Pass | J19: Pass | K19: Pass | L19: Pass | M19: Pass | N19: Pass | O19: Pass | P19: Pass | Q19: Pass | R19: Pass | S19: Pass | T19: Pass | U19: Pass | V19: Pass | W19: Pass | X19: Pass | Y19: Pass | Z19: Pass | AA19: Pass | AB19: Pass | AC19: Pass | AD19: Pass | AE19: Pass | AF19: Pass | AH19: 1
A20: 18 | B20: 209 | C20: Dropout | D20: Dropout | E20: Dropout | F20: Dropout | G20: Dropout | H20: Dropout | I20: Dropout | J20: Dropout | K20: Dropout | L20: Dropout | M20: Dropout | N20: Dropout | O20: Dropout | P20: Dropout | Q20: Dropout | R20: Dropout | S20: Dropout | T20: Dropout | U20: Dropout | V20: Dropout | W20: Dropout | X20: Dropout | Y20: Dropout | Z20: Dropout | AA20: Dropout | AB20: Dropout | AC20: Dropout | AD20: Dropout | AE20: Dropout | AF20: Dropout | AH20: 1
A21: 19 | B21: 219 | C21: Pass | D21: Pass | E21: Pass | F21: Pass | G21: Pass | H21: Pass | I21: Pass | J21: Pass | K21: Pass | L21: Pass | M21: Pass | N21: Pass | O21: Pass | P21: Pass | Q21: Pass | R21: Pass | S21: Pass | T21: Pass | U21: Pass | V21: Pass | W21: Pass | X21: Pass | Y21: Pass | Z21: Pass | AA21: Pass | AB21: Pass | AC21: Pass | AD21: Pass | AE21: Pass | AF21: Pass | AH21: 1
A22: 20 | B22: 255 | C22: Dropout | D22: Dropout | E22: Dropout | F22: Dropout | G22: Dropout | H22: Dropout | I22: Dropout | J22: Dropout | K22: Dropout | L22: Dropout | M22: Dropout | N22: Dropout | O22: Dropout | P22: Dropout | Q22: Dropout | R22: Dropout | S22: Dropout | T22: Dropout | U22: Dropout | V22: Dropout | W22: Dropout | X22: Dropout | Y22: Dropout | Z22: Dropout | AA22: Dropout | AB22: Dropout | AC22: Dropout | AD22: Dropout | AE22: Dropout | AF22: Dropout | AH22: 1
A23: 21 | B23: 266 | C23: Pass | D23: Pass | E23: Pass | F23: Pass | G23: Pass | H23: Pass | I23: Pass | J23: Pass | K23: Pass | L23: Pass | M23: Pass | N23: Pass | O23: Pass | P23: Pass | Q23: Pass | R23: Pass | S23: Pass | T23: Pass | U23: Pass | V23: Pass | W23: Pass | X23: Pass | Y23: Pass | Z23: Pass | AA23: Pass | AB23: Pass | AC23: Pass | AD23: Pass | AE23: Pass | AF23: Pass | AH23: 1
A24: 22 | B24: 273 | C24: Fail | D24: Dropout | E24: Dropout | F24: Dropout | G24: Dropout | H24: Dropout | I24: Dropout | J24: Dropout | K24: Dropout | L24: Dropout | M24: Dropout | N24: Dropout | O24: Dropout | P24: Dropout | Q24: Dropout | R24: Dropout | S24: Dropout | T24: Dropout | U24: Dropout | V24: Dropout | W24: Dropout | X24: Dropout | Y24: Dropout | Z24: Dropout | AA24: Dropout | AB24: Dropout | AC24: Dropout | AD24: Dropout | AE24: Dropout | AF24: Dropout
A25: 23 | B25: 306 | C25: Fail | D25: Dropout | E25: Dropout | F25: Dropout | G25: Dropout | H25: Dropout | I25: Dropout | J25: Dropout | K25: Dropout | L25: Dropout | M25: Dropout | N25: Dropout | O25: Dropout | P25: Dropout | Q25: Dropout | R25: Fail | S25: Fail | T25: Fail | U25: Fail | V25: Fail | W25: Fail | X25: Dropout | Y25: Dropout | Z25: Dropout | AA25: Dropout | AB25: Dropout | AC25: Dropout | AD25: Dropout | AE25: Dropout | AF25: Dropout
A26: 24 | B26: 317 | C26: Pass | D26: Pass | E26: Pass | F26: Pass | G26: Pass | H26: Pass | I26: Pass | J26: Pass | K26: Pass | L26: Pass | M26: Pass | N26: Pass | O26: Pass | P26: Pass | Q26: Pass | R26: Pass | S26: Pass | T26: Pass | U26: Pass | V26: Pass | W26: Pass | X26: Pass | Y26: Pass | Z26: Pass | AA26: Pass | AB26: Pass | AC26: Pass | AD26: Pass | AE26: Pass | AF26: Pass | AH26: 1
A27: 25 | B27: 327 | C27: Pass | D27: Pass | E27: Pass | F27: Pass | G27: Pass | H27: Pass | I27: Pass | J27: Pass | K27: Pass | L27: Pass | M27: Pass | N27: Pass | O27: Pass | P27: Pass | Q27: Pass | R27: Pass | S27: Pass | T27: Pass | U27: Pass | V27: Pass | W27: Pass | X27: Pass | Y27: Pass | Z27: Pass | AA27: Pass | AB27: Pass | AC27: Pass | AD27: Pass | AE27: Pass | AF27: Pass | AH27: 1
A28: 26 | B28: 330 | C28: Dropout | D28: Dropout | E28: Dropout | F28: Dropout | G28: Dropout | H28: Dropout | I28: Dropout | J28: Dropout | K28: Dropout | L28: Pass | M28: Pass | N28: Pass | O28: Pass | P28: Fail | Q28: Fail | R28: Pass | S28: Pass | T28: Pass | U28: Pass | V28: Fail | W28: Fail | X28: Fail | Y28: Fail | Z28: Fail | AA28: Fail | AB28: Fail | AC28: Fail | AD28: Fail | AE28: Fail | AF28: Fail
A29: 27 | B29: 355 | C29: Dropout | D29: Dropout | E29: Dropout | F29: Dropout | G29: Dropout | H29: Dropout | I29: Dropout | J29: Dropout | K29: Dropout | L29: Dropout | M29: Dropout | N29: Dropout | O29: Dropout | P29: Dropout | Q29: Dropout | R29: Dropout | S29: Dropout | T29: Dropout | U29: Dropout | V29: Dropout | W29: Dropout | X29: Dropout | Y29: Dropout | Z29: Dropout | AA29: Dropout | AB29: Dropout | AC29: Dropout | AD29: Dropout | AE29: Dropout | AF29: Dropout | AH29: 1
A30: 28 | B30: 368 | C30: Pass | D30: Pass | E30: Pass | F30: Pass | G30: Pass | H30: Pass | I30: Pass | J30: Pass | K30: Pass | L30: Pass | M30: Pass | N30: Pass | O30: Pass | P30: Pass | Q30: Pass | R30: Pass | S30: Pass | T30: Pass | U30: Pass | V30: Pass | W30: Pass | X30: Pass | Y30: Pass | Z30: Pass | AA30: Pass | AB30: Pass | AC30: Pass | AD30: Pass | AE30: Pass | AF30: Pass | AH30: 1
A31: 29 | B31: 381 | C31: Dropout | D31: Dropout | E31: Dropout | F31: Dropout | G31: Dropout | H31: Dropout | I31: Fail | J31: Fail | K31: Fail | L31: Fail | M31: Fail | N31: Fail | O31: Fail | P31: Fail | Q31: Fail | R31: Fail | S31: Dropout | T31: Fail | U31: Dropout | V31: Fail | W31: Fail | X31: Dropout | Y31: Dropout | Z31: Dropout | AA31: Dropout | AB31: Dropout | AC31: Dropout | AD31: Fail | AE31: Dropout | AF31: Fail
A32: 30 | B32: 411 | C32: Fail | D32: Dropout | E32: Dropout | F32: Dropout | G32: Dropout | H32: Dropout | I32: Dropout | J32: Dropout | K32: Dropout | L32: Dropout | M32: Dropout | N32: Dropout | O32: Dropout | P32: Dropout | Q32: Pass | R32: Dropout | S32: Dropout | T32: Dropout | U32: Dropout | V32: Dropout | W32: Dropout | X32: Dropout | Y32: Dropout | Z32: Dropout | AA32: Dropout | AB32: Dropout | AC32: Dropout | AD32: Dropout | AE32: Dropout | AF32: Dropout
